Workbook
Name __________________________________a129: #REF!
Name __________________________________a130: #REF!
Name _________________________________a129: #REF!
Name _________________________________a130: #REF!
Name ________________________________a129: #REF!
Name ________________________________a130: #REF!
Name _______________________________a129: #REF!
Name _______________________________a130: #REF!
Name ______________________________a129: #REF!
Name ______________________________a130: #REF!
Name _____________________________a129: #REF!
Name _____________________________a130: #REF!
Name ____________________________a129: #REF!
Name ____________________________a130: #REF!
Name ___________________________a129: #REF!
Name ___________________________a130: #REF!
Name __________________________a129: #REF!
Name __________________________a130: #REF!
Name _________________________a129: #REF!
Name _________________________a130: #REF!
Name ________________________a129: #REF!
Name ________________________a130: #REF!
Name _______________________a129: #REF!
Name _______________________a130: #REF!
Name ______________________a129: #REF!
Name ______________________a130: #REF!
Name _____________________a129: #REF!
Name _____________________a130: #REF!
Name ____________________a129: #REF!
Name ____________________a130: #REF!
Name ___________________a129: #REF!
Name ___________________a130: #REF!
Name __________________a129: #REF!
Name __________________a130: #REF!
Name _________________a129: #REF!
Name _________________a130: #REF!
Name ________________a129: #REF!
Name ________________a130: #REF!
Name _______________a129: #REF!
Name _______________a130: #REF!
Name ______________a129: #REF!
Name ______________a130: #REF!
Name _____________a129: #REF!
Name _____________a130: #REF!
Name ____________a129: #REF!
Name ____________a130: #REF!
Name ___________a129: #REF!
Name ___________a130: #REF!
Name __________a129: #REF!
Name __________a130: #REF!
Name _________a129: #REF!
Name _________a130: #REF!
Name ________a129: #REF!
Name ________a130: #REF!
Name _______a129: #REF!
Name _______a130: #REF!
Name ______a129: #REF!
Name ______a130: #REF!
Name _____a129: #REF!
Name _____a130: #REF!

Sheet MỤC LỤC
A1: DANH MỤC HỒ SƠ LƯƠNG THÁNG 04.2024
A2: STT | B2: Nội dung | C2: Link
A3: 1 | B3: Đề nghị thanh toán | C3: ĐỀ NGHỊ THANH TOÁN
A4: 2 | B4: Ngân hàng nhận lương của CBNV | C4: Bảng kê nhận lương
A5: 3 | B5: Bảng chấm công | C5: 3,BẢNG CHẤM CÔNG
A6: 4 | B6: Bảng phép năm 2025 | C6: Bảng phép năm 2023
A7: 5 | B7: Thông số tính lương | C7: Thông số TL
A8: 6 | B8: Bảng tính lương | C8: Bảng lương
A9: 7 | B9: Theo dõi Người phụ thuộc | C9: #'7.Danh sách NPT'!A1
A10: 8 | B10: Phiếu lương | C10: Phiếu lương

Sheet 1.ĐNTT LẦN 1
D1: CỘNG HOÀ XÃ HỘI CHỦ NGHĨA VIỆT NAM Độc lập - Tự do - Hạnh phúc
D2: ----------------------
M3: =IF(E3="","Hà Nội, Ngày 05 Tháng 08 Năm 2026",VLOOKUP(E3,'[23]NHẬP LIỆU'!B1:M29,2,0)) -> Hà Nội, Ngày 05 Tháng 08 Năm 2026
H5: ĐỀ NGHỊ THANH TOÁN
C6: Kính gửi: | D6: - Ban lãnh đạo Công ty cổ phần MS14 - Bộ phận kế toán của công ty
C7: Họ và tên người đề nghị: Nguyễn Thị Thu Hảo
C8: Bộ phận: | D8: Vận hành
C9: Nội dung thanh toán: MS14 thanh toán lương CBNV MS14 tháng 07/2026
C11: Nội dung thanh toán | N11: Thành tiền
C12: MS14 thanh toán lương CBNV MS14 tháng 07/2026 Danh sách cụ thể đính kèm. | N12: ='2. DS TKNH L1'!G18 -> 168977100
C13: Tổng tiền thanh toán | N13: =N12 -> 168977100
C14: Bằng chữ:
C15: =" Đề nghị Ban lãnh đạo và phòng kế toán phê duyệt để thanh toán số tiền nêu trên. Chi tiết cụ thể như số liệu đã đề cập." -> Đề nghị Ban lãnh đạo và phòng kế toán phê duyệt để thanh toán số tiền nêu trên. Chi tiết cụ thể như số liệu đã đề cập.
C16: Phương thức thanh toán: | H16: Tiền mặt | L16: FALSE
H17: Chuyển khoản | L17: TRUE
C18: Thông tin chuyển khoản:
C19: - Chủ tài khoản: | F19: Theo danh sách đính kèm
C20: - Số tài khoản : | F20: Theo danh sách đính kèm
C21: - Ngân hàng: | F21: Theo danh sách đính kèm
A23: Tổng Giám đốc | F23: Phòng TCKT | N23: Phòng HCNS | V23: Người lập

Sheet 2. DS TKNH L1
C1: BẢNG KÊ DANH SÁCH THANH TOÁN LƯƠNG THÁNG 07.2026
C2: Nội dung: MS14 thanh toán lương cho nhân sự MS14 Tháng 07.2026
A3: STT | B3: Mã NV | C3: Họ và tên | D3: Số tài khoản | E3: Ngân hàng | F3: Chi nhánh | G3: Số tiền thanh toán
A4: =SUBTOTAL(3,$C$3:C3) -> 1 | B4: MS04 | C4: =VLOOKUP(B4,'6.Bảng lương '!B15:$C$16,2,0) -> Nguyễn Thị Thu Hảo | D4: 19035531863010 | E4: Techcombank | G4: =VLOOKUP($B4,'6.Bảng lương '!$B$11:$AV$30,47,0) -> 12082100
A5: =SUBTOTAL(3,$C$3:C4) -> 2 | B5: MS02 | C5: =VLOOKUP(B5,'6.Bảng lương '!B12:$C$12,2,0) -> Bùi Thanh Anh | D5: 1978555558 | E5: ACB | G5: =VLOOKUP($B5,'6.Bảng lương '!$B$11:$AV$30,47,0) -> 15000000
A6: =SUBTOTAL(3,$C$3:C5) -> 3 | B6: MS06 | C6: =VLOOKUP(B6,'6.Bảng lương '!B$16:$C22,2,0) -> Eugene | D6: 1045887952 | E6: Vietcombank | G6: =VLOOKUP($B6,'6.Bảng lương '!$B$11:$AV$30,47,0)-7717000 -> 32921700 | H6: Giữ lại 7.717.000 tiền phí dịch vụ làm WP, TRC
A7: =SUBTOTAL(3,$C$3:C6) -> 4 | B7: MS07 | C7: =VLOOKUP(B7,'6.Bảng lương '!B$16:$C23,2,0) -> Nguyễn Ánh Hồng | D7: 1033638061 | E7: Vietcombank | G7: =VLOOKUP($B7,'6.Bảng lương '!$B$11:$AV$30,47,0) -> 9000000
A8: =SUBTOTAL(3,$C$3:C7) -> 5 | B8: MS09 | C8: =VLOOKUP(B8,'6.Bảng lương '!$B$12:$C$23,2,0) -> Nguyễn Thị Thu | D8: 1991555558 | E8: ACB | G8: =VLOOKUP($B8,'6.Bảng lương '!$B$11:$AV$30,47,0) -> 8000000
A9: =SUBTOTAL(3,$C$3:C8) -> 6 | B9: MS11 | C9: =VLOOKUP(B9,' 5. Thông số TL'!$D$12:$E$25,2,0) -> Phùng Thị Lụa | D9: 0563250894 | E9: MB | G9: =VLOOKUP($B9,'6.Bảng lương '!$B$11:$AV$30,47,0) -> 9000000
A10: =SUBTOTAL(3,$C$3:C9) -> 7 | B10: MS12 | C10: =VLOOKUP(B10,' 5. Thông số TL'!$D$12:$E$25,2,0) -> Đinh Thị Bích Ngọc | D10: 19032824127018 | E10: Techcombank | G10: =VLOOKUP($B10,'6.Bảng lương '!$B$11:$AV$30,47,0) -> 7000000
A11: =SUBTOTAL(3,$C$3:C10) -> 8 | B11: MS13 | C11: =VLOOKUP(B11,' 5. Thông số TL'!$D$12:$E$25,2,0) -> Lương Văn Châm | D11: 9904677976 | E11: Techcombank | G11: =VLOOKUP($B11,'6.Bảng lương '!$B$11:$AV$30,47,0) -> 10000000
A12: =SUBTOTAL(3,$C$3:C11) -> 9 | B12: MS14 | C12: =VLOOKUP(B12,' 5. Thông số TL'!$D$12:$E$25,2,0) -> Nguyễn Thị Phúc | D12: 1036236348 | E12: VCB | G12: =VLOOKUP($B12,'6.Bảng lương '!$B$11:$AV$30,47,0) -> 10000000
A13: =SUBTOTAL(3,$C$3:C12) -> 10 | B13: MS20 | C13: Nguyễn Thị Thu Hiền | D13: 19021081619016 | E13: Techcombank | G13: =VLOOKUP($B13,'6.Bảng lương '!$B$11:$AV$30,47,0) -> 9000000
A14: =SUBTOTAL(3,$C$3:C13) -> 11 | B14: MS21 | C14: Triệu Thị Thu | D14: 150822666999 | E14: Techcombank | G14: =VLOOKUP($B14,'6.Bảng lương '!$B$11:$AV$30,47,0) -> 12000000
A15: =SUBTOTAL(3,$C$3:C14) -> 12 | B15: MS22 | C15: Nguyễn Thị Hằng | D15: 19031171516025 | E15: Techcombank | G15: =VLOOKUP($B15,'6.Bảng lương '!$B$11:$AV$30,47,0) -> 11000000
A16: =SUBTOTAL(3,$C$3:C15) -> 13 | B16: MS23 | C16: Hoàng Thị Ánh Mão | D16: 19024964658010 | E16: Techcombank | G16: =VLOOKUP($B16,'6.Bảng lương '!$B$11:$AV$30,47,0) -> 9505700
A17: =SUBTOTAL(3,$C$3:C16) -> 14 | B17: MS24 | C17: Trương Hoàng Diễm | D17: 8819922368 | E17: VPBank | G17: =VLOOKUP($B17,'6.Bảng lương '!$B$11:$AV$30,47,0) -> 14467600
A18: Tổng | G18: =SUM(G4:G17) -> 168977100
E21: Hà Nội, ngày 05 tháng 08 năm 2026
A23: TỔNG GIÁM ĐỐC | C23: PHÒNG TÀI CHÍNH - KẾ TOÁN | E23: PHÒNG HCNS | F23: NGƯỜI LẬP

Sheet 3. BẢNG CHẤM CÔNG
C1: TÊN ĐƠN VỊ: CÔNG TY CỔ PHẦN MS14 ĐỊA CHỈ: Clubhouse 3 đường Phong Lan 1, khu đô thị Vinhomes Riverside, phường Phúc Lợi, thành phố Hà Nội MST: 0111258406
I2: Tháng | K2: 7 | M2: Bảng Ký Hiệu Các Loại Ngày Công
M3: Loại | O3: Đủ Công | P3: Nửa Ngày | Q3: Online | R3: Online nửa ngày | S3: Phép | T3: Nửa phép | U3: Làm việc CN, T7 | V3: Làm việc nửa CN/T7 | X3: Ngày Lễ | Y3: Nửa ngày lễ | Z3: Không Lương | AB3: Thai sản
I4: Năm | K4: 2026
M5: Ký Hiệu | O5: X | P5: N1 | Q5: On | R5: On/2 | S5: P | T5: P1 | U5: C | V5: C/2 | X5: L | Y5: L1 | Z5: K | AB5: TS
A6: MS14 - BẢNG CHẤM CÔNG THÁNG 06/2026
H7: 8 | I7: =1+H7 -> 9 | J7: =1+I7 -> 10 | K7: =1+J7 -> 11 | L7: =1+K7 -> 12 | M7: =1+L7 -> 13 | N7: =1+M7 -> 14 | O7: =1+N7 -> 15 | P7: =1+O7 -> 16 | ... AN7: =1+AM7 -> 40 | AP7: =1+AN7 -> 41 | AQ7: =1+AP7 -> 42 | AR7: =1+AQ7 -> 43 | AS7: =1+AR7 -> 44 | AT7: =1+AS7 -> 45 | AU7: =1+AT7 -> 46 | AV7: =1+AU7 -> 47
H8: =DATE(K4,K2,1) -> 46204 | I8: =H8+1 -> 46205 | J8: =I8+1 -> 46206 | K8: =J8+1 -> 46207 | L8: =K8+1 -> 46208 | M8: =L8+1 -> 46209 | N8: =M8+1 -> 46210 | O8: =N8+1 -> 46211 | P8: =O8+1 -> 46212 | ... AL8: =AK8+1 -> 46234 | AM8: X | AN8: N1 | AO8: ON | AP8: C | AQ8: P + P1 | AR8: Tổng Công đi làm & nghỉ phép | AS8: L | AT8: K | AU8: Số công full tháng | AV8: ="Phép Tồn năm 2023 tính đến T."&K2 -> Phép Tồn năm 2023 tính đến T.7
H9: =CHOOSE(WEEKDAY(H8),"Chủ Nhật","Thứ Hai","Thứ Ba","Thứ Tư","Thứ Năm","Thứ Sáu","Thứ Bảy") -> Thứ Tư | I9: =CHOOSE(WEEKDAY(I8),"Chủ Nhật","Thứ Hai","Thứ Ba","Thứ Tư","Thứ Năm","Thứ Sáu","Thứ Bảy") -> Thứ Năm | J9: =CHOOSE(WEEKDAY(J8),"Chủ Nhật","Thứ Hai","Thứ Ba","Thứ Tư","Thứ Năm","Thứ Sáu","Thứ Bảy") -> Thứ Sáu | K9: =CHOOSE(WEEKDAY(K8),"Chủ Nhật","Thứ Hai","Thứ Ba","Thứ Tư","Thứ Năm","Thứ Sáu","Thứ Bảy") -> Thứ Bảy | L9: =CHOOSE(WEEKDAY(L8),"Chủ Nhật","Thứ Hai","Thứ Ba","Thứ Tư","Thứ Năm","Thứ Sáu","Thứ Bảy") -> Chủ Nhật | M9: =CHOOSE(WEEKDAY(M8),"Chủ Nhật","Thứ Hai","Thứ Ba","Thứ Tư","Thứ Năm","Thứ Sáu","Thứ Bảy") -> Thứ Hai | N9: =CHOOSE(WEEKDAY(N8),"Chủ Nhật","Thứ Hai","Thứ Ba","Thứ Tư","Thứ Năm","Thứ Sáu","Thứ Bảy") -> Thứ Ba | O9: =CHOOSE(WEEKDAY(O8),"Chủ Nhật","Thứ Hai","Thứ Ba","Thứ Tư","Thứ Năm","Thứ Sáu","Thứ Bảy") -> Thứ Tư | ... AL9: =CHOOSE(WEEKDAY(AL8),"Chủ Nhật","Thứ Hai","Thứ Ba","Thứ Tư","Thứ Năm","Thứ Sáu","Thứ Bảy") -> Thứ Sáu | AM9: Đủ công | AN9: Nửa Công | AO9: Làm online | AP9: Làm việc CN, T7 | AQ9: Phép | AS9: Lễ Tết | AT9: Không Lương
A10: STT | B10: Mã NV | C10: Phòng ban | D10: Chức danh | E10: Tầng nhân sự | F10: Họ & Tên | G10: Tình Trạng | AR10: =SUM(AR12:AR30) -> 534 | AT10: =SUM(AT12:AT30) -> 60
A11: =SUBTOTAL(3,$F$11:F11) -> 1 | B11: MS04 | C11: Vận hành | D11: Trưởng phòng vận hành | F11: Nguyễn Thị Thu Hảo | G11: Chính Thức | H11: X | I11: X | J11: X | M11: X | N11: X | O11: X | P11: X | Q11: X | T11: X | U11: X | V11: X | W11: P | X11: P | AA11: P | AB11: On | AC11: On | AD11: On | AE11: On | AH11: On | AI11: On | AJ11: On | AK11: On | AL11: On | AM11: =IF(F11="","",COUNTIF($H11:$AL11,AM$8)) -> 11 | AN11: =IF(OR(G11="",G11="Đã nghỉ"),0,COUNTIF($H11:$AL11,"N1")/2++IF(AND(LEN(H11)>2,OR(LEFT(H11,2)="N1",RIGHT(H11,2)="N1")),0.5)+IF(AND(LEN(I11)>2,OR(LEFT(I11,2)="N1",RIGHT(I11,2)="N1")),0.5)+IF(AND(LEN(J11)>2,OR(LEFT(J11,2)="N1",RIGHT(J11,2)="N1")),0.5)+IF(AND(LEN(K11)>2,OR(LEFT(K11,2)="N1",RIGHT(K11,2)="N1")),0.5)+IF(AND(LEN(L11)>2,OR(LEFT(L11,2)="N1",RIGHT(L11,2)="N1")),0.5)+IF(AND(LEN(M11)>2,OR(LEFT(M11,2)="N1",RIGHT(M11,2)="N1")),0.5)+IF(AND(LEN(N11)>2,OR(LEFT(N11,2)="N1",RIGHT(N11,2)="N1")),0.5)+IF(AND(LEN(O11)>2,OR(LEFT(O11,2)="N1",RIGHT(O11,2)="N1")),0.5)+IF(AND(LEN(P11)>2,OR(LEFT(P11,2)="N1",RIGHT(P11,2)="N1")),0.5)+IF(AND(LEN(Q11)>2,OR(LEFT(Q11,2)="N1",RIGHT(Q11,2)="N1")),0.5)+IF(AND(LEN(R11)>2,OR(LEFT(R11,2)="N1",RIGHT(R11,2)="N1")),0.5)+IF(AND(LEN(S11)>2,OR(LEFT(S11,2)="N1",RIGHT(S11,2)="N1")),0.5)+IF(AND(LEN(T11)>2,OR(LEFT(T11,2)="N1",RIGHT(T11,2)="N1")),0.5)+IF(AND(LEN(U11)>2,OR(LEFT(U11,2)="N1",RIGHT(U11,2)="N1")),0.5)+IF(AND(LEN(V11)>2,OR(LEFT(V11,2)="N1",RIGHT(V11,2)="N1")),0.5)+IF(AND(LEN(W11)>2,OR(LEFT(W11,2)="N1",RIGHT(W11,2)="N1")),0.5)+IF(AND(LEN(X11)>2,OR(LEFT(X11,2)="N1",RIGHT(X11,2)="N1")),0.5)+IF(AND(LEN(Y11)>2,OR(LEFT(Y11,2)="N1",RIGHT(Y11,2)="N1")),0.5)+IF(AND(LEN(Z11)>2,OR(LEFT(Z11,2)="N1",RIGHT(Z11,2)="N1")),0.5)+IF(AND(LEN(AA11)>2,OR(LEFT(AA11,2)="N1",RIGHT(AA11,2)="N1")),0.5)+IF(AND(LEN(AB11)>2,OR(LEFT(AB11,2)="N1",RIGHT(AB11,2)="N1")),0.5)+IF(AND(LEN(AC11)>2,OR(LEFT(AC11,2)="N1",RIGHT(AC11,2)="N1")),0.5)+IF(AND(LEN(AD11)>2,OR(LEFT(AD11,2)="N1",RIGHT(AD11,2)="N1")),0.5)+IF(AND(LEN(AE11)>2,OR(LEFT(AE11,2)="N1",RIGHT(AE11,2)="N1")),0.5)+IF(AND(LEN(AF11)>2,OR(LEFT(AF11,2)="N1",RIGHT(AF11,2)="N1")),0.5)+IF(AND(LEN(AG11)>2,OR(LEFT(AG11,2)="N1",RIGHT(AG11,2)="N1")),0.5)+IF(AND(LEN(AH11)>2,OR(LEFT(AH11,2)="N1",RIGHT(AH11,2)="N1")),0.5)+IF(AND(LEN(AI11)>2,OR(LEFT(AI11,2)="N1",RIGHT(AI11,2)="N1")),0.5)+IF(AND(LEN(AJ11)>2,OR(LEFT(AJ11,2)="N1",RIGHT(AJ11,2)="N1")),0.5)+IF(AND(LEN(AK11)>2,OR(LEFT(AK11,2)="N1",RIGHT(AK11,2)="N1")),0.5)+IF(AND(LEN(AL11)>2,OR(LEFT(AL11,2)="N1",RIGHT(AL11,2)="N1")),0.5)) -> 0 | AO11: =COUNTIF(H11:AL11,"ON")+COUNTIF(H11:AL11,"ON/2")/2 -> 9 | AP11: =IF(F11="","",COUNTIF($H11:$AL11,AP$8))+IF(F11="","",COUNTIF($H11:$AL11,$V$5)/2) -> 0 | AQ11: =COUNTIF($H11:$AL11,"P")+COUNTIF($H11:$AL11,"P1")/2+IF(AND(LEN(I11)>2,OR(LEFT(I11,2)="P1",RIGHT(I11,2)="P1")),0.5)+IF(AND(LEN(J11)>2,OR(LEFT(J11,2)="P1",RIGHT(J11,2)="P1")),0.5)+IF(AND(LEN(K11)>2,OR(LEFT(K11,2)="P1",RIGHT(K11,2)="P1")),0.5)+IF(AND(LEN(L11)>2,OR(LEFT(L11,2)="P1",RIGHT(L11,2)="P1")),0.5)+IF(AND(LEN(M11)>2,OR(LEFT(M11,2)="P1",RIGHT(M11,2)="P1")),0.5)+IF(AND(LEN(N11)>2,OR(LEFT(N11,2)="P1",RIGHT(N11,2)="P1")),0.5)+IF(AND(LEN(O11)>2,OR(LEFT(O11,2)="P1",RIGHT(O11,2)="P1")),0.5)+IF(AND(LEN(P11)>2,OR(LEFT(P11,2)="P1",RIGHT(P11,2)="P1")),0.5)+IF(AND(LEN(Q11)>2,OR(LEFT(Q11,2)="P1",RIGHT(Q11,2)="P1")),0.5)+IF(AND(LEN(R11)>2,OR(LEFT(R11,2)="P1",RIGHT(R11,2)="P1")),0.5)+IF(AND(LEN(S11)>2,OR(LEFT(S11,2)="P1",RIGHT(S11,2)="P1")),0.5)+IF(AND(LEN(T11)>2,OR(LEFT(T11,2)="P1",RIGHT(T11,2)="P1")),0.5)+IF(AND(LEN(U11)>2,OR(LEFT(U11,2)="P1",RIGHT(U11,2)="P1")),0.5)+IF(AND(LEN(V11)>2,OR(LEFT(V11,2)="P1",RIGHT(V11,2)="P1")),0.5)+IF(AND(LEN(W11)>2,OR(LEFT(W11,2)="P1",RIGHT(W11,2)="P1")),0.5)+IF(AND(LEN(X11)>2,OR(LEFT(X11,2)="P1",RIGHT(X11,2)="P1")),0.5)+IF(AND(LEN(Y11)>2,OR(LEFT(Y11,2)="P1",RIGHT(Y11,2)="P1")),0.5)+IF(AND(LEN(Z11)>2,OR(LEFT(Z11,2)="P1",RIGHT(Z11,2)="P1")),0.5)+IF(AND(LEN(AA11)>2,OR(LEFT(AA11,2)="P1",RIGHT(AA11,2)="P1")),0.5)+IF(AND(LEN(AB11)>2,OR(LEFT(AB11,2)="P1",RIGHT(AB11,2)="P1")),0.5)+IF(AND(LEN(AC11)>2,OR(LEFT(AC11,2)="P1",RIGHT(AC11,2)="P1")),0.5)+IF(AND(LEN(AD11)>2,OR(LEFT(AD11,2)="P1",RIGHT(AD11,2)="P1")),0.5)+IF(AND(LEN(AE11)>2,OR(LEFT(AE354,2)="P1",RIGHT(AE11,2)="P1")),0.5)+IF(AND(LEN(AF11)>2,OR(LEFT(AF11,2)="P1",RIGHT(AF11,2)="P1")),0.5)+IF(AND(LEN(AG11)>2,OR(LEFT(AG11,2)="P1",RIGHT(AG11,2)="P1")),0.5)+IF(AND(LEN(AH11)>2,OR(LEFT(AH11,2)="P1",RIGHT(AH11,2)="P1")),0.5)+IF(AND(LEN(AI11)>2,OR(LEFT(AI11,2)="P1",RIGHT(AI11,2)="P1")),0.5)+IF(AND(LEN(AJ11)>2,OR(LEFT(AJ11,2)="P1",RIGHT(AJ11,2)="P1")),0.5)+IF(AND(LEN(AK11)>2,OR(LEFT(AK11,2)="P1",RIGHT(AK11,2)="P1")),0.5)+IF(AND(LEN(AL11)>2,OR(LEFT(AL11,2)="P1",RIGHT(AL11,2)="P1")),0.5) -> 3 | AR11: =IF(G11="","",AM11+AN11+AP11+AQ11) -> 14 | AS11: =IF(F11="","",COUNTIF($H11:$AL11,AS$8))++IF(F11="","",COUNTIF($H11:$AL11,"L1")/2) -> 0 | AT11: =AU11-AR11-AS11 -> 9 | AU11: 23
A12: =SUBTOTAL(3,$F$11:F12) -> 2 | B12: MS07 | C12: Giáo viên | D12: Giáo viên mầm non | F12: Nguyễn Ánh Hồng | G12: Chính Thức | H12: X | I12: X | J12: X | M12: X | N12: X | O12: X | P12: X | Q12: X | T12: X | U12: X | V12: X | W12: X | X12: X | AA12: X | AB12: X | AC12: X | AD12: X | AE12: X | AH12: X | AI12: X | AJ12: X | AK12: X | AL12: X | AM12: =IF(F12="","",COUNTIF($H12:$AL12,AM$8)) -> 23 | AN12: =IF(OR(G12="",G12="Đã nghỉ"),0,COUNTIF($H12:$AL12,"N1")/2++IF(AND(LEN(H12)>2,OR(LEFT(H12,2)="N1",RIGHT(H12,2)="N1")),0.5)+IF(AND(LEN(I12)>2,OR(LEFT(I12,2)="N1",RIGHT(I12,2)="N1")),0.5)+IF(AND(LEN(J12)>2,OR(LEFT(J12,2)="N1",RIGHT(J12,2)="N1")),0.5)+IF(AND(LEN(K12)>2,OR(LEFT(K12,2)="N1",RIGHT(K12,2)="N1")),0.5)+IF(AND(LEN(L12)>2,OR(LEFT(L12,2)="N1",RIGHT(L12,2)="N1")),0.5)+IF(AND(LEN(M12)>2,OR(LEFT(M12,2)="N1",RIGHT(M12,2)="N1")),0.5)+IF(AND(LEN(N12)>2,OR(LEFT(N12,2)="N1",RIGHT(N12,2)="N1")),0.5)+IF(AND(LEN(O12)>2,OR(LEFT(O12,2)="N1",RIGHT(O12,2)="N1")),0.5)+IF(AND(LEN(P12)>2,OR(LEFT(P12,2)="N1",RIGHT(P12,2)="N1")),0.5)+IF(AND(LEN(Q12)>2,OR(LEFT(Q12,2)="N1",RIGHT(Q12,2)="N1")),0.5)+IF(AND(LEN(R12)>2,OR(LEFT(R12,2)="N1",RIGHT(R12,2)="N1")),0.5)+IF(AND(LEN(S12)>2,OR(LEFT(S12,2)="N1",RIGHT(S12,2)="N1")),0.5)+IF(AND(LEN(T12)>2,OR(LEFT(T12,2)="N1",RIGHT(T12,2)="N1")),0.5)+IF(AND(LEN(U12)>2,OR(LEFT(U12,2)="N1",RIGHT(U12,2)="N1")),0.5)+IF(AND(LEN(V12)>2,OR(LEFT(V12,2)="N1",RIGHT(V12,2)="N1")),0.5)+IF(AND(LEN(W12)>2,OR(LEFT(W12,2)="N1",RIGHT(W12,2)="N1")),0.5)+IF(AND(LEN(X12)>2,OR(LEFT(X12,2)="N1",RIGHT(X12,2)="N1")),0.5)+IF(AND(LEN(Y12)>2,OR(LEFT(Y12,2)="N1",RIGHT(Y12,2)="N1")),0.5)+IF(AND(LEN(Z12)>2,OR(LEFT(Z12,2)="N1",RIGHT(Z12,2)="N1")),0.5)+IF(AND(LEN(AA12)>2,OR(LEFT(AA12,2)="N1",RIGHT(AA12,2)="N1")),0.5)+IF(AND(LEN(AB12)>2,OR(LEFT(AB12,2)="N1",RIGHT(AB12,2)="N1")),0.5)+IF(AND(LEN(AC12)>2,OR(LEFT(AC12,2)="N1",RIGHT(AC12,2)="N1")),0.5)+IF(AND(LEN(AD12)>2,OR(LEFT(AD12,2)="N1",RIGHT(AD12,2)="N1")),0.5)+IF(AND(LEN(AE12)>2,OR(LEFT(AE12,2)="N1",RIGHT(AE12,2)="N1")),0.5)+IF(AND(LEN(AF12)>2,OR(LEFT(AF12,2)="N1",RIGHT(AF12,2)="N1")),0.5)+IF(AND(LEN(AG12)>2,OR(LEFT(AG12,2)="N1",RIGHT(AG12,2)="N1")),0.5)+IF(AND(LEN(AH12)>2,OR(LEFT(AH12,2)="N1",RIGHT(AH12,2)="N1")),0.5)+IF(AND(LEN(AI12)>2,OR(LEFT(AI12,2)="N1",RIGHT(AI12,2)="N1")),0.5)+IF(AND(LEN(AJ12)>2,OR(LEFT(AJ12,2)="N1",RIGHT(AJ12,2)="N1")),0.5)+IF(AND(LEN(AK12)>2,OR(LEFT(AK12,2)="N1",RIGHT(AK12,2)="N1")),0.5)+IF(AND(LEN(AL12)>2,OR(LEFT(AL12,2)="N1",RIGHT(AL12,2)="N1")),0.5)) -> 0 | AO12: =COUNTIF(H12:AL12,"ON")+COUNTIF(H12:AL12,"ON/2")/2 -> 0 | AP12: =IF(F12="","",COUNTIF($H12:$AL12,AP$8))+IF(F12="","",COUNTIF($H12:$AL12,$V$5)/2) -> 0 | AQ12: =COUNTIF($H12:$AL12,"P")+COUNTIF($H12:$AL12,"P1")/2+IF(AND(LEN(I12)>2,OR(LEFT(I12,2)="P1",RIGHT(I12,2)="P1")),0.5)+IF(AND(LEN(J12)>2,OR(LEFT(J12,2)="P1",RIGHT(J12,2)="P1")),0.5)+IF(AND(LEN(K12)>2,OR(LEFT(K12,2)="P1",RIGHT(K12,2)="P1")),0.5)+IF(AND(LEN(L12)>2,OR(LEFT(L12,2)="P1",RIGHT(L12,2)="P1")),0.5)+IF(AND(LEN(M12)>2,OR(LEFT(M12,2)="P1",RIGHT(M12,2)="P1")),0.5)+IF(AND(LEN(N12)>2,OR(LEFT(N12,2)="P1",RIGHT(N12,2)="P1")),0.5)+IF(AND(LEN(O12)>2,OR(LEFT(O12,2)="P1",RIGHT(O12,2)="P1")),0.5)+IF(AND(LEN(P12)>2,OR(LEFT(P12,2)="P1",RIGHT(P12,2)="P1")),0.5)+IF(AND(LEN(Q12)>2,OR(LEFT(Q12,2)="P1",RIGHT(Q12,2)="P1")),0.5)+IF(AND(LEN(R12)>2,OR(LEFT(R12,2)="P1",RIGHT(R12,2)="P1")),0.5)+IF(AND(LEN(S12)>2,OR(LEFT(S12,2)="P1",RIGHT(S12,2)="P1")),0.5)+IF(AND(LEN(T12)>2,OR(LEFT(T12,2)="P1",RIGHT(T12,2)="P1")),0.5)+IF(AND(LEN(U12)>2,OR(LEFT(U12,2)="P1",RIGHT(U12,2)="P1")),0.5)+IF(AND(LEN(V12)>2,OR(LEFT(V12,2)="P1",RIGHT(V12,2)="P1")),0.5)+IF(AND(LEN(W12)>2,OR(LEFT(W12,2)="P1",RIGHT(W12,2)="P1")),0.5)+IF(AND(LEN(X12)>2,OR(LEFT(X12,2)="P1",RIGHT(X12,2)="P1")),0.5)+IF(AND(LEN(Y12)>2,OR(LEFT(Y12,2)="P1",RIGHT(Y12,2)="P1")),0.5)+IF(AND(LEN(Z12)>2,OR(LEFT(Z12,2)="P1",RIGHT(Z12,2)="P1")),0.5)+IF(AND(LEN(AA12)>2,OR(LEFT(AA12,2)="P1",RIGHT(AA12,2)="P1")),0.5)+IF(AND(LEN(AB12)>2,OR(LEFT(AB12,2)="P1",RIGHT(AB12,2)="P1")),0.5)+IF(AND(LEN(AC12)>2,OR(LEFT(AC12,2)="P1",RIGHT(AC12,2)="P1")),0.5)+IF(AND(LEN(AD12)>2,OR(LEFT(AD12,2)="P1",RIGHT(AD12,2)="P1")),0.5)+IF(AND(LEN(AE12)>2,OR(LEFT(AE356,2)="P1",RIGHT(AE12,2)="P1")),0.5)+IF(AND(LEN(AF12)>2,OR(LEFT(AF12,2)="P1",RIGHT(AF12,2)="P1")),0.5)+IF(AND(LEN(AG12)>2,OR(LEFT(AG12,2)="P1",RIGHT(AG12,2)="P1")),0.5)+IF(AND(LEN(AH12)>2,OR(LEFT(AH12,2)="P1",RIGHT(AH12,2)="P1")),0.5)+IF(AND(LEN(AI12)>2,OR(LEFT(AI12,2)="P1",RIGHT(AI12,2)="P1")),0.5)+IF(AND(LEN(AJ12)>2,OR(LEFT(AJ12,2)="P1",RIGHT(AJ12,2)="P1")),0.5)+IF(AND(LEN(AK12)>2,OR(LEFT(AK12,2)="P1",RIGHT(AK12,2)="P1")),0.5)+IF(AND(LEN(AL12)>2,OR(LEFT(AL12,2)="P1",RIGHT(AL12,2)="P1")),0.5) -> 0 | AR12: =IF(G12="","",AM12+AN12+AP12+AQ12) -> 23 | AS12: =IF(F12="","",COUNTIF($H12:$AL12,AS$8))++IF(F12="","",COUNTIF($H12:$AL12,"L1")/2) -> 0 | AT12: =AU12-AR12-AS12 -> 0 | AU12: 23
A13: =SUBTOTAL(3,$F$11:F13) -> 3 | B13: MS06 | C13: Giáo viên | D13: Giáo viên nước ngoài | F13: Eugene | G13: Chính Thức | H13: X | I13: N1 | J13: X | M13: X | N13: X | O13: X | P13: X | Q13: X | T13: X | U13: X | V13: X | W13: P | X13: K | AA13: X | AB13: X | AC13: K | AD13: X | AE13: X | AH13: X | AI13: X | AJ13: X | AK13: X | AL13: X | AM13: =IF(F13="","",COUNTIF($H13:$AL13,AM$8)) -> 19 | AN13: =IF(OR(G13="",G13="Đã nghỉ"),0,COUNTIF($H13:$AL13,"N1")/2++IF(AND(LEN(H13)>2,OR(LEFT(H13,2)="N1",RIGHT(H13,2)="N1")),0.5)+IF(AND(LEN(I13)>2,OR(LEFT(I13,2)="N1",RIGHT(I13,2)="N1")),0.5)+IF(AND(LEN(J13)>2,OR(LEFT(J13,2)="N1",RIGHT(J13,2)="N1")),0.5)+IF(AND(LEN(K13)>2,OR(LEFT(K13,2)="N1",RIGHT(K13,2)="N1")),0.5)+IF(AND(LEN(L13)>2,OR(LEFT(L13,2)="N1",RIGHT(L13,2)="N1")),0.5)+IF(AND(LEN(M13)>2,OR(LEFT(M13,2)="N1",RIGHT(M13,2)="N1")),0.5)+IF(AND(LEN(N13)>2,OR(LEFT(N13,2)="N1",RIGHT(N13,2)="N1")),0.5)+IF(AND(LEN(O13)>2,OR(LEFT(O13,2)="N1",RIGHT(O13,2)="N1")),0.5)+IF(AND(LEN(P13)>2,OR(LEFT(P13,2)="N1",RIGHT(P13,2)="N1")),0.5)+IF(AND(LEN(Q13)>2,OR(LEFT(Q13,2)="N1",RIGHT(Q13,2)="N1")),0.5)+IF(AND(LEN(R13)>2,OR(LEFT(R13,2)="N1",RIGHT(R13,2)="N1")),0.5)+IF(AND(LEN(S13)>2,OR(LEFT(S13,2)="N1",RIGHT(S13,2)="N1")),0.5)+IF(AND(LEN(T13)>2,OR(LEFT(T13,2)="N1",RIGHT(T13,2)="N1")),0.5)+IF(AND(LEN(U13)>2,OR(LEFT(U13,2)="N1",RIGHT(U13,2)="N1")),0.5)+IF(AND(LEN(V13)>2,OR(LEFT(V13,2)="N1",RIGHT(V13,2)="N1")),0.5)+IF(AND(LEN(W13)>2,OR(LEFT(W13,2)="N1",RIGHT(W13,2)="N1")),0.5)+IF(AND(LEN(X13)>2,OR(LEFT(X13,2)="N1",RIGHT(X13,2)="N1")),0.5)+IF(AND(LEN(Y13)>2,OR(LEFT(Y13,2)="N1",RIGHT(Y13,2)="N1")),0.5)+IF(AND(LEN(Z13)>2,OR(LEFT(Z13,2)="N1",RIGHT(Z13,2)="N1")),0.5)+IF(AND(LEN(AA13)>2,OR(LEFT(AA13,2)="N1",RIGHT(AA13,2)="N1")),0.5)+IF(AND(LEN(AB13)>2,OR(LEFT(AB13,2)="N1",RIGHT(AB13,2)="N1")),0.5)+IF(AND(LEN(AC13)>2,OR(LEFT(AC13,2)="N1",RIGHT(AC13,2)="N1")),0.5)+IF(AND(LEN(AD13)>2,OR(LEFT(AD13,2)="N1",RIGHT(AD13,2)="N1")),0.5)+IF(AND(LEN(AE13)>2,OR(LEFT(AE13,2)="N1",RIGHT(AE13,2)="N1")),0.5)+IF(AND(LEN(AF13)>2,OR(LEFT(AF13,2)="N1",RIGHT(AF13,2)="N1")),0.5)+IF(AND(LEN(AG13)>2,OR(LEFT(AG13,2)="N1",RIGHT(AG13,2)="N1")),0.5)+IF(AND(LEN(AH13)>2,OR(LEFT(AH13,2)="N1",RIGHT(AH13,2)="N1")),0.5)+IF(AND(LEN(AI13)>2,OR(LEFT(AI13,2)="N1",RIGHT(AI13,2)="N1")),0.5)+IF(AND(LEN(AJ13)>2,OR(LEFT(AJ13,2)="N1",RIGHT(AJ13,2)="N1")),0.5)+IF(AND(LEN(AK13)>2,OR(LEFT(AK13,2)="N1",RIGHT(AK13,2)="N1")),0.5)+IF(AND(LEN(AL13)>2,OR(LEFT(AL13,2)="N1",RIGHT(AL13,2)="N1")),0.5)) -> 0.5 | AO13: =COUNTIF(H13:AL13,"ON")+COUNTIF(H13:AL13,"ON/2")/2 -> 0 | AP13: =IF(F13="","",COUNTIF($H13:$AL13,AP$8))+IF(F13="","",COUNTIF($H13:$AL13,$V$5)/2) -> 0 | AQ13: =COUNTIF($H13:$AL13,"P")+COUNTIF($H13:$AL13,"P1")/2+IF(AND(LEN(I13)>2,OR(LEFT(I13,2)="P1",RIGHT(I13,2)="P1")),0.5)+IF(AND(LEN(J13)>2,OR(LEFT(J13,2)="P1",RIGHT(J13,2)="P1")),0.5)+IF(AND(LEN(K13)>2,OR(LEFT(K13,2)="P1",RIGHT(K13,2)="P1")),0.5)+IF(AND(LEN(L13)>2,OR(LEFT(L13,2)="P1",RIGHT(L13,2)="P1")),0.5)+IF(AND(LEN(M13)>2,OR(LEFT(M13,2)="P1",RIGHT(M13,2)="P1")),0.5)+IF(AND(LEN(N13)>2,OR(LEFT(N13,2)="P1",RIGHT(N13,2)="P1")),0.5)+IF(AND(LEN(O13)>2,OR(LEFT(O13,2)="P1",RIGHT(O13,2)="P1")),0.5)+IF(AND(LEN(P13)>2,OR(LEFT(P13,2)="P1",RIGHT(P13,2)="P1")),0.5)+IF(AND(LEN(Q13)>2,OR(LEFT(Q13,2)="P1",RIGHT(Q13,2)="P1")),0.5)+IF(AND(LEN(R13)>2,OR(LEFT(R13,2)="P1",RIGHT(R13,2)="P1")),0.5)+IF(AND(LEN(S13)>2,OR(LEFT(S13,2)="P1",RIGHT(S13,2)="P1")),0.5)+IF(AND(LEN(T13)>2,OR(LEFT(T13,2)="P1",RIGHT(T13,2)="P1")),0.5)+IF(AND(LEN(U13)>2,OR(LEFT(U13,2)="P1",RIGHT(U13,2)="P1")),0.5)+IF(AND(LEN(V13)>2,OR(LEFT(V13,2)="P1",RIGHT(V13,2)="P1")),0.5)+IF(AND(LEN(W13)>2,OR(LEFT(W13,2)="P1",RIGHT(W13,2)="P1")),0.5)+IF(AND(LEN(X13)>2,OR(LEFT(X13,2)="P1",RIGHT(X13,2)="P1")),0.5)+IF(AND(LEN(Y13)>2,OR(LEFT(Y13,2)="P1",RIGHT(Y13,2)="P1")),0.5)+IF(AND(LEN(Z13)>2,OR(LEFT(Z13,2)="P1",RIGHT(Z13,2)="P1")),0.5)+IF(AND(LEN(AA13)>2,OR(LEFT(AA13,2)="P1",RIGHT(AA13,2)="P1")),0.5)+IF(AND(LEN(AB13)>2,OR(LEFT(AB13,2)="P1",RIGHT(AB13,2)="P1")),0.5)+IF(AND(LEN(AC13)>2,OR(LEFT(AC13,2)="P1",RIGHT(AC13,2)="P1")),0.5)+IF(AND(LEN(AD13)>2,OR(LEFT(AD13,2)="P1",RIGHT(AD13,2)="P1")),0.5)+IF(AND(LEN(AE13)>2,OR(LEFT(AE357,2)="P1",RIGHT(AE13,2)="P1")),0.5)+IF(AND(LEN(AF13)>2,OR(LEFT(AF13,2)="P1",RIGHT(AF13,2)="P1")),0.5)+IF(AND(LEN(AG13)>2,OR(LEFT(AG13,2)="P1",RIGHT(AG13,2)="P1")),0.5)+IF(AND(LEN(AH13)>2,OR(LEFT(AH13,2)="P1",RIGHT(AH13,2)="P1")),0.5)+IF(AND(LEN(AI13)>2,OR(LEFT(AI13,2)="P1",RIGHT(AI13,2)="P1")),0.5)+IF(AND(LEN(AJ13)>2,OR(LEFT(AJ13,2)="P1",RIGHT(AJ13,2)="P1")),0.5)+IF(AND(LEN(AK13)>2,OR(LEFT(AK13,2)="P1",RIGHT(AK13,2)="P1")),0.5)+IF(AND(LEN(AL13)>2,OR(LEFT(AL13,2)="P1",RIGHT(AL13,2)="P1")),0.5) -> 1 | AR13: =IF(G13="","",AM13+AN13+AP13+AQ13) -> 20.5 | AS13: =IF(F13="","",COUNTIF($H13:$AL13,AS$8))++IF(F13="","",COUNTIF($H13:$AL13,"L1")/2) -> 0 | AT13: =AU13-AR13-AS13 -> 2.5 | AU13: 23
A14: =SUBTOTAL(3,$F$11:F14) -> 4 | B14: MS09 | C14: BGH | D14: Quản lý chương trình TA | F14: Nguyễn Thị Thu | G14: Chính Thức | H14: X | I14: X | J14: X | M14: X | N14: X | O14: X | P14: X | Q14: X | T14: X | U14: X | V14: X | W14: X | X14: X | AA14: X | AB14: X | AC14: X | AD14: X | AE14: X | AH14: X | AI14: X | AJ14: X | AK14: X | AL14: X | AM14: =IF(F14="","",COUNTIF($H14:$AL14,AM$8)) -> 23 | AN14: =IF(OR(G14="",G14="Đã nghỉ"),0,COUNTIF($H14:$AL14,"N1")/2++IF(AND(LEN(H14)>2,OR(LEFT(H14,2)="N1",RIGHT(H14,2)="N1")),0.5)+IF(AND(LEN(I14)>2,OR(LEFT(I14,2)="N1",RIGHT(I14,2)="N1")),0.5)+IF(AND(LEN(J14)>2,OR(LEFT(J14,2)="N1",RIGHT(J14,2)="N1")),0.5)+IF(AND(LEN(K14)>2,OR(LEFT(K14,2)="N1",RIGHT(K14,2)="N1")),0.5)+IF(AND(LEN(L14)>2,OR(LEFT(L14,2)="N1",RIGHT(L14,2)="N1")),0.5)+IF(AND(LEN(M14)>2,OR(LEFT(M14,2)="N1",RIGHT(M14,2)="N1")),0.5)+IF(AND(LEN(N14)>2,OR(LEFT(N14,2)="N1",RIGHT(N14,2)="N1")),0.5)+IF(AND(LEN(O14)>2,OR(LEFT(O14,2)="N1",RIGHT(O14,2)="N1")),0.5)+IF(AND(LEN(P14)>2,OR(LEFT(P14,2)="N1",RIGHT(P14,2)="N1")),0.5)+IF(AND(LEN(Q14)>2,OR(LEFT(Q14,2)="N1",RIGHT(Q14,2)="N1")),0.5)+IF(AND(LEN(R14)>2,OR(LEFT(R14,2)="N1",RIGHT(R14,2)="N1")),0.5)+IF(AND(LEN(S14)>2,OR(LEFT(S14,2)="N1",RIGHT(S14,2)="N1")),0.5)+IF(AND(LEN(T14)>2,OR(LEFT(T14,2)="N1",RIGHT(T14,2)="N1")),0.5)+IF(AND(LEN(U14)>2,OR(LEFT(U14,2)="N1",RIGHT(U14,2)="N1")),0.5)+IF(AND(LEN(V14)>2,OR(LEFT(V14,2)="N1",RIGHT(V14,2)="N1")),0.5)+IF(AND(LEN(W14)>2,OR(LEFT(W14,2)="N1",RIGHT(W14,2)="N1")),0.5)+IF(AND(LEN(X14)>2,OR(LEFT(X14,2)="N1",RIGHT(X14,2)="N1")),0.5)+IF(AND(LEN(Y14)>2,OR(LEFT(Y14,2)="N1",RIGHT(Y14,2)="N1")),0.5)+IF(AND(LEN(Z14)>2,OR(LEFT(Z14,2)="N1",RIGHT(Z14,2)="N1")),0.5)+IF(AND(LEN(AA14)>2,OR(LEFT(AA14,2)="N1",RIGHT(AA14,2)="N1")),0.5)+IF(AND(LEN(AB14)>2,OR(LEFT(AB14,2)="N1",RIGHT(AB14,2)="N1")),0.5)+IF(AND(LEN(AC14)>2,OR(LEFT(AC14,2)="N1",RIGHT(AC14,2)="N1")),0.5)+IF(AND(LEN(AD14)>2,OR(LEFT(AD14,2)="N1",RIGHT(AD14,2)="N1")),0.5)+IF(AND(LEN(AE14)>2,OR(LEFT(AE14,2)="N1",RIGHT(AE14,2)="N1")),0.5)+IF(AND(LEN(AF14)>2,OR(LEFT(AF14,2)="N1",RIGHT(AF14,2)="N1")),0.5)+IF(AND(LEN(AG14)>2,OR(LEFT(AG14,2)="N1",RIGHT(AG14,2)="N1")),0.5)+IF(AND(LEN(AH14)>2,OR(LEFT(AH14,2)="N1",RIGHT(AH14,2)="N1")),0.5)+IF(AND(LEN(AI14)>2,OR(LEFT(AI14,2)="N1",RIGHT(AI14,2)="N1")),0.5)+IF(AND(LEN(AJ14)>2,OR(LEFT(AJ14,2)="N1",RIGHT(AJ14,2)="N1")),0.5)+IF(AND(LEN(AK14)>2,OR(LEFT(AK14,2)="N1",RIGHT(AK14,2)="N1")),0.5)+IF(AND(LEN(AL14)>2,OR(LEFT(AL14,2)="N1",RIGHT(AL14,2)="N1")),0.5)) -> 0 | AO14: =COUNTIF(H14:AL14,"ON")+COUNTIF(H14:AL14,"ON/2")/2 -> 0 | AP14: =IF(F14="","",COUNTIF($H14:$AL14,AP$8))+IF(F14="","",COUNTIF($H14:$AL14,$V$5)/2) -> 0 | AQ14: =COUNTIF($H14:$AL14,"P")+COUNTIF($H14:$AL14,"P1")/2+IF(AND(LEN(I14)>2,OR(LEFT(I14,2)="P1",RIGHT(I14,2)="P1")),0.5)+IF(AND(LEN(J14)>2,OR(LEFT(J14,2)="P1",RIGHT(J14,2)="P1")),0.5)+IF(AND(LEN(K14)>2,OR(LEFT(K14,2)="P1",RIGHT(K14,2)="P1")),0.5)+IF(AND(LEN(L14)>2,OR(LEFT(L14,2)="P1",RIGHT(L14,2)="P1")),0.5)+IF(AND(LEN(M14)>2,OR(LEFT(M14,2)="P1",RIGHT(M14,2)="P1")),0.5)+IF(AND(LEN(N14)>2,OR(LEFT(N14,2)="P1",RIGHT(N14,2)="P1")),0.5)+IF(AND(LEN(O14)>2,OR(LEFT(O14,2)="P1",RIGHT(O14,2)="P1")),0.5)+IF(AND(LEN(P14)>2,OR(LEFT(P14,2)="P1",RIGHT(P14,2)="P1")),0.5)+IF(AND(LEN(Q14)>2,OR(LEFT(Q14,2)="P1",RIGHT(Q14,2)="P1")),0.5)+IF(AND(LEN(R14)>2,OR(LEFT(R14,2)="P1",RIGHT(R14,2)="P1")),0.5)+IF(AND(LEN(S14)>2,OR(LEFT(S14,2)="P1",RIGHT(S14,2)="P1")),0.5)+IF(AND(LEN(T14)>2,OR(LEFT(T14,2)="P1",RIGHT(T14,2)="P1")),0.5)+IF(AND(LEN(U14)>2,OR(LEFT(U14,2)="P1",RIGHT(U14,2)="P1")),0.5)+IF(AND(LEN(V14)>2,OR(LEFT(V14,2)="P1",RIGHT(V14,2)="P1")),0.5)+IF(AND(LEN(W14)>2,OR(LEFT(W14,2)="P1",RIGHT(W14,2)="P1")),0.5)+IF(AND(LEN(X14)>2,OR(LEFT(X14,2)="P1",RIGHT(X14,2)="P1")),0.5)+IF(AND(LEN(Y14)>2,OR(LEFT(Y14,2)="P1",RIGHT(Y14,2)="P1")),0.5)+IF(AND(LEN(Z14)>2,OR(LEFT(Z14,2)="P1",RIGHT(Z14,2)="P1")),0.5)+IF(AND(LEN(AA14)>2,OR(LEFT(AA14,2)="P1",RIGHT(AA14,2)="P1")),0.5)+IF(AND(LEN(AB14)>2,OR(LEFT(AB14,2)="P1",RIGHT(AB14,2)="P1")),0.5)+IF(AND(LEN(AC14)>2,OR(LEFT(AC14,2)="P1",RIGHT(AC14,2)="P1")),0.5)+IF(AND(LEN(AD14)>2,OR(LEFT(AD14,2)="P1",RIGHT(AD14,2)="P1")),0.5)+IF(AND(LEN(AE14)>2,OR(LEFT(AE358,2)="P1",RIGHT(AE14,2)="P1")),0.5)+IF(AND(LEN(AF14)>2,OR(LEFT(AF14,2)="P1",RIGHT(AF14,2)="P1")),0.5)+IF(AND(LEN(AG14)>2,OR(LEFT(AG14,2)="P1",RIGHT(AG14,2)="P1")),0.5)+IF(AND(LEN(AH14)>2,OR(LEFT(AH14,2)="P1",RIGHT(AH14,2)="P1")),0.5)+IF(AND(LEN(AI14)>2,OR(LEFT(AI14,2)="P1",RIGHT(AI14,2)="P1")),0.5)+IF(AND(LEN(AJ14)>2,OR(LEFT(AJ14,2)="P1",RIGHT(AJ14,2)="P1")),0.5)+IF(AND(LEN(AK14)>2,OR(LEFT(AK14,2)="P1",RIGHT(AK14,2)="P1")),0.5)+IF(AND(LEN(AL14)>2,OR(LEFT(AL14,2)="P1",RIGHT(AL14,2)="P1")),0.5) -> 0 | AR14: =IF(G14="","",AM14+AN14+AP14+AQ14) -> 23 | AS14: =IF(F14="","",COUNTIF($H14:$AL14,AS$8))++IF(F14="","",COUNTIF($H14:$AL14,"L1")/2) -> 0 | AT14: =AU14-AR14-AS14 -> 0 | AU14: 23
A15: =SUBTOTAL(3,$F$11:F15) -> 5 | B15: MS02 | C15: BGH | D15: Hiệu trưởng kiêm nhiệm | F15: Bùi Thanh Anh | G15: Chính Thức | H15: X | I15: X | J15: X | M15: X | N15: X | O15: X | P15: X | Q15: X | T15: X | U15: X | V15: X | W15: X | X15: X | AA15: X | AB15: X | AC15: X | AD15: X | AE15: X | AH15: X | AI15: X | AJ15: X | AK15: X | AL15: X | AM15: =IF(F15="","",COUNTIF($H15:$AL15,AM$8)) -> 23 | AN15: =IF(OR(G15="",G15="Đã nghỉ"),0,COUNTIF($H15:$AL15,"N1")/2++IF(AND(LEN(H15)>2,OR(LEFT(H15,2)="N1",RIGHT(H15,2)="N1")),0.5)+IF(AND(LEN(I15)>2,OR(LEFT(I15,2)="N1",RIGHT(I15,2)="N1")),0.5)+IF(AND(LEN(J15)>2,OR(LEFT(J15,2)="N1",RIGHT(J15,2)="N1")),0.5)+IF(AND(LEN(K15)>2,OR(LEFT(K15,2)="N1",RIGHT(K15,2)="N1")),0.5)+IF(AND(LEN(L15)>2,OR(LEFT(L15,2)="N1",RIGHT(L15,2)="N1")),0.5)+IF(AND(LEN(M15)>2,OR(LEFT(M15,2)="N1",RIGHT(M15,2)="N1")),0.5)+IF(AND(LEN(N15)>2,OR(LEFT(N15,2)="N1",RIGHT(N15,2)="N1")),0.5)+IF(AND(LEN(O15)>2,OR(LEFT(O15,2)="N1",RIGHT(O15,2)="N1")),0.5)+IF(AND(LEN(P15)>2,OR(LEFT(P15,2)="N1",RIGHT(P15,2)="N1")),0.5)+IF(AND(LEN(Q15)>2,OR(LEFT(Q15,2)="N1",RIGHT(Q15,2)="N1")),0.5)+IF(AND(LEN(R15)>2,OR(LEFT(R15,2)="N1",RIGHT(R15,2)="N1")),0.5)+IF(AND(LEN(S15)>2,OR(LEFT(S15,2)="N1",RIGHT(S15,2)="N1")),0.5)+IF(AND(LEN(T15)>2,OR(LEFT(T15,2)="N1",RIGHT(T15,2)="N1")),0.5)+IF(AND(LEN(U15)>2,OR(LEFT(U15,2)="N1",RIGHT(U15,2)="N1")),0.5)+IF(AND(LEN(V15)>2,OR(LEFT(V15,2)="N1",RIGHT(V15,2)="N1")),0.5)+IF(AND(LEN(W15)>2,OR(LEFT(W15,2)="N1",RIGHT(W15,2)="N1")),0.5)+IF(AND(LEN(X15)>2,OR(LEFT(X15,2)="N1",RIGHT(X15,2)="N1")),0.5)+IF(AND(LEN(Y15)>2,OR(LEFT(Y15,2)="N1",RIGHT(Y15,2)="N1")),0.5)+IF(AND(LEN(Z15)>2,OR(LEFT(Z15,2)="N1",RIGHT(Z15,2)="N1")),0.5)+IF(AND(LEN(AA15)>2,OR(LEFT(AA15,2)="N1",RIGHT(AA15,2)="N1")),0.5)+IF(AND(LEN(AB15)>2,OR(LEFT(AB15,2)="N1",RIGHT(AB15,2)="N1")),0.5)+IF(AND(LEN(AC15)>2,OR(LEFT(AC15,2)="N1",RIGHT(AC15,2)="N1")),0.5)+IF(AND(LEN(AD15)>2,OR(LEFT(AD15,2)="N1",RIGHT(AD15,2)="N1")),0.5)+IF(AND(LEN(AE15)>2,OR(LEFT(AE15,2)="N1",RIGHT(AE15,2)="N1")),0.5)+IF(AND(LEN(AF15)>2,OR(LEFT(AF15,2)="N1",RIGHT(AF15,2)="N1")),0.5)+IF(AND(LEN(AG15)>2,OR(LEFT(AG15,2)="N1",RIGHT(AG15,2)="N1")),0.5)+IF(AND(LEN(AH15)>2,OR(LEFT(AH15,2)="N1",RIGHT(AH15,2)="N1")),0.5)+IF(AND(LEN(AI15)>2,OR(LEFT(AI15,2)="N1",RIGHT(AI15,2)="N1")),0.5)+IF(AND(LEN(AJ15)>2,OR(LEFT(AJ15,2)="N1",RIGHT(AJ15,2)="N1")),0.5)+IF(AND(LEN(AK15)>2,OR(LEFT(AK15,2)="N1",RIGHT(AK15,2)="N1")),0.5)+IF(AND(LEN(AL15)>2,OR(LEFT(AL15,2)="N1",RIGHT(AL15,2)="N1")),0.5)) -> 0 | AO15: =COUNTIF(H15:AL15,"ON")+COUNTIF(H15:AL15,"ON/2")/2 -> 0 | AP15: =IF(F15="","",COUNTIF($H15:$AL15,AP$8))+IF(F15="","",COUNTIF($H15:$AL15,$V$5)/2) -> 0 | AQ15: =COUNTIF($H15:$AL15,"P")+COUNTIF($H15:$AL15,"P1")/2+IF(AND(LEN(I15)>2,OR(LEFT(I15,2)="P1",RIGHT(I15,2)="P1")),0.5)+IF(AND(LEN(J15)>2,OR(LEFT(J15,2)="P1",RIGHT(J15,2)="P1")),0.5)+IF(AND(LEN(K15)>2,OR(LEFT(K15,2)="P1",RIGHT(K15,2)="P1")),0.5)+IF(AND(LEN(L15)>2,OR(LEFT(L15,2)="P1",RIGHT(L15,2)="P1")),0.5)+IF(AND(LEN(M15)>2,OR(LEFT(M15,2)="P1",RIGHT(M15,2)="P1")),0.5)+IF(AND(LEN(N15)>2,OR(LEFT(N15,2)="P1",RIGHT(N15,2)="P1")),0.5)+IF(AND(LEN(O15)>2,OR(LEFT(O15,2)="P1",RIGHT(O15,2)="P1")),0.5)+IF(AND(LEN(P15)>2,OR(LEFT(P15,2)="P1",RIGHT(P15,2)="P1")),0.5)+IF(AND(LEN(Q15)>2,OR(LEFT(Q15,2)="P1",RIGHT(Q15,2)="P1")),0.5)+IF(AND(LEN(R15)>2,OR(LEFT(R15,2)="P1",RIGHT(R15,2)="P1")),0.5)+IF(AND(LEN(S15)>2,OR(LEFT(S15,2)="P1",RIGHT(S15,2)="P1")),0.5)+IF(AND(LEN(T15)>2,OR(LEFT(T15,2)="P1",RIGHT(T15,2)="P1")),0.5)+IF(AND(LEN(U15)>2,OR(LEFT(U15,2)="P1",RIGHT(U15,2)="P1")),0.5)+IF(AND(LEN(V15)>2,OR(LEFT(V15,2)="P1",RIGHT(V15,2)="P1")),0.5)+IF(AND(LEN(W15)>2,OR(LEFT(W15,2)="P1",RIGHT(W15,2)="P1")),0.5)+IF(AND(LEN(X15)>2,OR(LEFT(X15,2)="P1",RIGHT(X15,2)="P1")),0.5)+IF(AND(LEN(Y15)>2,OR(LEFT(Y15,2)="P1",RIGHT(Y15,2)="P1")),0.5)+IF(AND(LEN(Z15)>2,OR(LEFT(Z15,2)="P1",RIGHT(Z15,2)="P1")),0.5)+IF(AND(LEN(AA15)>2,OR(LEFT(AA15,2)="P1",RIGHT(AA15,2)="P1")),0.5)+IF(AND(LEN(AB15)>2,OR(LEFT(AB15,2)="P1",RIGHT(AB15,2)="P1")),0.5)+IF(AND(LEN(AC15)>2,OR(LEFT(AC15,2)="P1",RIGHT(AC15,2)="P1")),0.5)+IF(AND(LEN(AD15)>2,OR(LEFT(AD15,2)="P1",RIGHT(AD15,2)="P1")),0.5)+IF(AND(LEN(AE15)>2,OR(LEFT(AE359,2)="P1",RIGHT(AE15,2)="P1")),0.5)+IF(AND(LEN(AF15)>2,OR(LEFT(AF15,2)="P1",RIGHT(AF15,2)="P1")),0.5)+IF(AND(LEN(AG15)>2,OR(LEFT(AG15,2)="P1",RIGHT(AG15,2)="P1")),0.5)+IF(AND(LEN(AH15)>2,OR(LEFT(AH15,2)="P1",RIGHT(AH15,2)="P1")),0.5)+IF(AND(LEN(AI15)>2,OR(LEFT(AI15,2)="P1",RIGHT(AI15,2)="P1")),0.5)+IF(AND(LEN(AJ15)>2,OR(LEFT(AJ15,2)="P1",RIGHT(AJ15,2)="P1")),0.5)+IF(AND(LEN(AK15)>2,OR(LEFT(AK15,2)="P1",RIGHT(AK15,2)="P1")),0.5)+IF(AND(LEN(AL15)>2,OR(LEFT(AL15,2)="P1",RIGHT(AL15,2)="P1")),0.5) -> 0 | AR15: =IF(G15="","",AM15+AN15+AP15+AQ15) -> 23 | AS15: =IF(F15="","",COUNTIF($H15:$AL15,AS$8))++IF(F15="","",COUNTIF($H15:$AL15,"L1")/2) -> 0 | AT15: =AU15-AR15-AS15 -> 0 | AU15: 23
A16: =SUBTOTAL(3,$F$11:F16) -> 6 | B16: MS11 | C16: Giáo viên | D16: Giáo viên mầm non | F16: Phùng Thị Lụa | G16: Chính Thức | H16: X | I16: X | J16: X | M16: X | N16: X | O16: X | P16: X | Q16: X | T16: X | U16: X | V16: X | W16: X | X16: X | AA16: X | AB16: X | AC16: X | AD16: X | AE16: X | AH16: X | AI16: X | AJ16: X | AK16: X | AL16: X | AM16: =IF(F16="","",COUNTIF($H16:$AL16,AM$8)) -> 23 | AN16: =IF(OR(G16="",G16="Đã nghỉ"),0,COUNTIF($H16:$AL16,"N1")/2++IF(AND(LEN(H16)>2,OR(LEFT(H16,2)="N1",RIGHT(H16,2)="N1")),0.5)+IF(AND(LEN(I16)>2,OR(LEFT(I16,2)="N1",RIGHT(I16,2)="N1")),0.5)+IF(AND(LEN(J16)>2,OR(LEFT(J16,2)="N1",RIGHT(J16,2)="N1")),0.5)+IF(AND(LEN(K16)>2,OR(LEFT(K16,2)="N1",RIGHT(K16,2)="N1")),0.5)+IF(AND(LEN(L16)>2,OR(LEFT(L16,2)="N1",RIGHT(L16,2)="N1")),0.5)+IF(AND(LEN(M16)>2,OR(LEFT(M16,2)="N1",RIGHT(M16,2)="N1")),0.5)+IF(AND(LEN(N16)>2,OR(LEFT(N16,2)="N1",RIGHT(N16,2)="N1")),0.5)+IF(AND(LEN(O16)>2,OR(LEFT(O16,2)="N1",RIGHT(O16,2)="N1")),0.5)+IF(AND(LEN(P16)>2,OR(LEFT(P16,2)="N1",RIGHT(P16,2)="N1")),0.5)+IF(AND(LEN(Q16)>2,OR(LEFT(Q16,2)="N1",RIGHT(Q16,2)="N1")),0.5)+IF(AND(LEN(R16)>2,OR(LEFT(R16,2)="N1",RIGHT(R16,2)="N1")),0.5)+IF(AND(LEN(S16)>2,OR(LEFT(S16,2)="N1",RIGHT(S16,2)="N1")),0.5)+IF(AND(LEN(T16)>2,OR(LEFT(T16,2)="N1",RIGHT(T16,2)="N1")),0.5)+IF(AND(LEN(U16)>2,OR(LEFT(U16,2)="N1",RIGHT(U16,2)="N1")),0.5)+IF(AND(LEN(V16)>2,OR(LEFT(V16,2)="N1",RIGHT(V16,2)="N1")),0.5)+IF(AND(LEN(W16)>2,OR(LEFT(W16,2)="N1",RIGHT(W16,2)="N1")),0.5)+IF(AND(LEN(X16)>2,OR(LEFT(X16,2)="N1",RIGHT(X16,2)="N1")),0.5)+IF(AND(LEN(Y16)>2,OR(LEFT(Y16,2)="N1",RIGHT(Y16,2)="N1")),0.5)+IF(AND(LEN(Z16)>2,OR(LEFT(Z16,2)="N1",RIGHT(Z16,2)="N1")),0.5)+IF(AND(LEN(AA16)>2,OR(LEFT(AA16,2)="N1",RIGHT(AA16,2)="N1")),0.5)+IF(AND(LEN(AB16)>2,OR(LEFT(AB16,2)="N1",RIGHT(AB16,2)="N1")),0.5)+IF(AND(LEN(AC16)>2,OR(LEFT(AC16,2)="N1",RIGHT(AC16,2)="N1")),0.5)+IF(AND(LEN(AD16)>2,OR(LEFT(AD16,2)="N1",RIGHT(AD16,2)="N1")),0.5)+IF(AND(LEN(AE16)>2,OR(LEFT(AE16,2)="N1",RIGHT(AE16,2)="N1")),0.5)+IF(AND(LEN(AF16)>2,OR(LEFT(AF16,2)="N1",RIGHT(AF16,2)="N1")),0.5)+IF(AND(LEN(AG16)>2,OR(LEFT(AG16,2)="N1",RIGHT(AG16,2)="N1")),0.5)+IF(AND(LEN(AH16)>2,OR(LEFT(AH16,2)="N1",RIGHT(AH16,2)="N1")),0.5)+IF(AND(LEN(AI16)>2,OR(LEFT(AI16,2)="N1",RIGHT(AI16,2)="N1")),0.5)+IF(AND(LEN(AJ16)>2,OR(LEFT(AJ16,2)="N1",RIGHT(AJ16,2)="N1")),0.5)+IF(AND(LEN(AK16)>2,OR(LEFT(AK16,2)="N1",RIGHT(AK16,2)="N1")),0.5)+IF(AND(LEN(AL16)>2,OR(LEFT(AL16,2)="N1",RIGHT(AL16,2)="N1")),0.5)) -> 0 | AO16: =COUNTIF(H16:AL16,"ON")+COUNTIF(H16:AL16,"ON/2")/2 -> 0 | AP16: =IF(F16="","",COUNTIF($H16:$AL16,AP$8))+IF(F16="","",COUNTIF($H16:$AL16,$V$5)/2) -> 0 | AQ16: =COUNTIF($H16:$AL16,"P")+COUNTIF($H16:$AL16,"P1")/2+IF(AND(LEN(I16)>2,OR(LEFT(I16,2)="P1",RIGHT(I16,2)="P1")),0.5)+IF(AND(LEN(J16)>2,OR(LEFT(J16,2)="P1",RIGHT(J16,2)="P1")),0.5)+IF(AND(LEN(K16)>2,OR(LEFT(K16,2)="P1",RIGHT(K16,2)="P1")),0.5)+IF(AND(LEN(L16)>2,OR(LEFT(L16,2)="P1",RIGHT(L16,2)="P1")),0.5)+IF(AND(LEN(M16)>2,OR(LEFT(M16,2)="P1",RIGHT(M16,2)="P1")),0.5)+IF(AND(LEN(N16)>2,OR(LEFT(N16,2)="P1",RIGHT(N16,2)="P1")),0.5)+IF(AND(LEN(O16)>2,OR(LEFT(O16,2)="P1",RIGHT(O16,2)="P1")),0.5)+IF(AND(LEN(P16)>2,OR(LEFT(P16,2)="P1",RIGHT(P16,2)="P1")),0.5)+IF(AND(LEN(Q16)>2,OR(LEFT(Q16,2)="P1",RIGHT(Q16,2)="P1")),0.5)+IF(AND(LEN(R16)>2,OR(LEFT(R16,2)="P1",RIGHT(R16,2)="P1")),0.5)+IF(AND(LEN(S16)>2,OR(LEFT(S16,2)="P1",RIGHT(S16,2)="P1")),0.5)+IF(AND(LEN(T16)>2,OR(LEFT(T16,2)="P1",RIGHT(T16,2)="P1")),0.5)+IF(AND(LEN(U16)>2,OR(LEFT(U16,2)="P1",RIGHT(U16,2)="P1")),0.5)+IF(AND(LEN(V16)>2,OR(LEFT(V16,2)="P1",RIGHT(V16,2)="P1")),0.5)+IF(AND(LEN(W16)>2,OR(LEFT(W16,2)="P1",RIGHT(W16,2)="P1")),0.5)+IF(AND(LEN(X16)>2,OR(LEFT(X16,2)="P1",RIGHT(X16,2)="P1")),0.5)+IF(AND(LEN(Y16)>2,OR(LEFT(Y16,2)="P1",RIGHT(Y16,2)="P1")),0.5)+IF(AND(LEN(Z16)>2,OR(LEFT(Z16,2)="P1",RIGHT(Z16,2)="P1")),0.5)+IF(AND(LEN(AA16)>2,OR(LEFT(AA16,2)="P1",RIGHT(AA16,2)="P1")),0.5)+IF(AND(LEN(AB16)>2,OR(LEFT(AB16,2)="P1",RIGHT(AB16,2)="P1")),0.5)+IF(AND(LEN(AC16)>2,OR(LEFT(AC16,2)="P1",RIGHT(AC16,2)="P1")),0.5)+IF(AND(LEN(AD16)>2,OR(LEFT(AD16,2)="P1",RIGHT(AD16,2)="P1")),0.5)+IF(AND(LEN(AE16)>2,OR(LEFT(AE360,2)="P1",RIGHT(AE16,2)="P1")),0.5)+IF(AND(LEN(AF16)>2,OR(LEFT(AF16,2)="P1",RIGHT(AF16,2)="P1")),0.5)+IF(AND(LEN(AG16)>2,OR(LEFT(AG16,2)="P1",RIGHT(AG16,2)="P1")),0.5)+IF(AND(LEN(AH16)>2,OR(LEFT(AH16,2)="P1",RIGHT(AH16,2)="P1")),0.5)+IF(AND(LEN(AI16)>2,OR(LEFT(AI16,2)="P1",RIGHT(AI16,2)="P1")),0.5)+IF(AND(LEN(AJ16)>2,OR(LEFT(AJ16,2)="P1",RIGHT(AJ16,2)="P1")),0.5)+IF(AND(LEN(AK16)>2,OR(LEFT(AK16,2)="P1",RIGHT(AK16,2)="P1")),0.5)+IF(AND(LEN(AL16)>2,OR(LEFT(AL16,2)="P1",RIGHT(AL16,2)="P1")),0.5) -> 0 | AR16: =IF(G16="","",AM16+AN16+AP16+AQ16) -> 23 | AS16: =IF(F16="","",COUNTIF($H16:$AL16,AS$8))++IF(F16="","",COUNTIF($H16:$AL16,"L1")/2) -> 0 | AT16: =AU16-AR16-AS16 -> 0 | AU16: 23
A17: =SUBTOTAL(3,$F$11:F17) -> 7 | B17: MS12 | C17: Vận hành | D17: HK | F17: Đinh Thị Bích Ngọc | G17: Chính Thức | H17: X | I17: X | J17: X | M17: X | N17: X | O17: X | P17: X | Q17: X | T17: X | U17: X | V17: X | W17: X | X17: X | AA17: X | AB17: X | AC17: X | AD17: X | AE17: X | AH17: X | AI17: X | AJ17: X | AK17: X | AL17: X | AM17: =IF(F17="","",COUNTIF($H17:$AL17,AM$8)) -> 23 | AN17: =IF(OR(G17="",G17="Đã nghỉ"),0,COUNTIF($H17:$AL17,"N1")/2++IF(AND(LEN(H17)>2,OR(LEFT(H17,2)="N1",RIGHT(H17,2)="N1")),0.5)+IF(AND(LEN(I17)>2,OR(LEFT(I17,2)="N1",RIGHT(I17,2)="N1")),0.5)+IF(AND(LEN(J17)>2,OR(LEFT(J17,2)="N1",RIGHT(J17,2)="N1")),0.5)+IF(AND(LEN(K17)>2,OR(LEFT(K17,2)="N1",RIGHT(K17,2)="N1")),0.5)+IF(AND(LEN(L17)>2,OR(LEFT(L17,2)="N1",RIGHT(L17,2)="N1")),0.5)+IF(AND(LEN(M17)>2,OR(LEFT(M17,2)="N1",RIGHT(M17,2)="N1")),0.5)+IF(AND(LEN(N17)>2,OR(LEFT(N17,2)="N1",RIGHT(N17,2)="N1")),0.5)+IF(AND(LEN(O17)>2,OR(LEFT(O17,2)="N1",RIGHT(O17,2)="N1")),0.5)+IF(AND(LEN(P17)>2,OR(LEFT(P17,2)="N1",RIGHT(P17,2)="N1")),0.5)+IF(AND(LEN(Q17)>2,OR(LEFT(Q17,2)="N1",RIGHT(Q17,2)="N1")),0.5)+IF(AND(LEN(R17)>2,OR(LEFT(R17,2)="N1",RIGHT(R17,2)="N1")),0.5)+IF(AND(LEN(S17)>2,OR(LEFT(S17,2)="N1",RIGHT(S17,2)="N1")),0.5)+IF(AND(LEN(T17)>2,OR(LEFT(T17,2)="N1",RIGHT(T17,2)="N1")),0.5)+IF(AND(LEN(U17)>2,OR(LEFT(U17,2)="N1",RIGHT(U17,2)="N1")),0.5)+IF(AND(LEN(V17)>2,OR(LEFT(V17,2)="N1",RIGHT(V17,2)="N1")),0.5)+IF(AND(LEN(W17)>2,OR(LEFT(W17,2)="N1",RIGHT(W17,2)="N1")),0.5)+IF(AND(LEN(X17)>2,OR(LEFT(X17,2)="N1",RIGHT(X17,2)="N1")),0.5)+IF(AND(LEN(Y17)>2,OR(LEFT(Y17,2)="N1",RIGHT(Y17,2)="N1")),0.5)+IF(AND(LEN(Z17)>2,OR(LEFT(Z17,2)="N1",RIGHT(Z17,2)="N1")),0.5)+IF(AND(LEN(AA17)>2,OR(LEFT(AA17,2)="N1",RIGHT(AA17,2)="N1")),0.5)+IF(AND(LEN(AB17)>2,OR(LEFT(AB17,2)="N1",RIGHT(AB17,2)="N1")),0.5)+IF(AND(LEN(AC17)>2,OR(LEFT(AC17,2)="N1",RIGHT(AC17,2)="N1")),0.5)+IF(AND(LEN(AD17)>2,OR(LEFT(AD17,2)="N1",RIGHT(AD17,2)="N1")),0.5)+IF(AND(LEN(AE17)>2,OR(LEFT(AE17,2)="N1",RIGHT(AE17,2)="N1")),0.5)+IF(AND(LEN(AF17)>2,OR(LEFT(AF17,2)="N1",RIGHT(AF17,2)="N1")),0.5)+IF(AND(LEN(AG17)>2,OR(LEFT(AG17,2)="N1",RIGHT(AG17,2)="N1")),0.5)+IF(AND(LEN(AH17)>2,OR(LEFT(AH17,2)="N1",RIGHT(AH17,2)="N1")),0.5)+IF(AND(LEN(AI17)>2,OR(LEFT(AI17,2)="N1",RIGHT(AI17,2)="N1")),0.5)+IF(AND(LEN(AJ17)>2,OR(LEFT(AJ17,2)="N1",RIGHT(AJ17,2)="N1")),0.5)+IF(AND(LEN(AK17)>2,OR(LEFT(AK17,2)="N1",RIGHT(AK17,2)="N1")),0.5)+IF(AND(LEN(AL17)>2,OR(LEFT(AL17,2)="N1",RIGHT(AL17,2)="N1")),0.5)) -> 0 | AO17: =COUNTIF(H17:AL17,"ON")+COUNTIF(H17:AL17,"ON/2")/2 -> 0 | AP17: =IF(F17="","",COUNTIF($H17:$AL17,AP$8))+IF(F17="","",COUNTIF($H17:$AL17,$V$5)/2) -> 0 | AQ17: =COUNTIF($H17:$AL17,"P")+COUNTIF($H17:$AL17,"P1")/2+IF(AND(LEN(I17)>2,OR(LEFT(I17,2)="P1",RIGHT(I17,2)="P1")),0.5)+IF(AND(LEN(J17)>2,OR(LEFT(J17,2)="P1",RIGHT(J17,2)="P1")),0.5)+IF(AND(LEN(K17)>2,OR(LEFT(K17,2)="P1",RIGHT(K17,2)="P1")),0.5)+IF(AND(LEN(L17)>2,OR(LEFT(L17,2)="P1",RIGHT(L17,2)="P1")),0.5)+IF(AND(LEN(M17)>2,OR(LEFT(M17,2)="P1",RIGHT(M17,2)="P1")),0.5)+IF(AND(LEN(N17)>2,OR(LEFT(N17,2)="P1",RIGHT(N17,2)="P1")),0.5)+IF(AND(LEN(O17)>2,OR(LEFT(O17,2)="P1",RIGHT(O17,2)="P1")),0.5)+IF(AND(LEN(P17)>2,OR(LEFT(P17,2)="P1",RIGHT(P17,2)="P1")),0.5)+IF(AND(LEN(Q17)>2,OR(LEFT(Q17,2)="P1",RIGHT(Q17,2)="P1")),0.5)+IF(AND(LEN(R17)>2,OR(LEFT(R17,2)="P1",RIGHT(R17,2)="P1")),0.5)+IF(AND(LEN(S17)>2,OR(LEFT(S17,2)="P1",RIGHT(S17,2)="P1")),0.5)+IF(AND(LEN(T17)>2,OR(LEFT(T17,2)="P1",RIGHT(T17,2)="P1")),0.5)+IF(AND(LEN(U17)>2,OR(LEFT(U17,2)="P1",RIGHT(U17,2)="P1")),0.5)+IF(AND(LEN(V17)>2,OR(LEFT(V17,2)="P1",RIGHT(V17,2)="P1")),0.5)+IF(AND(LEN(W17)>2,OR(LEFT(W17,2)="P1",RIGHT(W17,2)="P1")),0.5)+IF(AND(LEN(X17)>2,OR(LEFT(X17,2)="P1",RIGHT(X17,2)="P1")),0.5)+IF(AND(LEN(Y17)>2,OR(LEFT(Y17,2)="P1",RIGHT(Y17,2)="P1")),0.5)+IF(AND(LEN(Z17)>2,OR(LEFT(Z17,2)="P1",RIGHT(Z17,2)="P1")),0.5)+IF(AND(LEN(AA17)>2,OR(LEFT(AA17,2)="P1",RIGHT(AA17,2)="P1")),0.5)+IF(AND(LEN(AB17)>2,OR(LEFT(AB17,2)="P1",RIGHT(AB17,2)="P1")),0.5)+IF(AND(LEN(AC17)>2,OR(LEFT(AC17,2)="P1",RIGHT(AC17,2)="P1")),0.5)+IF(AND(LEN(AD17)>2,OR(LEFT(AD17,2)="P1",RIGHT(AD17,2)="P1")),0.5)+IF(AND(LEN(AE17)>2,OR(LEFT(AE361,2)="P1",RIGHT(AE17,2)="P1")),0.5)+IF(AND(LEN(AF17)>2,OR(LEFT(AF17,2)="P1",RIGHT(AF17,2)="P1")),0.5)+IF(AND(LEN(AG17)>2,OR(LEFT(AG17,2)="P1",RIGHT(AG17,2)="P1")),0.5)+IF(AND(LEN(AH17)>2,OR(LEFT(AH17,2)="P1",RIGHT(AH17,2)="P1")),0.5)+IF(AND(LEN(AI17)>2,OR(LEFT(AI17,2)="P1",RIGHT(AI17,2)="P1")),0.5)+IF(AND(LEN(AJ17)>2,OR(LEFT(AJ17,2)="P1",RIGHT(AJ17,2)="P1")),0.5)+IF(AND(LEN(AK17)>2,OR(LEFT(AK17,2)="P1",RIGHT(AK17,2)="P1")),0.5)+IF(AND(LEN(AL17)>2,OR(LEFT(AL17,2)="P1",RIGHT(AL17,2)="P1")),0.5) -> 0 | AR17: =IF(G17="","",AM17+AN17+AP17+AQ17) -> 23 | AS17: =IF(F17="","",COUNTIF($H17:$AL17,AS$8))++IF(F17="","",COUNTIF($H17:$AL17,"L1")/2) -> 0 | AT17: =AU17-AR17-AS17 -> 0 | AU17: 23
A18: =SUBTOTAL(3,$F$11:F18) -> 8 | B18: MS13 | C18: Vận hành | D18: Bảo vệ | F18: Lương Văn Châm | G18: Chính Thức | H18: X | I18: X | J18: X | M18: X | N18: X | O18: X | P18: X | Q18: X | T18: X | U18: X | V18: X | W18: X | X18: X | AA18: X | AB18: X | AC18: X | AD18: X | AE18: X | AH18: X | AI18: X | AJ18: X | AK18: X | AL18: X | AM18: =IF(F18="","",COUNTIF($H18:$AL18,AM$8)) -> 23 | AN18: =IF(OR(G18="",G18="Đã nghỉ"),0,COUNTIF($H18:$AL18,"N1")/2++IF(AND(LEN(H18)>2,OR(LEFT(H18,2)="N1",RIGHT(H18,2)="N1")),0.5)+IF(AND(LEN(I18)>2,OR(LEFT(I18,2)="N1",RIGHT(I18,2)="N1")),0.5)+IF(AND(LEN(J18)>2,OR(LEFT(J18,2)="N1",RIGHT(J18,2)="N1")),0.5)+IF(AND(LEN(K18)>2,OR(LEFT(K18,2)="N1",RIGHT(K18,2)="N1")),0.5)+IF(AND(LEN(L18)>2,OR(LEFT(L18,2)="N1",RIGHT(L18,2)="N1")),0.5)+IF(AND(LEN(M18)>2,OR(LEFT(M18,2)="N1",RIGHT(M18,2)="N1")),0.5)+IF(AND(LEN(N18)>2,OR(LEFT(N18,2)="N1",RIGHT(N18,2)="N1")),0.5)+IF(AND(LEN(O18)>2,OR(LEFT(O18,2)="N1",RIGHT(O18,2)="N1")),0.5)+IF(AND(LEN(P18)>2,OR(LEFT(P18,2)="N1",RIGHT(P18,2)="N1")),0.5)+IF(AND(LEN(Q18)>2,OR(LEFT(Q18,2)="N1",RIGHT(Q18,2)="N1")),0.5)+IF(AND(LEN(R18)>2,OR(LEFT(R18,2)="N1",RIGHT(R18,2)="N1")),0.5)+IF(AND(LEN(S18)>2,OR(LEFT(S18,2)="N1",RIGHT(S18,2)="N1")),0.5)+IF(AND(LEN(T18)>2,OR(LEFT(T18,2)="N1",RIGHT(T18,2)="N1")),0.5)+IF(AND(LEN(U18)>2,OR(LEFT(U18,2)="N1",RIGHT(U18,2)="N1")),0.5)+IF(AND(LEN(V18)>2,OR(LEFT(V18,2)="N1",RIGHT(V18,2)="N1")),0.5)+IF(AND(LEN(W18)>2,OR(LEFT(W18,2)="N1",RIGHT(W18,2)="N1")),0.5)+IF(AND(LEN(X18)>2,OR(LEFT(X18,2)="N1",RIGHT(X18,2)="N1")),0.5)+IF(AND(LEN(Y18)>2,OR(LEFT(Y18,2)="N1",RIGHT(Y18,2)="N1")),0.5)+IF(AND(LEN(Z18)>2,OR(LEFT(Z18,2)="N1",RIGHT(Z18,2)="N1")),0.5)+IF(AND(LEN(AA18)>2,OR(LEFT(AA18,2)="N1",RIGHT(AA18,2)="N1")),0.5)+IF(AND(LEN(AB18)>2,OR(LEFT(AB18,2)="N1",RIGHT(AB18,2)="N1")),0.5)+IF(AND(LEN(AC18)>2,OR(LEFT(AC18,2)="N1",RIGHT(AC18,2)="N1")),0.5)+IF(AND(LEN(AD18)>2,OR(LEFT(AD18,2)="N1",RIGHT(AD18,2)="N1")),0.5)+IF(AND(LEN(AE18)>2,OR(LEFT(AE18,2)="N1",RIGHT(AE18,2)="N1")),0.5)+IF(AND(LEN(AF18)>2,OR(LEFT(AF18,2)="N1",RIGHT(AF18,2)="N1")),0.5)+IF(AND(LEN(AG18)>2,OR(LEFT(AG18,2)="N1",RIGHT(AG18,2)="N1")),0.5)+IF(AND(LEN(AH18)>2,OR(LEFT(AH18,2)="N1",RIGHT(AH18,2)="N1")),0.5)+IF(AND(LEN(AI18)>2,OR(LEFT(AI18,2)="N1",RIGHT(AI18,2)="N1")),0.5)+IF(AND(LEN(AJ18)>2,OR(LEFT(AJ18,2)="N1",RIGHT(AJ18,2)="N1")),0.5)+IF(AND(LEN(AK18)>2,OR(LEFT(AK18,2)="N1",RIGHT(AK18,2)="N1")),0.5)+IF(AND(LEN(AL18)>2,OR(LEFT(AL18,2)="N1",RIGHT(AL18,2)="N1")),0.5)) -> 0 | AO18: =COUNTIF(H18:AL18,"ON")+COUNTIF(H18:AL18,"ON/2")/2 -> 0 | AP18: =IF(F18="","",COUNTIF($H18:$AL18,AP$8))+IF(F18="","",COUNTIF($H18:$AL18,$V$5)/2) -> 0 | AQ18: =COUNTIF($H18:$AL18,"P")+COUNTIF($H18:$AL18,"P1")/2+IF(AND(LEN(I18)>2,OR(LEFT(I18,2)="P1",RIGHT(I18,2)="P1")),0.5)+IF(AND(LEN(J18)>2,OR(LEFT(J18,2)="P1",RIGHT(J18,2)="P1")),0.5)+IF(AND(LEN(K18)>2,OR(LEFT(K18,2)="P1",RIGHT(K18,2)="P1")),0.5)+IF(AND(LEN(L18)>2,OR(LEFT(L18,2)="P1",RIGHT(L18,2)="P1")),0.5)+IF(AND(LEN(M18)>2,OR(LEFT(M18,2)="P1",RIGHT(M18,2)="P1")),0.5)+IF(AND(LEN(N18)>2,OR(LEFT(N18,2)="P1",RIGHT(N18,2)="P1")),0.5)+IF(AND(LEN(O18)>2,OR(LEFT(O18,2)="P1",RIGHT(O18,2)="P1")),0.5)+IF(AND(LEN(P18)>2,OR(LEFT(P18,2)="P1",RIGHT(P18,2)="P1")),0.5)+IF(AND(LEN(Q18)>2,OR(LEFT(Q18,2)="P1",RIGHT(Q18,2)="P1")),0.5)+IF(AND(LEN(R18)>2,OR(LEFT(R18,2)="P1",RIGHT(R18,2)="P1")),0.5)+IF(AND(LEN(S18)>2,OR(LEFT(S18,2)="P1",RIGHT(S18,2)="P1")),0.5)+IF(AND(LEN(T18)>2,OR(LEFT(T18,2)="P1",RIGHT(T18,2)="P1")),0.5)+IF(AND(LEN(U18)>2,OR(LEFT(U18,2)="P1",RIGHT(U18,2)="P1")),0.5)+IF(AND(LEN(V18)>2,OR(LEFT(V18,2)="P1",RIGHT(V18,2)="P1")),0.5)+IF(AND(LEN(W18)>2,OR(LEFT(W18,2)="P1",RIGHT(W18,2)="P1")),0.5)+IF(AND(LEN(X18)>2,OR(LEFT(X18,2)="P1",RIGHT(X18,2)="P1")),0.5)+IF(AND(LEN(Y18)>2,OR(LEFT(Y18,2)="P1",RIGHT(Y18,2)="P1")),0.5)+IF(AND(LEN(Z18)>2,OR(LEFT(Z18,2)="P1",RIGHT(Z18,2)="P1")),0.5)+IF(AND(LEN(AA18)>2,OR(LEFT(AA18,2)="P1",RIGHT(AA18,2)="P1")),0.5)+IF(AND(LEN(AB18)>2,OR(LEFT(AB18,2)="P1",RIGHT(AB18,2)="P1")),0.5)+IF(AND(LEN(AC18)>2,OR(LEFT(AC18,2)="P1",RIGHT(AC18,2)="P1")),0.5)+IF(AND(LEN(AD18)>2,OR(LEFT(AD18,2)="P1",RIGHT(AD18,2)="P1")),0.5)+IF(AND(LEN(AE18)>2,OR(LEFT(AE362,2)="P1",RIGHT(AE18,2)="P1")),0.5)+IF(AND(LEN(AF18)>2,OR(LEFT(AF18,2)="P1",RIGHT(AF18,2)="P1")),0.5)+IF(AND(LEN(AG18)>2,OR(LEFT(AG18,2)="P1",RIGHT(AG18,2)="P1")),0.5)+IF(AND(LEN(AH18)>2,OR(LEFT(AH18,2)="P1",RIGHT(AH18,2)="P1")),0.5)+IF(AND(LEN(AI18)>2,OR(LEFT(AI18,2)="P1",RIGHT(AI18,2)="P1")),0.5)+IF(AND(LEN(AJ18)>2,OR(LEFT(AJ18,2)="P1",RIGHT(AJ18,2)="P1")),0.5)+IF(AND(LEN(AK18)>2,OR(LEFT(AK18,2)="P1",RIGHT(AK18,2)="P1")),0.5)+IF(AND(LEN(AL18)>2,OR(LEFT(AL18,2)="P1",RIGHT(AL18,2)="P1")),0.5) -> 0 | AR18: =IF(G18="","",AM18+AN18+AP18+AQ18) -> 23 | AS18: =IF(F18="","",COUNTIF($H18:$AL18,AS$8))++IF(F18="","",COUNTIF($H18:$AL18,"L1")/2) -> 0 | AT18: =AU18-AR18-AS18 -> 0 | AU18: 23
A19: =SUBTOTAL(3,$F$11:F19) -> 9 | B19: MS14 | C19: Vận hành | D19: Y tế | F19: Nguyễn Thị Phúc | G19: Chính Thức | H19: X | I19: X | J19: X | M19: X | N19: X | O19: X | P19: X | Q19: X | T19: X | U19: X | V19: X | W19: X | X19: X | AA19: X | AB19: X | AC19: X | AD19: X | AE19: X | AH19: X | AI19: X | AJ19: X | AK19: X | AL19: X | AM19: =IF(F19="","",COUNTIF($H19:$AL19,AM$8)) -> 23 | AN19: =IF(OR(G19="",G19="Đã nghỉ"),0,COUNTIF($H19:$AL19,"N1")/2++IF(AND(LEN(H19)>2,OR(LEFT(H19,2)="N1",RIGHT(H19,2)="N1")),0.5)+IF(AND(LEN(I19)>2,OR(LEFT(I19,2)="N1",RIGHT(I19,2)="N1")),0.5)+IF(AND(LEN(J19)>2,OR(LEFT(J19,2)="N1",RIGHT(J19,2)="N1")),0.5)+IF(AND(LEN(K19)>2,OR(LEFT(K19,2)="N1",RIGHT(K19,2)="N1")),0.5)+IF(AND(LEN(L19)>2,OR(LEFT(L19,2)="N1",RIGHT(L19,2)="N1")),0.5)+IF(AND(LEN(M19)>2,OR(LEFT(M19,2)="N1",RIGHT(M19,2)="N1")),0.5)+IF(AND(LEN(N19)>2,OR(LEFT(N19,2)="N1",RIGHT(N19,2)="N1")),0.5)+IF(AND(LEN(O19)>2,OR(LEFT(O19,2)="N1",RIGHT(O19,2)="N1")),0.5)+IF(AND(LEN(P19)>2,OR(LEFT(P19,2)="N1",RIGHT(P19,2)="N1")),0.5)+IF(AND(LEN(Q19)>2,OR(LEFT(Q19,2)="N1",RIGHT(Q19,2)="N1")),0.5)+IF(AND(LEN(R19)>2,OR(LEFT(R19,2)="N1",RIGHT(R19,2)="N1")),0.5)+IF(AND(LEN(S19)>2,OR(LEFT(S19,2)="N1",RIGHT(S19,2)="N1")),0.5)+IF(AND(LEN(T19)>2,OR(LEFT(T19,2)="N1",RIGHT(T19,2)="N1")),0.5)+IF(AND(LEN(U19)>2,OR(LEFT(U19,2)="N1",RIGHT(U19,2)="N1")),0.5)+IF(AND(LEN(V19)>2,OR(LEFT(V19,2)="N1",RIGHT(V19,2)="N1")),0.5)+IF(AND(LEN(W19)>2,OR(LEFT(W19,2)="N1",RIGHT(W19,2)="N1")),0.5)+IF(AND(LEN(X19)>2,OR(LEFT(X19,2)="N1",RIGHT(X19,2)="N1")),0.5)+IF(AND(LEN(Y19)>2,OR(LEFT(Y19,2)="N1",RIGHT(Y19,2)="N1")),0.5)+IF(AND(LEN(Z19)>2,OR(LEFT(Z19,2)="N1",RIGHT(Z19,2)="N1")),0.5)+IF(AND(LEN(AA19)>2,OR(LEFT(AA19,2)="N1",RIGHT(AA19,2)="N1")),0.5)+IF(AND(LEN(AB19)>2,OR(LEFT(AB19,2)="N1",RIGHT(AB19,2)="N1")),0.5)+IF(AND(LEN(AC19)>2,OR(LEFT(AC19,2)="N1",RIGHT(AC19,2)="N1")),0.5)+IF(AND(LEN(AD19)>2,OR(LEFT(AD19,2)="N1",RIGHT(AD19,2)="N1")),0.5)+IF(AND(LEN(AE19)>2,OR(LEFT(AE19,2)="N1",RIGHT(AE19,2)="N1")),0.5)+IF(AND(LEN(AF19)>2,OR(LEFT(AF19,2)="N1",RIGHT(AF19,2)="N1")),0.5)+IF(AND(LEN(AG19)>2,OR(LEFT(AG19,2)="N1",RIGHT(AG19,2)="N1")),0.5)+IF(AND(LEN(AH19)>2,OR(LEFT(AH19,2)="N1",RIGHT(AH19,2)="N1")),0.5)+IF(AND(LEN(AI19)>2,OR(LEFT(AI19,2)="N1",RIGHT(AI19,2)="N1")),0.5)+IF(AND(LEN(AJ19)>2,OR(LEFT(AJ19,2)="N1",RIGHT(AJ19,2)="N1")),0.5)+IF(AND(LEN(AK19)>2,OR(LEFT(AK19,2)="N1",RIGHT(AK19,2)="N1")),0.5)+IF(AND(LEN(AL19)>2,OR(LEFT(AL19,2)="N1",RIGHT(AL19,2)="N1")),0.5)) -> 0 | AO19: =COUNTIF(H19:AL19,"ON")+COUNTIF(H19:AL19,"ON/2")/2 -> 0 | AP19: =IF(F19="","",COUNTIF($H19:$AL19,AP$8))+IF(F19="","",COUNTIF($H19:$AL19,$V$5)/2) -> 0 | AQ19: =COUNTIF($H19:$AL19,"P")+COUNTIF($H19:$AL19,"P1")/2+IF(AND(LEN(I19)>2,OR(LEFT(I19,2)="P1",RIGHT(I19,2)="P1")),0.5)+IF(AND(LEN(J19)>2,OR(LEFT(J19,2)="P1",RIGHT(J19,2)="P1")),0.5)+IF(AND(LEN(K19)>2,OR(LEFT(K19,2)="P1",RIGHT(K19,2)="P1")),0.5)+IF(AND(LEN(L19)>2,OR(LEFT(L19,2)="P1",RIGHT(L19,2)="P1")),0.5)+IF(AND(LEN(M19)>2,OR(LEFT(M19,2)="P1",RIGHT(M19,2)="P1")),0.5)+IF(AND(LEN(N19)>2,OR(LEFT(N19,2)="P1",RIGHT(N19,2)="P1")),0.5)+IF(AND(LEN(O19)>2,OR(LEFT(O19,2)="P1",RIGHT(O19,2)="P1")),0.5)+IF(AND(LEN(P19)>2,OR(LEFT(P19,2)="P1",RIGHT(P19,2)="P1")),0.5)+IF(AND(LEN(Q19)>2,OR(LEFT(Q19,2)="P1",RIGHT(Q19,2)="P1")),0.5)+IF(AND(LEN(R19)>2,OR(LEFT(R19,2)="P1",RIGHT(R19,2)="P1")),0.5)+IF(AND(LEN(S19)>2,OR(LEFT(S19,2)="P1",RIGHT(S19,2)="P1")),0.5)+IF(AND(LEN(T19)>2,OR(LEFT(T19,2)="P1",RIGHT(T19,2)="P1")),0.5)+IF(AND(LEN(U19)>2,OR(LEFT(U19,2)="P1",RIGHT(U19,2)="P1")),0.5)+IF(AND(LEN(V19)>2,OR(LEFT(V19,2)="P1",RIGHT(V19,2)="P1")),0.5)+IF(AND(LEN(W19)>2,OR(LEFT(W19,2)="P1",RIGHT(W19,2)="P1")),0.5)+IF(AND(LEN(X19)>2,OR(LEFT(X19,2)="P1",RIGHT(X19,2)="P1")),0.5)+IF(AND(LEN(Y19)>2,OR(LEFT(Y19,2)="P1",RIGHT(Y19,2)="P1")),0.5)+IF(AND(LEN(Z19)>2,OR(LEFT(Z19,2)="P1",RIGHT(Z19,2)="P1")),0.5)+IF(AND(LEN(AA19)>2,OR(LEFT(AA19,2)="P1",RIGHT(AA19,2)="P1")),0.5)+IF(AND(LEN(AB19)>2,OR(LEFT(AB19,2)="P1",RIGHT(AB19,2)="P1")),0.5)+IF(AND(LEN(AC19)>2,OR(LEFT(AC19,2)="P1",RIGHT(AC19,2)="P1")),0.5)+IF(AND(LEN(AD19)>2,OR(LEFT(AD19,2)="P1",RIGHT(AD19,2)="P1")),0.5)+IF(AND(LEN(AE19)>2,OR(LEFT(AE363,2)="P1",RIGHT(AE19,2)="P1")),0.5)+IF(AND(LEN(AF19)>2,OR(LEFT(AF19,2)="P1",RIGHT(AF19,2)="P1")),0.5)+IF(AND(LEN(AG19)>2,OR(LEFT(AG19,2)="P1",RIGHT(AG19,2)="P1")),0.5)+IF(AND(LEN(AH19)>2,OR(LEFT(AH19,2)="P1",RIGHT(AH19,2)="P1")),0.5)+IF(AND(LEN(AI19)>2,OR(LEFT(AI19,2)="P1",RIGHT(AI19,2)="P1")),0.5)+IF(AND(LEN(AJ19)>2,OR(LEFT(AJ19,2)="P1",RIGHT(AJ19,2)="P1")),0.5)+IF(AND(LEN(AK19)>2,OR(LEFT(AK19,2)="P1",RIGHT(AK19,2)="P1")),0.5)+IF(AND(LEN(AL19)>2,OR(LEFT(AL19,2)="P1",RIGHT(AL19,2)="P1")),0.5) -> 0 | AR19: =IF(G19="","",AM19+AN19+AP19+AQ19) -> 23 | AS19: =IF(F19="","",COUNTIF($H19:$AL19,AS$8))++IF(F19="","",COUNTIF($H19:$AL19,"L1")/2) -> 0 | AT19: =AU19-AR19-AS19 -> 0 | AU19: 23
A20: =SUBTOTAL(3,$F$11:F20) -> 10 | B20: MS20 | C20: Vận hành | D20: Nhân viên bếp | F20: Nguyễn Thị Thu Hiền | G20: Chính Thức | H20: X | I20: X | J20: X | M20: X | N20: X | O20: X | P20: X | Q20: X | T20: X | U20: X | V20: X | W20: X | X20: X | AA20: X | AB20: X | AC20: X | AD20: X | AE20: X | AH20: X | AI20: X | AJ20: X | AK20: X | AL20: X | AM20: =IF(F20="","",COUNTIF($H20:$AL20,AM$8)) -> 23 | AN20: =IF(OR(G20="",G20="Đã nghỉ"),0,COUNTIF($H20:$AL20,"N1")/2++IF(AND(LEN(H20)>2,OR(LEFT(H20,2)="N1",RIGHT(H20,2)="N1")),0.5)+IF(AND(LEN(I20)>2,OR(LEFT(I20,2)="N1",RIGHT(I20,2)="N1")),0.5)+IF(AND(LEN(J20)>2,OR(LEFT(J20,2)="N1",RIGHT(J20,2)="N1")),0.5)+IF(AND(LEN(K20)>2,OR(LEFT(K20,2)="N1",RIGHT(K20,2)="N1")),0.5)+IF(AND(LEN(L20)>2,OR(LEFT(L20,2)="N1",RIGHT(L20,2)="N1")),0.5)+IF(AND(LEN(M20)>2,OR(LEFT(M20,2)="N1",RIGHT(M20,2)="N1")),0.5)+IF(AND(LEN(N20)>2,OR(LEFT(N20,2)="N1",RIGHT(N20,2)="N1")),0.5)+IF(AND(LEN(O20)>2,OR(LEFT(O20,2)="N1",RIGHT(O20,2)="N1")),0.5)+IF(AND(LEN(P20)>2,OR(LEFT(P20,2)="N1",RIGHT(P20,2)="N1")),0.5)+IF(AND(LEN(Q20)>2,OR(LEFT(Q20,2)="N1",RIGHT(Q20,2)="N1")),0.5)+IF(AND(LEN(R20)>2,OR(LEFT(R20,2)="N1",RIGHT(R20,2)="N1")),0.5)+IF(AND(LEN(S20)>2,OR(LEFT(S20,2)="N1",RIGHT(S20,2)="N1")),0.5)+IF(AND(LEN(T20)>2,OR(LEFT(T20,2)="N1",RIGHT(T20,2)="N1")),0.5)+IF(AND(LEN(U20)>2,OR(LEFT(U20,2)="N1",RIGHT(U20,2)="N1")),0.5)+IF(AND(LEN(V20)>2,OR(LEFT(V20,2)="N1",RIGHT(V20,2)="N1")),0.5)+IF(AND(LEN(W20)>2,OR(LEFT(W20,2)="N1",RIGHT(W20,2)="N1")),0.5)+IF(AND(LEN(X20)>2,OR(LEFT(X20,2)="N1",RIGHT(X20,2)="N1")),0.5)+IF(AND(LEN(Y20)>2,OR(LEFT(Y20,2)="N1",RIGHT(Y20,2)="N1")),0.5)+IF(AND(LEN(Z20)>2,OR(LEFT(Z20,2)="N1",RIGHT(Z20,2)="N1")),0.5)+IF(AND(LEN(AA20)>2,OR(LEFT(AA20,2)="N1",RIGHT(AA20,2)="N1")),0.5)+IF(AND(LEN(AB20)>2,OR(LEFT(AB20,2)="N1",RIGHT(AB20,2)="N1")),0.5)+IF(AND(LEN(AC20)>2,OR(LEFT(AC20,2)="N1",RIGHT(AC20,2)="N1")),0.5)+IF(AND(LEN(AD20)>2,OR(LEFT(AD20,2)="N1",RIGHT(AD20,2)="N1")),0.5)+IF(AND(LEN(AE20)>2,OR(LEFT(AE20,2)="N1",RIGHT(AE20,2)="N1")),0.5)+IF(AND(LEN(AF20)>2,OR(LEFT(AF20,2)="N1",RIGHT(AF20,2)="N1")),0.5)+IF(AND(LEN(AG20)>2,OR(LEFT(AG20,2)="N1",RIGHT(AG20,2)="N1")),0.5)+IF(AND(LEN(AH20)>2,OR(LEFT(AH20,2)="N1",RIGHT(AH20,2)="N1")),0.5)+IF(AND(LEN(AI20)>2,OR(LEFT(AI20,2)="N1",RIGHT(AI20,2)="N1")),0.5)+IF(AND(LEN(AJ20)>2,OR(LEFT(AJ20,2)="N1",RIGHT(AJ20,2)="N1")),0.5)+IF(AND(LEN(AK20)>2,OR(LEFT(AK20,2)="N1",RIGHT(AK20,2)="N1")),0.5)+IF(AND(LEN(AL20)>2,OR(LEFT(AL20,2)="N1",RIGHT(AL20,2)="N1")),0.5)) -> 0 | AO20: =COUNTIF(H20:AL20,"ON")+COUNTIF(H20:AL20,"ON/2")/2 -> 0 | AP20: =IF(F20="","",COUNTIF($H20:$AL20,AP$8))+IF(F20="","",COUNTIF($H20:$AL20,$V$5)/2) -> 0 | AQ20: =COUNTIF($H20:$AL20,"P")+COUNTIF($H20:$AL20,"P1")/2+IF(AND(LEN(I20)>2,OR(LEFT(I20,2)="P1",RIGHT(I20,2)="P1")),0.5)+IF(AND(LEN(J20)>2,OR(LEFT(J20,2)="P1",RIGHT(J20,2)="P1")),0.5)+IF(AND(LEN(K20)>2,OR(LEFT(K20,2)="P1",RIGHT(K20,2)="P1")),0.5)+IF(AND(LEN(L20)>2,OR(LEFT(L20,2)="P1",RIGHT(L20,2)="P1")),0.5)+IF(AND(LEN(M20)>2,OR(LEFT(M20,2)="P1",RIGHT(M20,2)="P1")),0.5)+IF(AND(LEN(N20)>2,OR(LEFT(N20,2)="P1",RIGHT(N20,2)="P1")),0.5)+IF(AND(LEN(O20)>2,OR(LEFT(O20,2)="P1",RIGHT(O20,2)="P1")),0.5)+IF(AND(LEN(P20)>2,OR(LEFT(P20,2)="P1",RIGHT(P20,2)="P1")),0.5)+IF(AND(LEN(Q20)>2,OR(LEFT(Q20,2)="P1",RIGHT(Q20,2)="P1")),0.5)+IF(AND(LEN(R20)>2,OR(LEFT(R20,2)="P1",RIGHT(R20,2)="P1")),0.5)+IF(AND(LEN(S20)>2,OR(LEFT(S20,2)="P1",RIGHT(S20,2)="P1")),0.5)+IF(AND(LEN(T20)>2,OR(LEFT(T20,2)="P1",RIGHT(T20,2)="P1")),0.5)+IF(AND(LEN(U20)>2,OR(LEFT(U20,2)="P1",RIGHT(U20,2)="P1")),0.5)+IF(AND(LEN(V20)>2,OR(LEFT(V20,2)="P1",RIGHT(V20,2)="P1")),0.5)+IF(AND(LEN(W20)>2,OR(LEFT(W20,2)="P1",RIGHT(W20,2)="P1")),0.5)+IF(AND(LEN(X20)>2,OR(LEFT(X20,2)="P1",RIGHT(X20,2)="P1")),0.5)+IF(AND(LEN(Y20)>2,OR(LEFT(Y20,2)="P1",RIGHT(Y20,2)="P1")),0.5)+IF(AND(LEN(Z20)>2,OR(LEFT(Z20,2)="P1",RIGHT(Z20,2)="P1")),0.5)+IF(AND(LEN(AA20)>2,OR(LEFT(AA20,2)="P1",RIGHT(AA20,2)="P1")),0.5)+IF(AND(LEN(AB20)>2,OR(LEFT(AB20,2)="P1",RIGHT(AB20,2)="P1")),0.5)+IF(AND(LEN(AC20)>2,OR(LEFT(AC20,2)="P1",RIGHT(AC20,2)="P1")),0.5)+IF(AND(LEN(AD20)>2,OR(LEFT(AD20,2)="P1",RIGHT(AD20,2)="P1")),0.5)+IF(AND(LEN(AE20)>2,OR(LEFT(AE370,2)="P1",RIGHT(AE20,2)="P1")),0.5)+IF(AND(LEN(AF20)>2,OR(LEFT(AF20,2)="P1",RIGHT(AF20,2)="P1")),0.5)+IF(AND(LEN(AG20)>2,OR(LEFT(AG20,2)="P1",RIGHT(AG20,2)="P1")),0.5)+IF(AND(LEN(AH20)>2,OR(LEFT(AH20,2)="P1",RIGHT(AH20,2)="P1")),0.5)+IF(AND(LEN(AI20)>2,OR(LEFT(AI20,2)="P1",RIGHT(AI20,2)="P1")),0.5)+IF(AND(LEN(AJ20)>2,OR(LEFT(AJ20,2)="P1",RIGHT(AJ20,2)="P1")),0.5)+IF(AND(LEN(AK20)>2,OR(LEFT(AK20,2)="P1",RIGHT(AK20,2)="P1")),0.5)+IF(AND(LEN(AL20)>2,OR(LEFT(AL20,2)="P1",RIGHT(AL20,2)="P1")),0.5) -> 0 | AR20: =IF(G20="","",AM20+AN20+AP20+AQ20) -> 23 | AS20: =IF(F20="","",COUNTIF($H20:$AL20,AS$8))++IF(F20="","",COUNTIF($H20:$AL20,"L1")/2) -> 0 | AT20: =AU20-AR20-AS20 -> 0 | AU20: 23
