Workbook
Name __________________________________a129: #REF!
Name __________________________________a130: #REF!
Name _________________________________a129: #REF!
Name _________________________________a130: #REF!
Name ________________________________a129: #REF!
Name ________________________________a130: #REF!
Name _______________________________a129: #REF!
Name _______________________________a130: #REF!
Name ______________________________a129: #REF!
Name ______________________________a130: #REF!
Name _____________________________a129: #REF!
Name _____________________________a130: #REF!
Name ____________________________a129: #REF!
Name ____________________________a130: #REF!
Name ___________________________a129: #REF!
Name ___________________________a130: #REF!
Name __________________________a129: #REF!
Name __________________________a130: #REF!
Name _________________________a129: #REF!
Name _________________________a130: #REF!
Name ________________________a129: #REF!
Name ________________________a130: #REF!
Name _______________________a129: #REF!
Name _______________________a130: #REF!
Name ______________________a129: #REF!
Name ______________________a130: #REF!
Name _____________________a129: #REF!
Name _____________________a130: #REF!
Name ____________________a129: #REF!
Name ____________________a130: #REF!
Name ___________________a129: #REF!
Name ___________________a130: #REF!
Name __________________a129: #REF!
Name __________________a130: #REF!
Name _________________a129: #REF!
Name _________________a130: #REF!
Name ________________a129: #REF!
Name ________________a130: #REF!
Name _______________a129: #REF!
Name _______________a130: #REF!
Name ______________a129: #REF!
Name ______________a130: #REF!
Name _____________a129: #REF!
Name _____________a130: #REF!
Name ____________a129: #REF!
Name ____________a130: #REF!
Name ___________a129: #REF!
Name ___________a130: #REF!
Name __________a129: #REF!
Name __________a130: #REF!
Name _________a129: #REF!
Name _________a130: #REF!
Name ________a129: #REF!
Name ________a130: #REF!
Name _______a129: #REF!
Name _______a130: #REF!
Name ______a129: #REF!
Name ______a130: #REF!
Name _____a129: #REF!
Name _____a130: #REF!

Sheet MỤC LỤC
A1: DANH MỤC HỒ SƠ LƯƠNG THÁNG 04.2024
A2: STT | B2: Nội dung | C2: Link
A3: 1 | B3: Đề nghị thanh toán | C3: ĐỀ NGHỊ THANH TOÁN
A4: 2 | B4: Ngân hàng nhận lương của CBNV | C4: Bảng kê nhận lương
A5: 3 | B5: Bảng chấm công | C5: 3,BẢNG CHẤM CÔNG
A6: 4 | B6: Bảng phép năm 2025 | C6: Bảng phép năm 2023
A7: 5 | B7: Thông số tính lương | C7: Thông số TL
A8: 6 | B8: Bảng tính lương | C8: Bảng lương
A9: 7 | B9: Theo dõi Người phụ thuộc | C9: #'7.Danh sách NPT'!A1
A10: 8 | B10: Phiếu lương | C10: Phiếu lương

Sheet 1.ĐNTT LẦN 1
D1: CỘNG HOÀ XÃ HỘI CHỦ NGHĨA VIỆT NAM Độc lập - Tự do - Hạnh phúc
D2: ----------------------
M3: =IF(E3="","Hà Nội, Ngày 05 Tháng 05 Năm 2026",VLOOKUP(E3,'[24]NHẬP LIỆU'!B1:M29,2,0)) -> Hà Nội, Ngày 05 Tháng 05 Năm 2026
H5: ĐỀ NGHỊ THANH TOÁN
C6: Kính gửi: | D6: - Ban lãnh đạo Công ty cổ phần MS14 - Bộ phận kế toán của công ty
C7: Họ và tên người đề nghị: Nguyễn Thị Thu Hảo
C8: Bộ phận: | D8: Vận hành
C9: Nội dung thanh toán: MS14 thanh toán lương CBNV MS14 tháng 04/2026
C11: Nội dung thanh toán | N11: Thành tiền
C12: MS14 thanh toán lương CBNV MS14 tháng 04/2026 Danh sách cụ thể đính kèm. | N12: ='2. DS TKNH L1'!G20 -> 151759700
C13: Tổng tiền thanh toán | N13: =N12 -> 151759700
C14: Bằng chữ:
C15: =" Đề nghị Ban lãnh đạo và phòng kế toán phê duyệt để thanh toán số tiền nêu trên. Chi tiết cụ thể như số liệu đã đề cập." -> Đề nghị Ban lãnh đạo và phòng kế toán phê duyệt để thanh toán số tiền nêu trên. Chi tiết cụ thể như số liệu đã đề cập.
C16: Phương thức thanh toán: | H16: Tiền mặt | L16: FALSE
H17: Chuyển khoản | L17: TRUE
C18: Thông tin chuyển khoản:
C19: - Chủ tài khoản: | F19: Theo danh sách đính kèm
C20: - Số tài khoản : | F20: Theo danh sách đính kèm
C21: - Ngân hàng: | F21: Theo danh sách đính kèm
A23: Tổng Giám đốc | F23: Phòng TCKT | N23: Phòng HCNS | V23: Người lập

Sheet 2. DS TKNH L1
C1: BẢNG KÊ DANH SÁCH THANH TOÁN LƯƠNG THÁNG 04.2026
C2: Nội dung: MS14 thanh toán lương cho nhân sự MS14 Tháng 04.2026
A3: STT | B3: Mã NV | C3: Họ và tên | D3: Số tài khoản | E3: Ngân hàng | F3: Chi nhánh | G3: Số tiền thanh toán
A4: 1 | B4: MS03 | C4: =VLOOKUP(B4,'6.Bảng lương '!B13:$C$16,2,0) -> Lê Thị Kim Liên | D4: 19031627139016 | E4: Techcombank | G4: =VLOOKUP($B4,'6.Bảng lương '!$B$11:$AV$38,47,0) -> 16212500
A5: 2 | B5: MS04 | C5: =VLOOKUP(B5,'6.Bảng lương '!B15:$C$16,2,0) -> Nguyễn Thị Thu Hảo | D5: 19035531863010 | E5: Techcombank | G5: =VLOOKUP($B5,'6.Bảng lương '!$B$11:$AV$38,47,0) -> 10121600
A6: 3 | B6: MS02 | C6: =VLOOKUP(B6,'6.Bảng lương '!B12:$C$12,2,0) -> Bùi Thanh Anh | D6: 1978555558 | E6: ACB | G6: =VLOOKUP($B6,'6.Bảng lương '!$B$11:$AV$38,47,0) -> 15000000
A7: 4 | B7: MS06 | C7: =VLOOKUP(B7,'6.Bảng lương '!B$16:$C29,2,0) -> Eugene | D7: 1045887952 | E7: Vietcombank | G7: =VLOOKUP($B7,'6.Bảng lương '!$B$11:$AV$38,47,0) -> 22275400
A8: 5 | B8: MS07 | C8: =VLOOKUP(B8,'6.Bảng lương '!B$16:$C30,2,0) -> Nguyễn Ánh Hồng | D8: 1033638061 | E8: Vietcombank | G8: =VLOOKUP($B8,'6.Bảng lương '!$B$11:$AV$38,47,0) -> 8422500
A9: 6 | B9: MS16 | C9: Phạm Thị Hương Thuỷ | D9: 0906951113 | E9: MB | G9: =VLOOKUP($B9,'6.Bảng lương '!$B$11:$AV$38,47,0) -> 7758300
A10: 7 | B10: MS09 | C10: =VLOOKUP(B10,'6.Bảng lương '!$B$12:$C$30,2,0) -> Nguyễn Thị Thu | D10: 1991555558 | E10: ACB | G10: =VLOOKUP($B10,'6.Bảng lương '!$B$11:$AV$38,47,0) -> 8000000
A11: 8 | B11: MS11 | C11: =VLOOKUP(B11,' 5. Thông số TL'!$D$12:$E$25,2,0) -> Phùng Thị Lụa | D11: 0563250894 | E11: MB | G11: ='6.Bảng lương '!AV34 -> 10850200
A12: 9 | B12: MS12 | C12: =VLOOKUP(B12,' 5. Thông số TL'!$D$12:$E$25,2,0) -> Đinh Thị Bích Ngọc | D12: 19032824127018 | E12: Techcombank | G12: ='6.Bảng lương '!AV21 -> 9034000
A13: 10 | B13: MS13 | C13: =VLOOKUP(B13,' 5. Thông số TL'!$D$12:$E$25,2,0) -> Lương Văn Châm | D13: 9904677976 | E13: Techcombank | G13: ='6.Bảng lương '!AV22 -> 8179100
A14: 11 | B14: MS14 | C14: =VLOOKUP(B14,' 5. Thông số TL'!$D$12:$E$25,2,0) -> Nguyễn Thị Phúc | D14: 1036236348 | E14: VCB | G14: =VLOOKUP($B14,'6.Bảng lương '!$B$11:$AV$38,47,0) -> 10000000
A15: 12 | B15: MS15 | C15: =VLOOKUP(B15,' 5. Thông số TL'!$D$12:$E$25,2,0) -> Nguyễn Thị Thuỳ Trang | D15: 0374624154 | E15: MB | G15: =VLOOKUP($B15,'6.Bảng lương '!$B$11:$AV$38,47,0) -> 5397800
A16: 13 | B16: MS17 | C16: Lê Thị Bích Hường | D16: 0984903219 | E16: MB | G16: =VLOOKUP($B16,'6.Bảng lương '!$B$11:$AV$38,47,0) -> 5439600
A17: 14 | B17: MS18 | C17: Nguyễn Hương Thảo | D17: 8862965558 | E17: BIDV | G17: =VLOOKUP($B17,'6.Bảng lương '!$B$11:$AV$38,47,0) -> 5328600
A18: 15 | B18: MS19 | C18: Bác Hạnh | G18: =VLOOKUP($B18,'6.Bảng lương '!$B$11:$AV$38,47,0) -> 9000000
A19: 16 | B19: MS20 | C19: Nguyễn Thị Thu Hiền | D19: 19021081619016 | E19: Techcombank | G19: =VLOOKUP($B19,'6.Bảng lương '!$B$11:$AV$38,47,0) -> 740100
A20: Tổng | G20: =SUM(G4:G19) -> 151759700
E23: Hà Nội, ngày 05 tháng 05 năm 2026
A25: TỔNG GIÁM ĐỐC | C25: PHÒNG TÀI CHÍNH - KẾ TOÁN | E25: PHÒNG HCNS | F25: NGƯỜI LẬP

Sheet 3. BẢNG CHẤM CÔNG
C1: TÊN ĐƠN VỊ: CÔNG TY CỔ PHẦN MS14 ĐỊA CHỈ: Clubhouse 3 đường Phong Lan 1, khu đô thị Vinhomes Riverside, phường Phúc Lợi, thành phố Hà Nội MST: 0111258406
I2: Tháng | K2: 4 | M2: Bảng Ký Hiệu Các Loại Ngày Công
M3: Loại | O3: Đủ Công | P3: Nửa Ngày | Q3: Online | R3: Online nửa ngày | S3: Phép | T3: Nửa phép | U3: Làm việc CN, T7 | V3: Làm việc nửa CN/T7 | X3: Ngày Lễ | Y3: Nửa ngày lễ | Z3: Không Lương | AB3: Thai sản
I4: Năm | K4: 2026
M5: Ký Hiệu | O5: X | P5: N1 | Q5: On | R5: On/2 | S5: P | T5: P1 | U5: C | V5: C/2 | X5: L | Y5: L1 | Z5: K | AB5: TS
A6: MS14 - BẢNG CHẤM CÔNG THÁNG 04/2026
H7: 8 | I7: =1+H7 -> 9 | J7: =1+I7 -> 10 | K7: =1+J7 -> 11 | L7: =1+K7 -> 12 | M7: =1+L7 -> 13 | N7: =1+M7 -> 14 | O7: =1+N7 -> 15 | P7: =1+O7 -> 16 | ... AN7: =1+AM7 -> 40 | AP7: =1+AN7 -> 41 | AQ7: =1+AP7 -> 42 | AR7: =1+AQ7 -> 43 | AS7: =1+AR7 -> 44 | AT7: =1+AS7 -> 45 | AU7: =1+AT7 -> 46 | AV7: =1+AU7 -> 47
H8: =DATE(K4,K2,1) -> 46113 | I8: =H8+1 -> 46114 | J8: =I8+1 -> 46115 | K8: =J8+1 -> 46116 | L8: =K8+1 -> 46117 | M8: =L8+1 -> 46118 | N8: =M8+1 -> 46119 | O8: =N8+1 -> 46120 | P8: =O8+1 -> 46121 | ... AL8: =AK8+1 -> 46143 | AM8: X | AN8: N1 | AO8: ON | AP8: C | AQ8: P + P1 | AR8: Tổng Công đi làm & nghỉ phép | AS8: L | AT8: K | AU8: Số công full tháng | AV8: ="Phép Tồn năm 2023 tính đến T."&K2 -> Phép Tồn năm 2023 tính đến T.4
H9: =CHOOSE(WEEKDAY(H8),"Chủ Nhật","Thứ Hai","Thứ Ba","Thứ Tư","Thứ Năm","Thứ Sáu","Thứ Bảy") -> Thứ Tư | I9: =CHOOSE(WEEKDAY(I8),"Chủ Nhật","Thứ Hai","Thứ Ba","Thứ Tư","Thứ Năm","Thứ Sáu","Thứ Bảy") -> Thứ Năm | J9: =CHOOSE(WEEKDAY(J8),"Chủ Nhật","Thứ Hai","Thứ Ba","Thứ Tư","Thứ Năm","Thứ Sáu","Thứ Bảy") -> Thứ Sáu | K9: =CHOOSE(WEEKDAY(K8),"Chủ Nhật","Thứ Hai","Thứ Ba","Thứ Tư","Thứ Năm","Thứ Sáu","Thứ Bảy") -> Thứ Bảy | L9: =CHOOSE(WEEKDAY(L8),"Chủ Nhật","Thứ Hai","Thứ Ba","Thứ Tư","Thứ Năm","Thứ Sáu","Thứ Bảy") -> Chủ Nhật | M9: =CHOOSE(WEEKDAY(M8),"Chủ Nhật","Thứ Hai","Thứ Ba","Thứ Tư","Thứ Năm","Thứ Sáu","Thứ Bảy") -> Thứ Hai | N9: =CHOOSE(WEEKDAY(N8),"Chủ Nhật","Thứ Hai","Thứ Ba","Thứ Tư","Thứ Năm","Thứ Sáu","Thứ Bảy") -> Thứ Ba | O9: =CHOOSE(WEEKDAY(O8),"Chủ Nhật","Thứ Hai","Thứ Ba","Thứ Tư","Thứ Năm","Thứ Sáu","Thứ Bảy") -> Thứ Tư | ... AL9: =CHOOSE(WEEKDAY(AL8),"Chủ Nhật","Thứ Hai","Thứ Ba","Thứ Tư","Thứ Năm","Thứ Sáu","Thứ Bảy") -> Thứ Sáu | AM9: Đủ công | AN9: Nửa Công | AO9: Làm online | AP9: Làm việc CN, T7 | AQ9: Phép | AS9: Lễ Tết | AT9: Không Lương
A10: STT | B10: Mã NV | C10: Phòng ban | D10: Chức danh | E10: Tầng nhân sự | F10: Họ & Tên | G10: Tình Trạng | AR10: =SUM(AR12:AR33) -> 505 | AT10: =SUM(AT12:AT33) -> 131
A11: =SUBTOTAL(3,$F$11:F11) -> 1 | B11: MS04 | C11: Vận hành | D11: Trưởng phòng vận hành | F11: Nguyễn Thị Thu Hảo | G11: Chính Thức | H11: On | I11: On | J11: On | M11: On | N11: On | O11: On | P11: On | Q11: On | T11: On | U11: On | V11: L | W11: L | X11: L | AA11: X | AB11: X | AC11: X | AD11: X | AE11: X | AH11: L | AI11: X | AJ11: X | AK11: L | AM11: =IF(F11="","",COUNTIF($H11:$AL11,AM$8)) -> 7 | AN11: =IF(OR(G11="",G11="Đã nghỉ"),0,COUNTIF($H11:$AL11,"N1")/2++IF(AND(LEN(H11)>2,OR(LEFT(H11,2)="N1",RIGHT(H11,2)="N1")),0.5)+IF(AND(LEN(I11)>2,OR(LEFT(I11,2)="N1",RIGHT(I11,2)="N1")),0.5)+IF(AND(LEN(J11)>2,OR(LEFT(J11,2)="N1",RIGHT(J11,2)="N1")),0.5)+IF(AND(LEN(K11)>2,OR(LEFT(K11,2)="N1",RIGHT(K11,2)="N1")),0.5)+IF(AND(LEN(L11)>2,OR(LEFT(L11,2)="N1",RIGHT(L11,2)="N1")),0.5)+IF(AND(LEN(M11)>2,OR(LEFT(M11,2)="N1",RIGHT(M11,2)="N1")),0.5)+IF(AND(LEN(N11)>2,OR(LEFT(N11,2)="N1",RIGHT(N11,2)="N1")),0.5)+IF(AND(LEN(O11)>2,OR(LEFT(O11,2)="N1",RIGHT(O11,2)="N1")),0.5)+IF(AND(LEN(P11)>2,OR(LEFT(P11,2)="N1",RIGHT(P11,2)="N1")),0.5)+IF(AND(LEN(Q11)>2,OR(LEFT(Q11,2)="N1",RIGHT(Q11,2)="N1")),0.5)+IF(AND(LEN(R11)>2,OR(LEFT(R11,2)="N1",RIGHT(R11,2)="N1")),0.5)+IF(AND(LEN(S11)>2,OR(LEFT(S11,2)="N1",RIGHT(S11,2)="N1")),0.5)+IF(AND(LEN(T11)>2,OR(LEFT(T11,2)="N1",RIGHT(T11,2)="N1")),0.5)+IF(AND(LEN(U11)>2,OR(LEFT(U11,2)="N1",RIGHT(U11,2)="N1")),0.5)+IF(AND(LEN(V11)>2,OR(LEFT(V11,2)="N1",RIGHT(V11,2)="N1")),0.5)+IF(AND(LEN(W11)>2,OR(LEFT(W11,2)="N1",RIGHT(W11,2)="N1")),0.5)+IF(AND(LEN(X11)>2,OR(LEFT(X11,2)="N1",RIGHT(X11,2)="N1")),0.5)+IF(AND(LEN(Y11)>2,OR(LEFT(Y11,2)="N1",RIGHT(Y11,2)="N1")),0.5)+IF(AND(LEN(Z11)>2,OR(LEFT(Z11,2)="N1",RIGHT(Z11,2)="N1")),0.5)+IF(AND(LEN(AA11)>2,OR(LEFT(AA11,2)="N1",RIGHT(AA11,2)="N1")),0.5)+IF(AND(LEN(AB11)>2,OR(LEFT(AB11,2)="N1",RIGHT(AB11,2)="N1")),0.5)+IF(AND(LEN(AC11)>2,OR(LEFT(AC11,2)="N1",RIGHT(AC11,2)="N1")),0.5)+IF(AND(LEN(AD11)>2,OR(LEFT(AD11,2)="N1",RIGHT(AD11,2)="N1")),0.5)+IF(AND(LEN(AE11)>2,OR(LEFT(AE11,2)="N1",RIGHT(AE11,2)="N1")),0.5)+IF(AND(LEN(AF11)>2,OR(LEFT(AF11,2)="N1",RIGHT(AF11,2)="N1")),0.5)+IF(AND(LEN(AG11)>2,OR(LEFT(AG11,2)="N1",RIGHT(AG11,2)="N1")),0.5)+IF(AND(LEN(AH11)>2,OR(LEFT(AH11,2)="N1",RIGHT(AH11,2)="N1")),0.5)+IF(AND(LEN(AI11)>2,OR(LEFT(AI11,2)="N1",RIGHT(AI11,2)="N1")),0.5)+IF(AND(LEN(AJ11)>2,OR(LEFT(AJ11,2)="N1",RIGHT(AJ11,2)="N1")),0.5)+IF(AND(LEN(AK11)>2,OR(LEFT(AK11,2)="N1",RIGHT(AK11,2)="N1")),0.5)+IF(AND(LEN(AL11)>2,OR(LEFT(AL11,2)="N1",RIGHT(AL11,2)="N1")),0.5)) -> 0 | AO11: =COUNTIF(H11:AL11,"ON")+COUNTIF(H11:AL11,"ON/2")/2 -> 10 | AP11: =IF(F11="","",COUNTIF($H11:$AL11,AP$8))+IF(F11="","",COUNTIF($H11:$AL11,$V$5)/2) -> 0 | AQ11: =COUNTIF($H11:$AL11,"P")+COUNTIF($H11:$AL11,"P1")/2+IF(AND(LEN(I11)>2,OR(LEFT(I11,2)="P1",RIGHT(I11,2)="P1")),0.5)+IF(AND(LEN(J11)>2,OR(LEFT(J11,2)="P1",RIGHT(J11,2)="P1")),0.5)+IF(AND(LEN(K11)>2,OR(LEFT(K11,2)="P1",RIGHT(K11,2)="P1")),0.5)+IF(AND(LEN(L11)>2,OR(LEFT(L11,2)="P1",RIGHT(L11,2)="P1")),0.5)+IF(AND(LEN(M11)>2,OR(LEFT(M11,2)="P1",RIGHT(M11,2)="P1")),0.5)+IF(AND(LEN(N11)>2,OR(LEFT(N11,2)="P1",RIGHT(N11,2)="P1")),0.5)+IF(AND(LEN(O11)>2,OR(LEFT(O11,2)="P1",RIGHT(O11,2)="P1")),0.5)+IF(AND(LEN(P11)>2,OR(LEFT(P11,2)="P1",RIGHT(P11,2)="P1")),0.5)+IF(AND(LEN(Q11)>2,OR(LEFT(Q11,2)="P1",RIGHT(Q11,2)="P1")),0.5)+IF(AND(LEN(R11)>2,OR(LEFT(R11,2)="P1",RIGHT(R11,2)="P1")),0.5)+IF(AND(LEN(S11)>2,OR(LEFT(S11,2)="P1",RIGHT(S11,2)="P1")),0.5)+IF(AND(LEN(T11)>2,OR(LEFT(T11,2)="P1",RIGHT(T11,2)="P1")),0.5)+IF(AND(LEN(U11)>2,OR(LEFT(U11,2)="P1",RIGHT(U11,2)="P1")),0.5)+IF(AND(LEN(V11)>2,OR(LEFT(V11,2)="P1",RIGHT(V11,2)="P1")),0.5)+IF(AND(LEN(W11)>2,OR(LEFT(W11,2)="P1",RIGHT(W11,2)="P1")),0.5)+IF(AND(LEN(X11)>2,OR(LEFT(X11,2)="P1",RIGHT(X11,2)="P1")),0.5)+IF(AND(LEN(Y11)>2,OR(LEFT(Y11,2)="P1",RIGHT(Y11,2)="P1")),0.5)+IF(AND(LEN(Z11)>2,OR(LEFT(Z11,2)="P1",RIGHT(Z11,2)="P1")),0.5)+IF(AND(LEN(AA11)>2,OR(LEFT(AA11,2)="P1",RIGHT(AA11,2)="P1")),0.5)+IF(AND(LEN(AB11)>2,OR(LEFT(AB11,2)="P1",RIGHT(AB11,2)="P1")),0.5)+IF(AND(LEN(AC11)>2,OR(LEFT(AC11,2)="P1",RIGHT(AC11,2)="P1")),0.5)+IF(AND(LEN(AD11)>2,OR(LEFT(AD11,2)="P1",RIGHT(AD11,2)="P1")),0.5)+IF(AND(LEN(AE11)>2,OR(LEFT(AE357,2)="P1",RIGHT(AE11,2)="P1")),0.5)+IF(AND(LEN(AF11)>2,OR(LEFT(AF11,2)="P1",RIGHT(AF11,2)="P1")),0.5)+IF(AND(LEN(AG11)>2,OR(LEFT(AG11,2)="P1",RIGHT(AG11,2)="P1")),0.5)+IF(AND(LEN(AH11)>2,OR(LEFT(AH11,2)="P1",RIGHT(AH11,2)="P1")),0.5)+IF(AND(LEN(AI11)>2,OR(LEFT(AI11,2)="P1",RIGHT(AI11,2)="P1")),0.5)+IF(AND(LEN(AJ11)>2,OR(LEFT(AJ11,2)="P1",RIGHT(AJ11,2)="P1")),0.5)+IF(AND(LEN(AK11)>2,OR(LEFT(AK11,2)="P1",RIGHT(AK11,2)="P1")),0.5)+IF(AND(LEN(AL11)>2,OR(LEFT(AL11,2)="P1",RIGHT(AL11,2)="P1")),0.5) -> 0 | AR11: =IF(G11="","",AM11+AN11+AP11+AQ11) -> 7 | AS11: =IF(F11="","",COUNTIF($H11:$AL11,AS$8))++IF(F11="","",COUNTIF($H11:$AL11,"L1")/2) -> 5 | AT11: 5 | AU11: 22
A12: =SUBTOTAL(3,$F$11:F12) -> 2 | B12: MS03 | C12: BGH | D12: Hiệu phó cơ sở | F12: Lê Thị Kim Liên | G12: Chính Thức | H12: X | I12: X | J12: X | M12: X | N12: X | O12: X | P12: X | Q12: X | T12: X | U12: X | V12: X | W12: X | X12: X | AA12: X | AB12: X | AC12: X | AD12: X | AE12: X | AH12: L | AI12: X | AJ12: X | AK12: L | AM12: =IF(F12="","",COUNTIF($H12:$AL12,AM$8)) -> 20 | AN12: =IF(OR(G12="",G12="Đã nghỉ"),0,COUNTIF($H12:$AL12,"N1")/2++IF(AND(LEN(H12)>2,OR(LEFT(H12,2)="N1",RIGHT(H12,2)="N1")),0.5)+IF(AND(LEN(I12)>2,OR(LEFT(I12,2)="N1",RIGHT(I12,2)="N1")),0.5)+IF(AND(LEN(J12)>2,OR(LEFT(J12,2)="N1",RIGHT(J12,2)="N1")),0.5)+IF(AND(LEN(K12)>2,OR(LEFT(K12,2)="N1",RIGHT(K12,2)="N1")),0.5)+IF(AND(LEN(L12)>2,OR(LEFT(L12,2)="N1",RIGHT(L12,2)="N1")),0.5)+IF(AND(LEN(M12)>2,OR(LEFT(M12,2)="N1",RIGHT(M12,2)="N1")),0.5)+IF(AND(LEN(N12)>2,OR(LEFT(N12,2)="N1",RIGHT(N12,2)="N1")),0.5)+IF(AND(LEN(O12)>2,OR(LEFT(O12,2)="N1",RIGHT(O12,2)="N1")),0.5)+IF(AND(LEN(P12)>2,OR(LEFT(P12,2)="N1",RIGHT(P12,2)="N1")),0.5)+IF(AND(LEN(Q12)>2,OR(LEFT(Q12,2)="N1",RIGHT(Q12,2)="N1")),0.5)+IF(AND(LEN(R12)>2,OR(LEFT(R12,2)="N1",RIGHT(R12,2)="N1")),0.5)+IF(AND(LEN(S12)>2,OR(LEFT(S12,2)="N1",RIGHT(S12,2)="N1")),0.5)+IF(AND(LEN(T12)>2,OR(LEFT(T12,2)="N1",RIGHT(T12,2)="N1")),0.5)+IF(AND(LEN(U12)>2,OR(LEFT(U12,2)="N1",RIGHT(U12,2)="N1")),0.5)+IF(AND(LEN(V12)>2,OR(LEFT(V12,2)="N1",RIGHT(V12,2)="N1")),0.5)+IF(AND(LEN(W12)>2,OR(LEFT(W12,2)="N1",RIGHT(W12,2)="N1")),0.5)+IF(AND(LEN(X12)>2,OR(LEFT(X12,2)="N1",RIGHT(X12,2)="N1")),0.5)+IF(AND(LEN(Y12)>2,OR(LEFT(Y12,2)="N1",RIGHT(Y12,2)="N1")),0.5)+IF(AND(LEN(Z12)>2,OR(LEFT(Z12,2)="N1",RIGHT(Z12,2)="N1")),0.5)+IF(AND(LEN(AA12)>2,OR(LEFT(AA12,2)="N1",RIGHT(AA12,2)="N1")),0.5)+IF(AND(LEN(AB12)>2,OR(LEFT(AB12,2)="N1",RIGHT(AB12,2)="N1")),0.5)+IF(AND(LEN(AC12)>2,OR(LEFT(AC12,2)="N1",RIGHT(AC12,2)="N1")),0.5)+IF(AND(LEN(AD12)>2,OR(LEFT(AD12,2)="N1",RIGHT(AD12,2)="N1")),0.5)+IF(AND(LEN(AE12)>2,OR(LEFT(AE12,2)="N1",RIGHT(AE12,2)="N1")),0.5)+IF(AND(LEN(AF12)>2,OR(LEFT(AF12,2)="N1",RIGHT(AF12,2)="N1")),0.5)+IF(AND(LEN(AG12)>2,OR(LEFT(AG12,2)="N1",RIGHT(AG12,2)="N1")),0.5)+IF(AND(LEN(AH12)>2,OR(LEFT(AH12,2)="N1",RIGHT(AH12,2)="N1")),0.5)+IF(AND(LEN(AI12)>2,OR(LEFT(AI12,2)="N1",RIGHT(AI12,2)="N1")),0.5)+IF(AND(LEN(AJ12)>2,OR(LEFT(AJ12,2)="N1",RIGHT(AJ12,2)="N1")),0.5)+IF(AND(LEN(AK12)>2,OR(LEFT(AK12,2)="N1",RIGHT(AK12,2)="N1")),0.5)+IF(AND(LEN(AL12)>2,OR(LEFT(AL12,2)="N1",RIGHT(AL12,2)="N1")),0.5)) -> 0 | AO12: =COUNTIF(H12:AL12,"ON")+COUNTIF(H12:AL12,"ON/2")/2 -> 0 | AP12: =IF(F12="","",COUNTIF($H12:$AL12,AP$8))+IF(F12="","",COUNTIF($H12:$AL12,$V$5)/2) -> 0 | AQ12: 0 | AR12: =IF(G12="","",AM12+AN12+AP12+AQ12) -> 20 | AS12: =IF(F12="","",COUNTIF($H12:$AL12,AS$8))++IF(F12="","",COUNTIF($H12:$AL12,"L1")/2) -> 2 | AT12: =AU12-AR12-AS12 -> 0 | AU12: 22 | AV12: =VLOOKUP(B12,'4. Bảng phép năm 2026'!B7:T7,24,0) -> #REF!
A13: =SUBTOTAL(3,$F$11:F13) -> 3 | B13: MS07 | C13: Giáo viên | D13: Giáo viên mầm non | F13: Nguyễn Ánh Hồng | G13: Chính Thức | H13: X | I13: X | J13: X | M13: X | N13: X | O13: X | P13: X | Q13: P | T13: X | U13: X | V13: X | W13: X | X13: X | AA13: X | AB13: X | AC13: X | AD13: X | AE13: X | AH13: L | AI13: X | AJ13: X | AK13: L | AM13: =IF(F13="","",COUNTIF($H13:$AL13,AM$8)) -> 19 | AN13: =IF(OR(G13="",G13="Đã nghỉ"),0,COUNTIF($H13:$AL13,"N1")/2++IF(AND(LEN(H13)>2,OR(LEFT(H13,2)="N1",RIGHT(H13,2)="N1")),0.5)+IF(AND(LEN(I13)>2,OR(LEFT(I13,2)="N1",RIGHT(I13,2)="N1")),0.5)+IF(AND(LEN(J13)>2,OR(LEFT(J13,2)="N1",RIGHT(J13,2)="N1")),0.5)+IF(AND(LEN(K13)>2,OR(LEFT(K13,2)="N1",RIGHT(K13,2)="N1")),0.5)+IF(AND(LEN(L13)>2,OR(LEFT(L13,2)="N1",RIGHT(L13,2)="N1")),0.5)+IF(AND(LEN(M13)>2,OR(LEFT(M13,2)="N1",RIGHT(M13,2)="N1")),0.5)+IF(AND(LEN(N13)>2,OR(LEFT(N13,2)="N1",RIGHT(N13,2)="N1")),0.5)+IF(AND(LEN(O13)>2,OR(LEFT(O13,2)="N1",RIGHT(O13,2)="N1")),0.5)+IF(AND(LEN(P13)>2,OR(LEFT(P13,2)="N1",RIGHT(P13,2)="N1")),0.5)+IF(AND(LEN(Q13)>2,OR(LEFT(Q13,2)="N1",RIGHT(Q13,2)="N1")),0.5)+IF(AND(LEN(R13)>2,OR(LEFT(R13,2)="N1",RIGHT(R13,2)="N1")),0.5)+IF(AND(LEN(S13)>2,OR(LEFT(S13,2)="N1",RIGHT(S13,2)="N1")),0.5)+IF(AND(LEN(T13)>2,OR(LEFT(T13,2)="N1",RIGHT(T13,2)="N1")),0.5)+IF(AND(LEN(U13)>2,OR(LEFT(U13,2)="N1",RIGHT(U13,2)="N1")),0.5)+IF(AND(LEN(V13)>2,OR(LEFT(V13,2)="N1",RIGHT(V13,2)="N1")),0.5)+IF(AND(LEN(W13)>2,OR(LEFT(W13,2)="N1",RIGHT(W13,2)="N1")),0.5)+IF(AND(LEN(X13)>2,OR(LEFT(X13,2)="N1",RIGHT(X13,2)="N1")),0.5)+IF(AND(LEN(Y13)>2,OR(LEFT(Y13,2)="N1",RIGHT(Y13,2)="N1")),0.5)+IF(AND(LEN(Z13)>2,OR(LEFT(Z13,2)="N1",RIGHT(Z13,2)="N1")),0.5)+IF(AND(LEN(AA13)>2,OR(LEFT(AA13,2)="N1",RIGHT(AA13,2)="N1")),0.5)+IF(AND(LEN(AB13)>2,OR(LEFT(AB13,2)="N1",RIGHT(AB13,2)="N1")),0.5)+IF(AND(LEN(AC13)>2,OR(LEFT(AC13,2)="N1",RIGHT(AC13,2)="N1")),0.5)+IF(AND(LEN(AD13)>2,OR(LEFT(AD13,2)="N1",RIGHT(AD13,2)="N1")),0.5)+IF(AND(LEN(AE13)>2,OR(LEFT(AE13,2)="N1",RIGHT(AE13,2)="N1")),0.5)+IF(AND(LEN(AF13)>2,OR(LEFT(AF13,2)="N1",RIGHT(AF13,2)="N1")),0.5)+IF(AND(LEN(AG13)>2,OR(LEFT(AG13,2)="N1",RIGHT(AG13,2)="N1")),0.5)+IF(AND(LEN(AH13)>2,OR(LEFT(AH13,2)="N1",RIGHT(AH13,2)="N1")),0.5)+IF(AND(LEN(AI13)>2,OR(LEFT(AI13,2)="N1",RIGHT(AI13,2)="N1")),0.5)+IF(AND(LEN(AJ13)>2,OR(LEFT(AJ13,2)="N1",RIGHT(AJ13,2)="N1")),0.5)+IF(AND(LEN(AK13)>2,OR(LEFT(AK13,2)="N1",RIGHT(AK13,2)="N1")),0.5)+IF(AND(LEN(AL13)>2,OR(LEFT(AL13,2)="N1",RIGHT(AL13,2)="N1")),0.5)) -> 0 | AO13: =COUNTIF(H13:AL13,"ON")+COUNTIF(H13:AL13,"ON/2")/2 -> 0 | AP13: =IF(F13="","",COUNTIF($H13:$AL13,AP$8))+IF(F13="","",COUNTIF($H13:$AL13,$V$5)/2) -> 0 | AQ13: 1 | AR13: =IF(G13="","",AM13+AN13+AP13+AQ13) -> 20 | AS13: =IF(F13="","",COUNTIF($H13:$AL13,AS$8))++IF(F13="","",COUNTIF($H13:$AL13,"L1")/2) -> 2 | AT13: =AU13-AR13-AS13 -> 0 | AU13: 22
A14: =SUBTOTAL(3,$F$11:F14) -> 4 | B14: MS06 | C14: Giáo viên | D14: Giáo viên nước ngoài | F14: Eugene | G14: Chính Thức | H14: N1 | I14: N1 | J14: N1 | M14: N1 | N14: N1 | O14: N1 | P14: N1 | Q14: N1 | T14: N1 | U14: N1 | V14: K | W14: N1 | X14: N1 | AA14: N1 | AB14: K | AC14: N1 | AD14: K | AE14: N1 | AH14: L | AI14: K | AJ14: N1 | AK14: L | AM14: =IF(F14="","",COUNTIF($H14:$AL14,AM$8)) -> 0 | AN14: =IF(OR(G14="",G14="Đã nghỉ"),0,COUNTIF($H14:$AL14,"N1")/2++IF(AND(LEN(H14)>2,OR(LEFT(H14,2)="N1",RIGHT(H14,2)="N1")),0.5)+IF(AND(LEN(I14)>2,OR(LEFT(I14,2)="N1",RIGHT(I14,2)="N1")),0.5)+IF(AND(LEN(J14)>2,OR(LEFT(J14,2)="N1",RIGHT(J14,2)="N1")),0.5)+IF(AND(LEN(K14)>2,OR(LEFT(K14,2)="N1",RIGHT(K14,2)="N1")),0.5)+IF(AND(LEN(L14)>2,OR(LEFT(L14,2)="N1",RIGHT(L14,2)="N1")),0.5)+IF(AND(LEN(M14)>2,OR(LEFT(M14,2)="N1",RIGHT(M14,2)="N1")),0.5)+IF(AND(LEN(N14)>2,OR(LEFT(N14,2)="N1",RIGHT(N14,2)="N1")),0.5)+IF(AND(LEN(O14)>2,OR(LEFT(O14,2)="N1",RIGHT(O14,2)="N1")),0.5)+IF(AND(LEN(P14)>2,OR(LEFT(P14,2)="N1",RIGHT(P14,2)="N1")),0.5)+IF(AND(LEN(Q14)>2,OR(LEFT(Q14,2)="N1",RIGHT(Q14,2)="N1")),0.5)+IF(AND(LEN(R14)>2,OR(LEFT(R14,2)="N1",RIGHT(R14,2)="N1")),0.5)+IF(AND(LEN(S14)>2,OR(LEFT(S14,2)="N1",RIGHT(S14,2)="N1")),0.5)+IF(AND(LEN(T14)>2,OR(LEFT(T14,2)="N1",RIGHT(T14,2)="N1")),0.5)+IF(AND(LEN(U14)>2,OR(LEFT(U14,2)="N1",RIGHT(U14,2)="N1")),0.5)+IF(AND(LEN(V14)>2,OR(LEFT(V14,2)="N1",RIGHT(V14,2)="N1")),0.5)+IF(AND(LEN(W14)>2,OR(LEFT(W14,2)="N1",RIGHT(W14,2)="N1")),0.5)+IF(AND(LEN(X14)>2,OR(LEFT(X14,2)="N1",RIGHT(X14,2)="N1")),0.5)+IF(AND(LEN(Y14)>2,OR(LEFT(Y14,2)="N1",RIGHT(Y14,2)="N1")),0.5)+IF(AND(LEN(Z14)>2,OR(LEFT(Z14,2)="N1",RIGHT(Z14,2)="N1")),0.5)+IF(AND(LEN(AA14)>2,OR(LEFT(AA14,2)="N1",RIGHT(AA14,2)="N1")),0.5)+IF(AND(LEN(AB14)>2,OR(LEFT(AB14,2)="N1",RIGHT(AB14,2)="N1")),0.5)+IF(AND(LEN(AC14)>2,OR(LEFT(AC14,2)="N1",RIGHT(AC14,2)="N1")),0.5)+IF(AND(LEN(AD14)>2,OR(LEFT(AD14,2)="N1",RIGHT(AD14,2)="N1")),0.5)+IF(AND(LEN(AE14)>2,OR(LEFT(AE14,2)="N1",RIGHT(AE14,2)="N1")),0.5)+IF(AND(LEN(AF14)>2,OR(LEFT(AF14,2)="N1",RIGHT(AF14,2)="N1")),0.5)+IF(AND(LEN(AG14)>2,OR(LEFT(AG14,2)="N1",RIGHT(AG14,2)="N1")),0.5)+IF(AND(LEN(AH14)>2,OR(LEFT(AH14,2)="N1",RIGHT(AH14,2)="N1")),0.5)+IF(AND(LEN(AI14)>2,OR(LEFT(AI14,2)="N1",RIGHT(AI14,2)="N1")),0.5)+IF(AND(LEN(AJ14)>2,OR(LEFT(AJ14,2)="N1",RIGHT(AJ14,2)="N1")),0.5)+IF(AND(LEN(AK14)>2,OR(LEFT(AK14,2)="N1",RIGHT(AK14,2)="N1")),0.5)+IF(AND(LEN(AL14)>2,OR(LEFT(AL14,2)="N1",RIGHT(AL14,2)="N1")),0.5)) -> 8 | AO14: =COUNTIF(H14:AL14,"ON")+COUNTIF(H14:AL14,"ON/2")/2 -> 0 | AP14: =IF(F14="","",COUNTIF($H14:$AL14,AP$8))+IF(F14="","",COUNTIF($H14:$AL14,$V$5)/2) -> 0 | AQ14: 0 | AR14: =IF(G14="","",AM14+AN14+AP14+AQ14) -> 8 | AS14: =IF(F14="","",COUNTIF($H14:$AL14,AS$8))++IF(F14="","",COUNTIF($H14:$AL14,"L1")/2) -> 2 | AT14: =AU14-AR14-AS14 -> 12 | AU14: 22
A15: =SUBTOTAL(3,$F$11:F15) -> 5 | B15: MS16 | C15: Vận hành | D15: Kế toán | F15: Phạm Thị Hương Thuỷ | G15: Thử Việc | M15: X | N15: X | O15: X | P15: X | Q15: X | T15: X | U15: X | V15: X | W15: X | X15: X | AA15: X | AB15: X | AC15: X | AD15: X | AE15: X | AH15: K | AI15: X | AJ15: X | AK15: K | AM15: =IF(F15="","",COUNTIF($H15:$AL15,AM$8)) -> 17 | AN15: =IF(OR(G15="",G15="Đã nghỉ"),0,COUNTIF($H15:$AL15,"N1")/2++IF(AND(LEN(H15)>2,OR(LEFT(H15,2)="N1",RIGHT(H15,2)="N1")),0.5)+IF(AND(LEN(I15)>2,OR(LEFT(I15,2)="N1",RIGHT(I15,2)="N1")),0.5)+IF(AND(LEN(J15)>2,OR(LEFT(J15,2)="N1",RIGHT(J15,2)="N1")),0.5)+IF(AND(LEN(K15)>2,OR(LEFT(K15,2)="N1",RIGHT(K15,2)="N1")),0.5)+IF(AND(LEN(L15)>2,OR(LEFT(L15,2)="N1",RIGHT(L15,2)="N1")),0.5)+IF(AND(LEN(M15)>2,OR(LEFT(M15,2)="N1",RIGHT(M15,2)="N1")),0.5)+IF(AND(LEN(N15)>2,OR(LEFT(N15,2)="N1",RIGHT(N15,2)="N1")),0.5)+IF(AND(LEN(O15)>2,OR(LEFT(O15,2)="N1",RIGHT(O15,2)="N1")),0.5)+IF(AND(LEN(P15)>2,OR(LEFT(P15,2)="N1",RIGHT(P15,2)="N1")),0.5)+IF(AND(LEN(Q15)>2,OR(LEFT(Q15,2)="N1",RIGHT(Q15,2)="N1")),0.5)+IF(AND(LEN(R15)>2,OR(LEFT(R15,2)="N1",RIGHT(R15,2)="N1")),0.5)+IF(AND(LEN(S15)>2,OR(LEFT(S15,2)="N1",RIGHT(S15,2)="N1")),0.5)+IF(AND(LEN(T15)>2,OR(LEFT(T15,2)="N1",RIGHT(T15,2)="N1")),0.5)+IF(AND(LEN(U15)>2,OR(LEFT(U15,2)="N1",RIGHT(U15,2)="N1")),0.5)+IF(AND(LEN(V15)>2,OR(LEFT(V15,2)="N1",RIGHT(V15,2)="N1")),0.5)+IF(AND(LEN(W15)>2,OR(LEFT(W15,2)="N1",RIGHT(W15,2)="N1")),0.5)+IF(AND(LEN(X15)>2,OR(LEFT(X15,2)="N1",RIGHT(X15,2)="N1")),0.5)+IF(AND(LEN(Y15)>2,OR(LEFT(Y15,2)="N1",RIGHT(Y15,2)="N1")),0.5)+IF(AND(LEN(Z15)>2,OR(LEFT(Z15,2)="N1",RIGHT(Z15,2)="N1")),0.5)+IF(AND(LEN(AA15)>2,OR(LEFT(AA15,2)="N1",RIGHT(AA15,2)="N1")),0.5)+IF(AND(LEN(AB15)>2,OR(LEFT(AB15,2)="N1",RIGHT(AB15,2)="N1")),0.5)+IF(AND(LEN(AC15)>2,OR(LEFT(AC15,2)="N1",RIGHT(AC15,2)="N1")),0.5)+IF(AND(LEN(AD15)>2,OR(LEFT(AD15,2)="N1",RIGHT(AD15,2)="N1")),0.5)+IF(AND(LEN(AE15)>2,OR(LEFT(AE15,2)="N1",RIGHT(AE15,2)="N1")),0.5)+IF(AND(LEN(AF15)>2,OR(LEFT(AF15,2)="N1",RIGHT(AF15,2)="N1")),0.5)+IF(AND(LEN(AG15)>2,OR(LEFT(AG15,2)="N1",RIGHT(AG15,2)="N1")),0.5)+IF(AND(LEN(AH15)>2,OR(LEFT(AH15,2)="N1",RIGHT(AH15,2)="N1")),0.5)+IF(AND(LEN(AI15)>2,OR(LEFT(AI15,2)="N1",RIGHT(AI15,2)="N1")),0.5)+IF(AND(LEN(AJ15)>2,OR(LEFT(AJ15,2)="N1",RIGHT(AJ15,2)="N1")),0.5)+IF(AND(LEN(AK15)>2,OR(LEFT(AK15,2)="N1",RIGHT(AK15,2)="N1")),0.5)+IF(AND(LEN(AL15)>2,OR(LEFT(AL15,2)="N1",RIGHT(AL15,2)="N1")),0.5)) -> 0 | AO15: =COUNTIF(H15:AL15,"ON")+COUNTIF(H15:AL15,"ON/2")/2 -> 0 | AP15: =IF(F15="","",COUNTIF($H15:$AL15,AP$8))+IF(F15="","",COUNTIF($H15:$AL15,$V$5)/2) -> 0 | AQ15: 0 | AR15: =IF(G15="","",AM15+AN15+AP15+AQ15) -> 17 | AS15: =IF(F15="","",COUNTIF($H15:$AL15,AS$8))++IF(F15="","",COUNTIF($H15:$AL15,"L1")/2) -> 0 | AT15: =AU15-AR15-AS15 -> 5 | AU15: 22
A16: =SUBTOTAL(3,$F$11:F16) -> 6 | B16: MS09 | C16: BGH | D16: Quản lý chương trình TA | F16: Nguyễn Thị Thu | G16: Chính Thức | H16: X | I16: X | J16: X | M16: X | N16: X | O16: X | P16: X | Q16: X | T16: X | U16: X | V16: X | W16: X | X16: X | AA16: X | AB16: X | AC16: X | AD16: X | AE16: X | AH16: L | AI16: X | AJ16: X | AK16: L | AM16: =IF(F16="","",COUNTIF($H16:$AL16,AM$8)) -> 20 | AN16: =IF(OR(G16="",G16="Đã nghỉ"),0,COUNTIF($H16:$AL16,"N1")/2++IF(AND(LEN(H16)>2,OR(LEFT(H16,2)="N1",RIGHT(H16,2)="N1")),0.5)+IF(AND(LEN(I16)>2,OR(LEFT(I16,2)="N1",RIGHT(I16,2)="N1")),0.5)+IF(AND(LEN(J16)>2,OR(LEFT(J16,2)="N1",RIGHT(J16,2)="N1")),0.5)+IF(AND(LEN(K16)>2,OR(LEFT(K16,2)="N1",RIGHT(K16,2)="N1")),0.5)+IF(AND(LEN(L16)>2,OR(LEFT(L16,2)="N1",RIGHT(L16,2)="N1")),0.5)+IF(AND(LEN(M16)>2,OR(LEFT(M16,2)="N1",RIGHT(M16,2)="N1")),0.5)+IF(AND(LEN(N16)>2,OR(LEFT(N16,2)="N1",RIGHT(N16,2)="N1")),0.5)+IF(AND(LEN(O16)>2,OR(LEFT(O16,2)="N1",RIGHT(O16,2)="N1")),0.5)+IF(AND(LEN(P16)>2,OR(LEFT(P16,2)="N1",RIGHT(P16,2)="N1")),0.5)+IF(AND(LEN(Q16)>2,OR(LEFT(Q16,2)="N1",RIGHT(Q16,2)="N1")),0.5)+IF(AND(LEN(R16)>2,OR(LEFT(R16,2)="N1",RIGHT(R16,2)="N1")),0.5)+IF(AND(LEN(S16)>2,OR(LEFT(S16,2)="N1",RIGHT(S16,2)="N1")),0.5)+IF(AND(LEN(T16)>2,OR(LEFT(T16,2)="N1",RIGHT(T16,2)="N1")),0.5)+IF(AND(LEN(U16)>2,OR(LEFT(U16,2)="N1",RIGHT(U16,2)="N1")),0.5)+IF(AND(LEN(V16)>2,OR(LEFT(V16,2)="N1",RIGHT(V16,2)="N1")),0.5)+IF(AND(LEN(W16)>2,OR(LEFT(W16,2)="N1",RIGHT(W16,2)="N1")),0.5)+IF(AND(LEN(X16)>2,OR(LEFT(X16,2)="N1",RIGHT(X16,2)="N1")),0.5)+IF(AND(LEN(Y16)>2,OR(LEFT(Y16,2)="N1",RIGHT(Y16,2)="N1")),0.5)+IF(AND(LEN(Z16)>2,OR(LEFT(Z16,2)="N1",RIGHT(Z16,2)="N1")),0.5)+IF(AND(LEN(AA16)>2,OR(LEFT(AA16,2)="N1",RIGHT(AA16,2)="N1")),0.5)+IF(AND(LEN(AB16)>2,OR(LEFT(AB16,2)="N1",RIGHT(AB16,2)="N1")),0.5)+IF(AND(LEN(AC16)>2,OR(LEFT(AC16,2)="N1",RIGHT(AC16,2)="N1")),0.5)+IF(AND(LEN(AD16)>2,OR(LEFT(AD16,2)="N1",RIGHT(AD16,2)="N1")),0.5)+IF(AND(LEN(AE16)>2,OR(LEFT(AE16,2)="N1",RIGHT(AE16,2)="N1")),0.5)+IF(AND(LEN(AF16)>2,OR(LEFT(AF16,2)="N1",RIGHT(AF16,2)="N1")),0.5)+IF(AND(LEN(AG16)>2,OR(LEFT(AG16,2)="N1",RIGHT(AG16,2)="N1")),0.5)+IF(AND(LEN(AH16)>2,OR(LEFT(AH16,2)="N1",RIGHT(AH16,2)="N1")),0.5)+IF(AND(LEN(AI16)>2,OR(LEFT(AI16,2)="N1",RIGHT(AI16,2)="N1")),0.5)+IF(AND(LEN(AJ16)>2,OR(LEFT(AJ16,2)="N1",RIGHT(AJ16,2)="N1")),0.5)+IF(AND(LEN(AK16)>2,OR(LEFT(AK16,2)="N1",RIGHT(AK16,2)="N1")),0.5)+IF(AND(LEN(AL16)>2,OR(LEFT(AL16,2)="N1",RIGHT(AL16,2)="N1")),0.5)) -> 0 | AO16: =COUNTIF(H16:AL16,"ON")+COUNTIF(H16:AL16,"ON/2")/2 -> 0 | AP16: =IF(F16="","",COUNTIF($H16:$AL16,AP$8))+IF(F16="","",COUNTIF($H16:$AL16,$V$5)/2) -> 0 | AQ16: 0 | AR16: =IF(G16="","",AM16+AN16+AP16+AQ16) -> 20 | AS16: =IF(F16="","",COUNTIF($H16:$AL16,AS$8))++IF(F16="","",COUNTIF($H16:$AL16,"L1")/2) -> 2 | AT16: =AU16-AR16-AS16 -> 0 | AU16: 22
A17: =SUBTOTAL(3,$F$11:F17) -> 7 | B17: MS02 | C17: BGH | D17: Hiệu trưởng kiêm nhiệm | F17: Bùi Thanh Anh | G17: Chính Thức | H17: X | I17: X | J17: X | M17: X | N17: X | O17: X | P17: X | Q17: X | T17: X | U17: X | V17: X | W17: X | X17: X | AA17: X | AB17: X | AC17: X | AD17: X | AE17: X | AH17: L | AI17: X | AJ17: X | AK17: L | AM17: =IF(F17="","",COUNTIF($H17:$AL17,AM$8)) -> 20 | AN17: =IF(OR(G17="",G17="Đã nghỉ"),0,COUNTIF($H17:$AL17,"N1")/2++IF(AND(LEN(H17)>2,OR(LEFT(H17,2)="N1",RIGHT(H17,2)="N1")),0.5)+IF(AND(LEN(I17)>2,OR(LEFT(I17,2)="N1",RIGHT(I17,2)="N1")),0.5)+IF(AND(LEN(J17)>2,OR(LEFT(J17,2)="N1",RIGHT(J17,2)="N1")),0.5)+IF(AND(LEN(K17)>2,OR(LEFT(K17,2)="N1",RIGHT(K17,2)="N1")),0.5)+IF(AND(LEN(L17)>2,OR(LEFT(L17,2)="N1",RIGHT(L17,2)="N1")),0.5)+IF(AND(LEN(M17)>2,OR(LEFT(M17,2)="N1",RIGHT(M17,2)="N1")),0.5)+IF(AND(LEN(N17)>2,OR(LEFT(N17,2)="N1",RIGHT(N17,2)="N1")),0.5)+IF(AND(LEN(O17)>2,OR(LEFT(O17,2)="N1",RIGHT(O17,2)="N1")),0.5)+IF(AND(LEN(P17)>2,OR(LEFT(P17,2)="N1",RIGHT(P17,2)="N1")),0.5)+IF(AND(LEN(Q17)>2,OR(LEFT(Q17,2)="N1",RIGHT(Q17,2)="N1")),0.5)+IF(AND(LEN(R17)>2,OR(LEFT(R17,2)="N1",RIGHT(R17,2)="N1")),0.5)+IF(AND(LEN(S17)>2,OR(LEFT(S17,2)="N1",RIGHT(S17,2)="N1")),0.5)+IF(AND(LEN(T17)>2,OR(LEFT(T17,2)="N1",RIGHT(T17,2)="N1")),0.5)+IF(AND(LEN(U17)>2,OR(LEFT(U17,2)="N1",RIGHT(U17,2)="N1")),0.5)+IF(AND(LEN(V17)>2,OR(LEFT(V17,2)="N1",RIGHT(V17,2)="N1")),0.5)+IF(AND(LEN(W17)>2,OR(LEFT(W17,2)="N1",RIGHT(W17,2)="N1")),0.5)+IF(AND(LEN(X17)>2,OR(LEFT(X17,2)="N1",RIGHT(X17,2)="N1")),0.5)+IF(AND(LEN(Y17)>2,OR(LEFT(Y17,2)="N1",RIGHT(Y17,2)="N1")),0.5)+IF(AND(LEN(Z17)>2,OR(LEFT(Z17,2)="N1",RIGHT(Z17,2)="N1")),0.5)+IF(AND(LEN(AA17)>2,OR(LEFT(AA17,2)="N1",RIGHT(AA17,2)="N1")),0.5)+IF(AND(LEN(AB17)>2,OR(LEFT(AB17,2)="N1",RIGHT(AB17,2)="N1")),0.5)+IF(AND(LEN(AC17)>2,OR(LEFT(AC17,2)="N1",RIGHT(AC17,2)="N1")),0.5)+IF(AND(LEN(AD17)>2,OR(LEFT(AD17,2)="N1",RIGHT(AD17,2)="N1")),0.5)+IF(AND(LEN(AE17)>2,OR(LEFT(AE17,2)="N1",RIGHT(AE17,2)="N1")),0.5)+IF(AND(LEN(AF17)>2,OR(LEFT(AF17,2)="N1",RIGHT(AF17,2)="N1")),0.5)+IF(AND(LEN(AG17)>2,OR(LEFT(AG17,2)="N1",RIGHT(AG17,2)="N1")),0.5)+IF(AND(LEN(AH17)>2,OR(LEFT(AH17,2)="N1",RIGHT(AH17,2)="N1")),0.5)+IF(AND(LEN(AI17)>2,OR(LEFT(AI17,2)="N1",RIGHT(AI17,2)="N1")),0.5)+IF(AND(LEN(AJ17)>2,OR(LEFT(AJ17,2)="N1",RIGHT(AJ17,2)="N1")),0.5)+IF(AND(LEN(AK17)>2,OR(LEFT(AK17,2)="N1",RIGHT(AK17,2)="N1")),0.5)+IF(AND(LEN(AL17)>2,OR(LEFT(AL17,2)="N1",RIGHT(AL17,2)="N1")),0.5)) -> 0 | AO17: =COUNTIF(H17:AL17,"ON")+COUNTIF(H17:AL17,"ON/2")/2 -> 0 | AP17: =IF(F17="","",COUNTIF($H17:$AL17,AP$8))+IF(F17="","",COUNTIF($H17:$AL17,$V$5)/2) -> 0 | AQ17: 0 | AR17: =IF(G17="","",AM17+AN17+AP17+AQ17) -> 20 | AS17: =IF(F17="","",COUNTIF($H17:$AL17,AS$8))++IF(F17="","",COUNTIF($H17:$AL17,"L1")/2) -> 2 | AT17: =AU17-AR17-AS17 -> 0 | AU17: 22
A18: =SUBTOTAL(3,$F$11:F18) -> 8 | B18: MS11 | C18: Giáo viên | D18: Giáo viên mầm non | F18: Phùng Thị Lụa | G18: Chính Thức | H18: X | I18: X | J18: X | M18: X | N18: X | O18: X | P18: X | Q18: X | T18: X | U18: X | V18: X | W18: X | X18: X | AA18: X | AB18: X | AC18: X | AD18: X | AE18: X | AH18: L | AI18: X | AJ18: X | AK18: L | AM18: =IF(F18="","",COUNTIF($H18:$AL18,AM$8)) -> 20 | AN18: =IF(OR(G18="",G18="Đã nghỉ"),0,COUNTIF($H18:$AL18,"N1")/2++IF(AND(LEN(H18)>2,OR(LEFT(H18,2)="N1",RIGHT(H18,2)="N1")),0.5)+IF(AND(LEN(I18)>2,OR(LEFT(I18,2)="N1",RIGHT(I18,2)="N1")),0.5)+IF(AND(LEN(J18)>2,OR(LEFT(J18,2)="N1",RIGHT(J18,2)="N1")),0.5)+IF(AND(LEN(K18)>2,OR(LEFT(K18,2)="N1",RIGHT(K18,2)="N1")),0.5)+IF(AND(LEN(L18)>2,OR(LEFT(L18,2)="N1",RIGHT(L18,2)="N1")),0.5)+IF(AND(LEN(M18)>2,OR(LEFT(M18,2)="N1",RIGHT(M18,2)="N1")),0.5)+IF(AND(LEN(N18)>2,OR(LEFT(N18,2)="N1",RIGHT(N18,2)="N1")),0.5)+IF(AND(LEN(O18)>2,OR(LEFT(O18,2)="N1",RIGHT(O18,2)="N1")),0.5)+IF(AND(LEN(P18)>2,OR(LEFT(P18,2)="N1",RIGHT(P18,2)="N1")),0.5)+IF(AND(LEN(Q18)>2,OR(LEFT(Q18,2)="N1",RIGHT(Q18,2)="N1")),0.5)+IF(AND(LEN(R18)>2,OR(LEFT(R18,2)="N1",RIGHT(R18,2)="N1")),0.5)+IF(AND(LEN(S18)>2,OR(LEFT(S18,2)="N1",RIGHT(S18,2)="N1")),0.5)+IF(AND(LEN(T18)>2,OR(LEFT(T18,2)="N1",RIGHT(T18,2)="N1")),0.5)+IF(AND(LEN(U18)>2,OR(LEFT(U18,2)="N1",RIGHT(U18,2)="N1")),0.5)+IF(AND(LEN(V18)>2,OR(LEFT(V18,2)="N1",RIGHT(V18,2)="N1")),0.5)+IF(AND(LEN(W18)>2,OR(LEFT(W18,2)="N1",RIGHT(W18,2)="N1")),0.5)+IF(AND(LEN(X18)>2,OR(LEFT(X18,2)="N1",RIGHT(X18,2)="N1")),0.5)+IF(AND(LEN(Y18)>2,OR(LEFT(Y18,2)="N1",RIGHT(Y18,2)="N1")),0.5)+IF(AND(LEN(Z18)>2,OR(LEFT(Z18,2)="N1",RIGHT(Z18,2)="N1")),0.5)+IF(AND(LEN(AA18)>2,OR(LEFT(AA18,2)="N1",RIGHT(AA18,2)="N1")),0.5)+IF(AND(LEN(AB18)>2,OR(LEFT(AB18,2)="N1",RIGHT(AB18,2)="N1")),0.5)+IF(AND(LEN(AC18)>2,OR(LEFT(AC18,2)="N1",RIGHT(AC18,2)="N1")),0.5)+IF(AND(LEN(AD18)>2,OR(LEFT(AD18,2)="N1",RIGHT(AD18,2)="N1")),0.5)+IF(AND(LEN(AE18)>2,OR(LEFT(AE18,2)="N1",RIGHT(AE18,2)="N1")),0.5)+IF(AND(LEN(AF18)>2,OR(LEFT(AF18,2)="N1",RIGHT(AF18,2)="N1")),0.5)+IF(AND(LEN(AG18)>2,OR(LEFT(AG18,2)="N1",RIGHT(AG18,2)="N1")),0.5)+IF(AND(LEN(AH18)>2,OR(LEFT(AH18,2)="N1",RIGHT(AH18,2)="N1")),0.5)+IF(AND(LEN(AI18)>2,OR(LEFT(AI18,2)="N1",RIGHT(AI18,2)="N1")),0.5)+IF(AND(LEN(AJ18)>2,OR(LEFT(AJ18,2)="N1",RIGHT(AJ18,2)="N1")),0.5)+IF(AND(LEN(AK18)>2,OR(LEFT(AK18,2)="N1",RIGHT(AK18,2)="N1")),0.5)+IF(AND(LEN(AL18)>2,OR(LEFT(AL18,2)="N1",RIGHT(AL18,2)="N1")),0.5)) -> 0 | AO18: =COUNTIF(H18:AL18,"ON")+COUNTIF(H18:AL18,"ON/2")/2 -> 0 | AP18: =IF(F18="","",COUNTIF($H18:$AL18,AP$8))+IF(F18="","",COUNTIF($H18:$AL18,$V$5)/2) -> 0 | AQ18: 0 | AR18: =IF(G18="","",AM18+AN18+AP18+AQ18) -> 20 | AS18: =IF(F18="","",COUNTIF($H18:$AL18,AS$8))++IF(F18="","",COUNTIF($H18:$AL18,"L1")/2) -> 2 | AT18: =AU18-AR18-AS18 -> 0 | AU18: 22
A19: =SUBTOTAL(3,$F$11:F19) -> 9 | B19: MS12 | C19: Vận hành | D19: HK | F19: Đinh Thị Bích Ngọc | G19: Chính Thức | H19: X | I19: X | J19: X | M19: X | N19: X | O19: X | P19: X | Q19: X | T19: X | U19: X | V19: X | W19: X | X19: X | AA19: X | AB19: X | AC19: X | AD19: X | AE19: X | AH19: L | AI19: X | AJ19: X | AK19: L | AM19: =IF(F19="","",COUNTIF($H19:$AL19,AM$8)) -> 20 | AN19: =IF(OR(G19="",G19="Đã nghỉ"),0,COUNTIF($H19:$AL19,"N1")/2++IF(AND(LEN(H19)>2,OR(LEFT(H19,2)="N1",RIGHT(H19,2)="N1")),0.5)+IF(AND(LEN(I19)>2,OR(LEFT(I19,2)="N1",RIGHT(I19,2)="N1")),0.5)+IF(AND(LEN(J19)>2,OR(LEFT(J19,2)="N1",RIGHT(J19,2)="N1")),0.5)+IF(AND(LEN(K19)>2,OR(LEFT(K19,2)="N1",RIGHT(K19,2)="N1")),0.5)+IF(AND(LEN(L19)>2,OR(LEFT(L19,2)="N1",RIGHT(L19,2)="N1")),0.5)+IF(AND(LEN(M19)>2,OR(LEFT(M19,2)="N1",RIGHT(M19,2)="N1")),0.5)+IF(AND(LEN(N19)>2,OR(LEFT(N19,2)="N1",RIGHT(N19,2)="N1")),0.5)+IF(AND(LEN(O19)>2,OR(LEFT(O19,2)="N1",RIGHT(O19,2)="N1")),0.5)+IF(AND(LEN(P19)>2,OR(LEFT(P19,2)="N1",RIGHT(P19,2)="N1")),0.5)+IF(AND(LEN(Q19)>2,OR(LEFT(Q19,2)="N1",RIGHT(Q19,2)="N1")),0.5)+IF(AND(LEN(R19)>2,OR(LEFT(R19,2)="N1",RIGHT(R19,2)="N1")),0.5)+IF(AND(LEN(S19)>2,OR(LEFT(S19,2)="N1",RIGHT(S19,2)="N1")),0.5)+IF(AND(LEN(T19)>2,OR(LEFT(T19,2)="N1",RIGHT(T19,2)="N1")),0.5)+IF(AND(LEN(U19)>2,OR(LEFT(U19,2)="N1",RIGHT(U19,2)="N1")),0.5)+IF(AND(LEN(V19)>2,OR(LEFT(V19,2)="N1",RIGHT(V19,2)="N1")),0.5)+IF(AND(LEN(W19)>2,OR(LEFT(W19,2)="N1",RIGHT(W19,2)="N1")),0.5)+IF(AND(LEN(X19)>2,OR(LEFT(X19,2)="N1",RIGHT(X19,2)="N1")),0.5)+IF(AND(LEN(Y19)>2,OR(LEFT(Y19,2)="N1",RIGHT(Y19,2)="N1")),0.5)+IF(AND(LEN(Z19)>2,OR(LEFT(Z19,2)="N1",RIGHT(Z19,2)="N1")),0.5)+IF(AND(LEN(AA19)>2,OR(LEFT(AA19,2)="N1",RIGHT(AA19,2)="N1")),0.5)+IF(AND(LEN(AB19)>2,OR(LEFT(AB19,2)="N1",RIGHT(AB19,2)="N1")),0.5)+IF(AND(LEN(AC19)>2,OR(LEFT(AC19,2)="N1",RIGHT(AC19,2)="N1")),0.5)+IF(AND(LEN(AD19)>2,OR(LEFT(AD19,2)="N1",RIGHT(AD19,2)="N1")),0.5)+IF(AND(LEN(AE19)>2,OR(LEFT(AE19,2)="N1",RIGHT(AE19,2)="N1")),0.5)+IF(AND(LEN(AF19)>2,OR(LEFT(AF19,2)="N1",RIGHT(AF19,2)="N1")),0.5)+IF(AND(LEN(AG19)>2,OR(LEFT(AG19,2)="N1",RIGHT(AG19,2)="N1")),0.5)+IF(AND(LEN(AH19)>2,OR(LEFT(AH19,2)="N1",RIGHT(AH19,2)="N1")),0.5)+IF(AND(LEN(AI19)>2,OR(LEFT(AI19,2)="N1",RIGHT(AI19,2)="N1")),0.5)+IF(AND(LEN(AJ19)>2,OR(LEFT(AJ19,2)="N1",RIGHT(AJ19,2)="N1")),0.5)+IF(AND(LEN(AK19)>2,OR(LEFT(AK19,2)="N1",RIGHT(AK19,2)="N1")),0.5)+IF(AND(LEN(AL19)>2,OR(LEFT(AL19,2)="N1",RIGHT(AL19,2)="N1")),0.5)) -> 0 | AO19: =COUNTIF(H19:AL19,"ON")+COUNTIF(H19:AL19,"ON/2")/2 -> 0 | AP19: =IF(F19="","",COUNTIF($H19:$AL19,AP$8))+IF(F19="","",COUNTIF($H19:$AL19,$V$5)/2) -> 0 | AQ19: 0 | AR19: =IF(G19="","",AM19+AN19+AP19+AQ19) -> 20 | AS19: =IF(F19="","",COUNTIF($H19:$AL19,AS$8))++IF(F19="","",COUNTIF($H19:$AL19,"L1")/2) -> 2 | AT19: =AU19-AR19-AS19 -> 0 | AU19: 22
A20: =SUBTOTAL(3,$F$11:F20) -> 10 | B20: MS13 | C20: Vận hành | D20: Bảo vệ | F20: Lương Văn Châm | G20: Thử Việc | H20: X | I20: X | J20: X | M20: X | N20: X | O20: X | P20: X | Q20: X | AM20: =IF(F20="","",COUNTIF($H20:$AL20,AM$8)) -> 8 | AN20: =IF(OR(G20="",G20="Đã nghỉ"),0,COUNTIF($H20:$AL20,"N1")/2++IF(AND(LEN(H20)>2,OR(LEFT(H20,2)="N1",RIGHT(H20,2)="N1")),0.5)+IF(AND(LEN(I20)>2,OR(LEFT(I20,2)="N1",RIGHT(I20,2)="N1")),0.5)+IF(AND(LEN(J20)>2,OR(LEFT(J20,2)="N1",RIGHT(J20,2)="N1")),0.5)+IF(AND(LEN(K20)>2,OR(LEFT(K20,2)="N1",RIGHT(K20,2)="N1")),0.5)+IF(AND(LEN(L20)>2,OR(LEFT(L20,2)="N1",RIGHT(L20,2)="N1")),0.5)+IF(AND(LEN(M20)>2,OR(LEFT(M20,2)="N1",RIGHT(M20,2)="N1")),0.5)+IF(AND(LEN(N20)>2,OR(LEFT(N20,2)="N1",RIGHT(N20,2)="N1")),0.5)+IF(AND(LEN(O20)>2,OR(LEFT(O20,2)="N1",RIGHT(O20,2)="N1")),0.5)+IF(AND(LEN(P20)>2,OR(LEFT(P20,2)="N1",RIGHT(P20,2)="N1")),0.5)+IF(AND(LEN(Q20)>2,OR(LEFT(Q20,2)="N1",RIGHT(Q20,2)="N1")),0.5)+IF(AND(LEN(R20)>2,OR(LEFT(R20,2)="N1",RIGHT(R20,2)="N1")),0.5)+IF(AND(LEN(S20)>2,OR(LEFT(S20,2)="N1",RIGHT(S20,2)="N1")),0.5)+IF(AND(LEN(T20)>2,OR(LEFT(T20,2)="N1",RIGHT(T20,2)="N1")),0.5)+IF(AND(LEN(U20)>2,OR(LEFT(U20,2)="N1",RIGHT(U20,2)="N1")),0.5)+IF(AND(LEN(V20)>2,OR(LEFT(V20,2)="N1",RIGHT(V20,2)="N1")),0.5)+IF(AND(LEN(W20)>2,OR(LEFT(W20,2)="N1",RIGHT(W20,2)="N1")),0.5)+IF(AND(LEN(X20)>2,OR(LEFT(X20,2)="N1",RIGHT(X20,2)="N1")),0.5)+IF(AND(LEN(Y20)>2,OR(LEFT(Y20,2)="N1",RIGHT(Y20,2)="N1")),0.5)+IF(AND(LEN(Z20)>2,OR(LEFT(Z20,2)="N1",RIGHT(Z20,2)="N1")),0.5)+IF(AND(LEN(AA20)>2,OR(LEFT(AA20,2)="N1",RIGHT(AA20,2)="N1")),0.5)+IF(AND(LEN(AB20)>2,OR(LEFT(AB20,2)="N1",RIGHT(AB20,2)="N1")),0.5)+IF(AND(LEN(AC20)>2,OR(LEFT(AC20,2)="N1",RIGHT(AC20,2)="N1")),0.5)+IF(AND(LEN(AD20)>2,OR(LEFT(AD20,2)="N1",RIGHT(AD20,2)="N1")),0.5)+IF(AND(LEN(AE20)>2,OR(LEFT(AE20,2)="N1",RIGHT(AE20,2)="N1")),0.5)+IF(AND(LEN(AF20)>2,OR(LEFT(AF20,2)="N1",RIGHT(AF20,2)="N1")),0.5)+IF(AND(LEN(AG20)>2,OR(LEFT(AG20,2)="N1",RIGHT(AG20,2)="N1")),0.5)+IF(AND(LEN(AH20)>2,OR(LEFT(AH20,2)="N1",RIGHT(AH20,2)="N1")),0.5)+IF(AND(LEN(AI20)>2,OR(LEFT(AI20,2)="N1",RIGHT(AI20,2)="N1")),0.5)+IF(AND(LEN(AJ20)>2,OR(LEFT(AJ20,2)="N1",RIGHT(AJ20,2)="N1")),0.5)+IF(AND(LEN(AK20)>2,OR(LEFT(AK20,2)="N1",RIGHT(AK20,2)="N1")),0.5)+IF(AND(LEN(AL20)>2,OR(LEFT(AL20,2)="N1",RIGHT(AL20,2)="N1")),0.5)) -> 0 | AO20: =COUNTIF(H20:AL20,"ON")+COUNTIF(H20:AL20,"ON/2")/2 -> 0 | AP20: =IF(F20="","",COUNTIF($H20:$AL20,AP$8))+IF(F20="","",COUNTIF($H20:$AL20,$V$5)/2) -> 0 | AQ20: 0 | AR20: =IF(G20="","",AM20+AN20+AP20+AQ20) -> 8 | AS20: =IF(F20="","",COUNTIF($H20:$AL20,AS$8))++IF(F20="","",COUNTIF($H20:$AL20,"L1")/2) -> 0 | AT20: =AU20-AR20-AS20 -> 0 | AU20: 8
A21: 10 | B21: MS13 | C21: Vận hành | D21: Bảo vệ | F21: Lương Văn Châm | G21: Chính Thức | T21: X | U21: X | V21: X | W21: X | X21: X | AA21: X | AB21: X | AC21: X | AD21: X | AE21: X | AH21: L | AI21: X | AJ21: X | AK21: L | AM21: =IF(F21="","",COUNTIF($H21:$AL21,AM$8)) -> 12 | AN21: =IF(OR(G21="",G21="Đã nghỉ"),0,COUNTIF($H21:$AL21,"N1")/2++IF(AND(LEN(H21)>2,OR(LEFT(H21,2)="N1",RIGHT(H21,2)="N1")),0.5)+IF(AND(LEN(I21)>2,OR(LEFT(I21,2)="N1",RIGHT(I21,2)="N1")),0.5)+IF(AND(LEN(J21)>2,OR(LEFT(J21,2)="N1",RIGHT(J21,2)="N1")),0.5)+IF(AND(LEN(K21)>2,OR(LEFT(K21,2)="N1",RIGHT(K21,2)="N1")),0.5)+IF(AND(LEN(L21)>2,OR(LEFT(L21,2)="N1",RIGHT(L21,2)="N1")),0.5)+IF(AND(LEN(M21)>2,OR(LEFT(M21,2)="N1",RIGHT(M21,2)="N1")),0.5)+IF(AND(LEN(N21)>2,OR(LEFT(N21,2)="N1",RIGHT(N21,2)="N1")),0.5)+IF(AND(LEN(O21)>2,OR(LEFT(O21,2)="N1",RIGHT(O21,2)="N1")),0.5)+IF(AND(LEN(P21)>2,OR(LEFT(P21,2)="N1",RIGHT(P21,2)="N1")),0.5)+IF(AND(LEN(Q21)>2,OR(LEFT(Q21,2)="N1",RIGHT(Q21,2)="N1")),0.5)+IF(AND(LEN(R21)>2,OR(LEFT(R21,2)="N1",RIGHT(R21,2)="N1")),0.5)+IF(AND(LEN(S21)>2,OR(LEFT(S21,2)="N1",RIGHT(S21,2)="N1")),0.5)+IF(AND(LEN(T21)>2,OR(LEFT(T21,2)="N1",RIGHT(T21,2)="N1")),0.5)+IF(AND(LEN(U21)>2,OR(LEFT(U21,2)="N1",RIGHT(U21,2)="N1")),0.5)+IF(AND(LEN(V21)>2,OR(LEFT(V21,2)="N1",RIGHT(V21,2)="N1")),0.5)+IF(AND(LEN(W21)>2,OR(LEFT(W21,2)="N1",RIGHT(W21,2)="N1")),0.5)+IF(AND(LEN(X21)>2,OR(LEFT(X21,2)="N1",RIGHT(X21,2)="N1")),0.5)+IF(AND(LEN(Y21)>2,OR(LEFT(Y21,2)="N1",RIGHT(Y21,2)="N1")),0.5)+IF(AND(LEN(Z21)>2,OR(LEFT(Z21,2)="N1",RIGHT(Z21,2)="N1")),0.5)+IF(AND(LEN(AA21)>2,OR(LEFT(AA21,2)="N1",RIGHT(AA21,2)="N1")),0.5)+IF(AND(LEN(AB21)>2,OR(LEFT(AB21,2)="N1",RIGHT(AB21,2)="N1")),0.5)+IF(AND(LEN(AC21)>2,OR(LEFT(AC21,2)="N1",RIGHT(AC21,2)="N1")),0.5)+IF(AND(LEN(AD21)>2,OR(LEFT(AD21,2)="N1",RIGHT(AD21,2)="N1")),0.5)+IF(AND(LEN(AE21)>2,OR(LEFT(AE21,2)="N1",RIGHT(AE21,2)="N1")),0.5)+IF(AND(LEN(AF21)>2,OR(LEFT(AF21,2)="N1",RIGHT(AF21,2)="N1")),0.5)+IF(AND(LEN(AG21)>2,OR(LEFT(AG21,2)="N1",RIGHT(AG21,2)="N1")),0.5)+IF(AND(LEN(AH21)>2,OR(LEFT(AH21,2)="N1",RIGHT(AH21,2)="N1")),0.5)+IF(AND(LEN(AI21)>2,OR(LEFT(AI21,2)="N1",RIGHT(AI21,2)="N1")),0.5)+IF(AND(LEN(AJ21)>2,OR(LEFT(AJ21,2)="N1",RIGHT(AJ21,2)="N1")),0.5)+IF(AND(LEN(AK21)>2,OR(LEFT(AK21,2)="N1",RIGHT(AK21,2)="N1")),0.5)+IF(AND(LEN(AL21)>2,OR(LEFT(AL21,2)="N1",RIGHT(AL21,2)="N1")),0.5)) -> 0 | AO21: =COUNTIF(H21:AL21,"ON")+COUNTIF(H21:AL21,"ON/2")/2 -> 0 | AP21: =IF(F21="","",COUNTIF($H21:$AL21,AP$8))+IF(F21="","",COUNTIF($H21:$AL21,$V$5)/2) -> 0 | AQ21: 0 | AR21: =IF(G21="","",AM21+AN21+AP21+AQ21) -> 12 | AS21: =IF(F21="","",COUNTIF($H21:$AL21,AS$8))++IF(F21="","",COUNTIF($H21:$AL21,"L1")/2) -> 2 | AT21: =AU21-AR21-AS21 -> 0 | AU21: 14
A22: 11 | B22: MS14 | C22: Vận hành | D22: Y tế | F22: Nguyễn Thị Phúc | G22: Chính Thức | H22: X | I22: X | J22: X | M22: X | N22: X | O22: X | P22: X | Q22: X | T22: X | U22: X | V22: X | W22: X | X22: X | AA22: X | AB22: X | AC22: X | AD22: X | AE22: X | AH22: L | AI22: X | AJ22: X | AK22: L | AM22: =IF(F22="","",COUNTIF($H22:$AL22,AM$8)) -> 20 | AN22: =IF(OR(G22="",G22="Đã nghỉ"),0,COUNTIF($H22:$AL22,"N1")/2++IF(AND(LEN(H22)>2,OR(LEFT(H22,2)="N1",RIGHT(H22,2)="N1")),0.5)+IF(AND(LEN(I22)>2,OR(LEFT(I22,2)="N1",RIGHT(I22,2)="N1")),0.5)+IF(AND(LEN(J22)>2,OR(LEFT(J22,2)="N1",RIGHT(J22,2)="N1")),0.5)+IF(AND(LEN(K22)>2,OR(LEFT(K22,2)="N1",RIGHT(K22,2)="N1")),0.5)+IF(AND(LEN(L22)>2,OR(LEFT(L22,2)="N1",RIGHT(L22,2)="N1")),0.5)+IF(AND(LEN(M22)>2,OR(LEFT(M22,2)="N1",RIGHT(M22,2)="N1")),0.5)+IF(AND(LEN(N22)>2,OR(LEFT(N22,2)="N1",RIGHT(N22,2)="N1")),0.5)+IF(AND(LEN(O22)>2,OR(LEFT(O22,2)="N1",RIGHT(O22,2)="N1")),0.5)+IF(AND(LEN(P22)>2,OR(LEFT(P22,2)="N1",RIGHT(P22,2)="N1")),0.5)+IF(AND(LEN(Q22)>2,OR(LEFT(Q22,2)="N1",RIGHT(Q22,2)="N1")),0.5)+IF(AND(LEN(R22)>2,OR(LEFT(R22,2)="N1",RIGHT(R22,2)="N1")),0.5)+IF(AND(LEN(S22)>2,OR(LEFT(S22,2)="N1",RIGHT(S22,2)="N1")),0.5)+IF(AND(LEN(T22)>2,OR(LEFT(T22,2)="N1",RIGHT(T22,2)="N1")),0.5)+IF(AND(LEN(U22)>2,OR(LEFT(U22,2)="N1",RIGHT(U22,2)="N1")),0.5)+IF(AND(LEN(V22)>2,OR(LEFT(V22,2)="N1",RIGHT(V22,2)="N1")),0.5)+IF(AND(LEN(W22)>2,OR(LEFT(W22,2)="N1",RIGHT(W22,2)="N1")),0.5)+IF(AND(LEN(X22)>2,OR(LEFT(X22,2)="N1",RIGHT(X22,2)="N1")),0.5)+IF(AND(LEN(Y22)>2,OR(LEFT(Y22,2)="N1",RIGHT(Y22,2)="N1")),0.5)+IF(AND(LEN(Z22)>2,OR(LEFT(Z22,2)="N1",RIGHT(Z22,2)="N1")),0.5)+IF(AND(LEN(AA22)>2,OR(LEFT(AA22,2)="N1",RIGHT(AA22,2)="N1")),0.5)+IF(AND(LEN(AB22)>2,OR(LEFT(AB22,2)="N1",RIGHT(AB22,2)="N1")),0.5)+IF(AND(LEN(AC22)>2,OR(LEFT(AC22,2)="N1",RIGHT(AC22,2)="N1")),0.5)+IF(AND(LEN(AD22)>2,OR(LEFT(AD22,2)="N1",RIGHT(AD22,2)="N1")),0.5)+IF(AND(LEN(AE22)>2,OR(LEFT(AE22,2)="N1",RIGHT(AE22,2)="N1")),0.5)+IF(AND(LEN(AF22)>2,OR(LEFT(AF22,2)="N1",RIGHT(AF22,2)="N1")),0.5)+IF(AND(LEN(AG22)>2,OR(LEFT(AG22,2)="N1",RIGHT(AG22,2)="N1")),0.5)+IF(AND(LEN(AH22)>2,OR(LEFT(AH22,2)="N1",RIGHT(AH22,2)="N1")),0.5)+IF(AND(LEN(AI22)>2,OR(LEFT(AI22,2)="N1",RIGHT(AI22,2)="N1")),0.5)+IF(AND(LEN(AJ22)>2,OR(LEFT(AJ22,2)="N1",RIGHT(AJ22,2)="N1")),0.5)+IF(AND(LEN(AK22)>2,OR(LEFT(AK22,2)="N1",RIGHT(AK22,2)="N1")),0.5)+IF(AND(LEN(AL22)>2,OR(LEFT(AL22,2)="N1",RIGHT(AL22,2)="N1")),0.5)) -> 0 | AO22: =COUNTIF(H22:AL22,"ON")+COUNTIF(H22:AL22,"ON/2")/2 -> 0 | AP22: =IF(F22="","",COUNTIF($H22:$AL22,AP$8))+IF(F22="","",COUNTIF($H22:$AL22,$V$5)/2) -> 0 | AQ22: 0 | AR22: =IF(G22="","",AM22+AN22+AP22+AQ22) -> 20 | AS22: =IF(F22="","",COUNTIF($H22:$AL22,AS$8))++IF(F22="","",COUNTIF($H22:$AL22,"L1")/2) -> 2 | AT22: =AU22-AR22-AS22 -> 0 | AU22: 22
A23: 12 | B23: MS15 | C23: Vận hành | D23: Vận hành | F23: Nguyễn Thị Thuỳ Trang | G23: Thử Việc | H23: X | I23: X | J23: X | M23: X | N23: X | O23: X | T23: X | U23: X | V23: X | W23: X | X23: X | AA23: X | AB23: X | AC23: X | AD23: X | AE23: X | AM23: =IF(F23="","",COUNTIF($H23:$AL23,AM$8)) -> 16 | AN23: =IF(OR(G23="",G23="Đã nghỉ"),0,COUNTIF($H23:$AL23,"N1")/2++IF(AND(LEN(H23)>2,OR(LEFT(H23,2)="N1",RIGHT(H23,2)="N1")),0.5)+IF(AND(LEN(I23)>2,OR(LEFT(I23,2)="N1",RIGHT(I23,2)="N1")),0.5)+IF(AND(LEN(J23)>2,OR(LEFT(J23,2)="N1",RIGHT(J23,2)="N1")),0.5)+IF(AND(LEN(K23)>2,OR(LEFT(K23,2)="N1",RIGHT(K23,2)="N1")),0.5)+IF(AND(LEN(L23)>2,OR(LEFT(L23,2)="N1",RIGHT(L23,2)="N1")),0.5)+IF(AND(LEN(M23)>2,OR(LEFT(M23,2)="N1",RIGHT(M23,2)="N1")),0.5)+IF(AND(LEN(N23)>2,OR(LEFT(N23,2)="N1",RIGHT(N23,2)="N1")),0.5)+IF(AND(LEN(O23)>2,OR(LEFT(O23,2)="N1",RIGHT(O23,2)="N1")),0.5)+IF(AND(LEN(P23)>2,OR(LEFT(P23,2)="N1",RIGHT(P23,2)="N1")),0.5)+IF(AND(LEN(Q23)>2,OR(LEFT(Q23,2)="N1",RIGHT(Q23,2)="N1")),0.5)+IF(AND(LEN(R23)>2,OR(LEFT(R23,2)="N1",RIGHT(R23,2)="N1")),0.5)+IF(AND(LEN(S23)>2,OR(LEFT(S23,2)="N1",RIGHT(S23,2)="N1")),0.5)+IF(AND(LEN(T23)>2,OR(LEFT(T23,2)="N1",RIGHT(T23,2)="N1")),0.5)+IF(AND(LEN(U23)>2,OR(LEFT(U23,2)="N1",RIGHT(U23,2)="N1")),0.5)+IF(AND(LEN(V23)>2,OR(LEFT(V23,2)="N1",RIGHT(V23,2)="N1")),0.5)+IF(AND(LEN(W23)>2,OR(LEFT(W23,2)="N1",RIGHT(W23,2)="N1")),0.5)+IF(AND(LEN(X23)>2,OR(LEFT(X23,2)="N1",RIGHT(X23,2)="N1")),0.5)+IF(AND(LEN(Y23)>2,OR(LEFT(Y23,2)="N1",RIGHT(Y23,2)="N1")),0.5)+IF(AND(LEN(Z23)>2,OR(LEFT(Z23,2)="N1",RIGHT(Z23,2)="N1")),0.5)+IF(AND(LEN(AA23)>2,OR(LEFT(AA23,2)="N1",RIGHT(AA23,2)="N1")),0.5)+IF(AND(LEN(AB23)>2,OR(LEFT(AB23,2)="N1",RIGHT(AB23,2)="N1")),0.5)+IF(AND(LEN(AC23)>2,OR(LEFT(AC23,2)="N1",RIGHT(AC23,2)="N1")),0.5)+IF(AND(LEN(AD23)>2,OR(LEFT(AD23,2)="N1",RIGHT(AD23,2)="N1")),0.5)+IF(AND(LEN(AE23)>2,OR(LEFT(AE23,2)="N1",RIGHT(AE23,2)="N1")),0.5)+IF(AND(LEN(AF23)>2,OR(LEFT(AF23,2)="N1",RIGHT(AF23,2)="N1")),0.5)+IF(AND(LEN(AG23)>2,OR(LEFT(AG23,2)="N1",RIGHT(AG23,2)="N1")),0.5)+IF(AND(LEN(AH23)>2,OR(LEFT(AH23,2)="N1",RIGHT(AH23,2)="N1")),0.5)+IF(AND(LEN(AI23)>2,OR(LEFT(AI23,2)="N1",RIGHT(AI23,2)="N1")),0.5)+IF(AND(LEN(AJ23)>2,OR(LEFT(AJ23,2)="N1",RIGHT(AJ23,2)="N1")),0.5)+IF(AND(LEN(AK23)>2,OR(LEFT(AK23,2)="N1",RIGHT(AK23,2)="N1")),0.5)+IF(AND(LEN(AL23)>2,OR(LEFT(AL23,2)="N1",RIGHT(AL23,2)="N1")),0.5)) -> 0 | AO23: =COUNTIF(H23:AL23,"ON")+COUNTIF(H23:AL23,"ON/2")/2 -> 0 | AP23: =IF(F23="","",COUNTIF($H23:$AL23,AP$8))+IF(F23="","",COUNTIF($H23:$AL23,$V$5)/2) -> 0 | AQ23: 0 | AR23: =IF(G23="","",AM23+AN23+AP23+AQ23) -> 16 | AS23: =IF(F23="","",COUNTIF($H23:$AL23,AS$8))++IF(F23="","",COUNTIF($H23:$AL23,"L1")/2) -> 0 | AT23: =AU23-AR23-AS23 -> 6 | AU23: 22
A24: 13 | B24: MS17 | C24: Giáo viên | D24: Giáo viên mầm non | F24: Lê Thị Bích Hường | G24: Thử Việc | M24: X | N24: X | O24: X | P24: X | Q24: X | T24: X | U24: X | V24: X | W24: X | X24: X | AA24: X | AB24: X | AC24: X | AD24: X | AE24: X | AH24: K | AI24: X | AJ24: X | AK24: K | AM24: =IF(F24="","",COUNTIF($H24:$AL24,AM$8)) -> 17 | AN24: =IF(OR(G24="",G24="Đã nghỉ"),0,COUNTIF($H24:$AL24,"N1")/2++IF(AND(LEN(H24)>2,OR(LEFT(H24,2)="N1",RIGHT(H24,2)="N1")),0.5)+IF(AND(LEN(I24)>2,OR(LEFT(I24,2)="N1",RIGHT(I24,2)="N1")),0.5)+IF(AND(LEN(J24)>2,OR(LEFT(J24,2)="N1",RIGHT(J24,2)="N1")),0.5)+IF(AND(LEN(K24)>2,OR(LEFT(K24,2)="N1",RIGHT(K24,2)="N1")),0.5)+IF(AND(LEN(L24)>2,OR(LEFT(L24,2)="N1",RIGHT(L24,2)="N1")),0.5)+IF(AND(LEN(M24)>2,OR(LEFT(M24,2)="N1",RIGHT(M24,2)="N1")),0.5)+IF(AND(LEN(N24)>2,OR(LEFT(N24,2)="N1",RIGHT(N24,2)="N1")),0.5)+IF(AND(LEN(O24)>2,OR(LEFT(O24,2)="N1",RIGHT(O24,2)="N1")),0.5)+IF(AND(LEN(P24)>2,OR(LEFT(P24,2)="N1",RIGHT(P24,2)="N1")),0.5)+IF(AND(LEN(Q24)>2,OR(LEFT(Q24,2)="N1",RIGHT(Q24,2)="N1")),0.5)+IF(AND(LEN(R24)>2,OR(LEFT(R24,2)="N1",RIGHT(R24,2)="N1")),0.5)+IF(AND(LEN(S24)>2,OR(LEFT(S24,2)="N1",RIGHT(S24,2)="N1")),0.5)+IF(AND(LEN(T24)>2,OR(LEFT(T24,2)="N1",RIGHT(T24,2)="N1")),0.5)+IF(AND(LEN(U24)>2,OR(LEFT(U24,2)="N1",RIGHT(U24,2)="N1")),0.5)+IF(AND(LEN(V24)>2,OR(LEFT(V24,2)="N1",RIGHT(V24,2)="N1")),0.5)+IF(AND(LEN(W24)>2,OR(LEFT(W24,2)="N1",RIGHT(W24,2)="N1")),0.5)+IF(AND(LEN(X24)>2,OR(LEFT(X24,2)="N1",RIGHT(X24,2)="N1")),0.5)+IF(AND(LEN(Y24)>2,OR(LEFT(Y24,2)="N1",RIGHT(Y24,2)="N1")),0.5)+IF(AND(LEN(Z24)>2,OR(LEFT(Z24,2)="N1",RIGHT(Z24,2)="N1")),0.5)+IF(AND(LEN(AA24)>2,OR(LEFT(AA24,2)="N1",RIGHT(AA24,2)="N1")),0.5)+IF(AND(LEN(AB24)>2,OR(LEFT(AB24,2)="N1",RIGHT(AB24,2)="N1")),0.5)+IF(AND(LEN(AC24)>2,OR(LEFT(AC24,2)="N1",RIGHT(AC24,2)="N1")),0.5)+IF(AND(LEN(AD24)>2,OR(LEFT(AD24,2)="N1",RIGHT(AD24,2)="N1")),0.5)+IF(AND(LEN(AE24)>2,OR(LEFT(AE24,2)="N1",RIGHT(AE24,2)="N1")),0.5)+IF(AND(LEN(AF24)>2,OR(LEFT(AF24,2)="N1",RIGHT(AF24,2)="N1")),0.5)+IF(AND(LEN(AG24)>2,OR(LEFT(AG24,2)="N1",RIGHT(AG24,2)="N1")),0.5)+IF(AND(LEN(AH24)>2,OR(LEFT(AH24,2)="N1",RIGHT(AH24,2)="N1")),0.5)+IF(AND(LEN(AI24)>2,OR(LEFT(AI24,2)="N1",RIGHT(AI24,2)="N1")),0.5)+IF(AND(LEN(AJ24)>2,OR(LEFT(AJ24,2)="N1",RIGHT(AJ24,2)="N1")),0.5)+IF(AND(LEN(AK24)>2,OR(LEFT(AK24,2)="N1",RIGHT(AK24,2)="N1")),0.5)+IF(AND(LEN(AL24)>2,OR(LEFT(AL24,2)="N1",RIGHT(AL24,2)="N1")),0.5)) -> 0 | AO24: =COUNTIF(H24:AL24,"ON")+COUNTIF(H24:AL24,"ON/2")/2 -> 0 | AP24: =IF(F24="","",COUNTIF($H24:$AL24,AP$8))+IF(F24="","",COUNTIF($H24:$AL24,$V$5)/2) -> 0 | AQ24: 0 | AR24: =IF(G24="","",AM24+AN24+AP24+AQ24) -> 17 | AS24: =IF(F24="","",COUNTIF($H24:$AL24,AS$8))++IF(F24="","",COUNTIF($H24:$AL24,"L1")/2) -> 0 | AT24: =AU24-AR24-AS24 -> 5 | AU24: 22
A25: 14 | B25: MS18 | C25: Giáo viên | D25: Giáo viên mầm non | F25: Nguyễn Hương Thảo | G25: Thử Việc | N25: X | O25: X | P25: X | Q25: X | T25: X | U25: X | V25: X | W25: X | X25: X | AA25: X | AB25: X | AC25: X | AD25: X | AE25: X | AH25: K | AI25: X | AJ25: X | AK25: K | AM25: =IF(F25="","",COUNTIF($H25:$AL25,AM$8)) -> 16 | AN25: =IF(OR(G25="",G25="Đã nghỉ"),0,COUNTIF($H25:$AL25,"N1")/2++IF(AND(LEN(H25)>2,OR(LEFT(H25,2)="N1",RIGHT(H25,2)="N1")),0.5)+IF(AND(LEN(I25)>2,OR(LEFT(I25,2)="N1",RIGHT(I25,2)="N1")),0.5)+IF(AND(LEN(J25)>2,OR(LEFT(J25,2)="N1",RIGHT(J25,2)="N1")),0.5)+IF(AND(LEN(K25)>2,OR(LEFT(K25,2)="N1",RIGHT(K25,2)="N1")),0.5)+IF(AND(LEN(L25)>2,OR(LEFT(L25,2)="N1",RIGHT(L25,2)="N1")),0.5)+IF(AND(LEN(M25)>2,OR(LEFT(M25,2)="N1",RIGHT(M25,2)="N1")),0.5)+IF(AND(LEN(N25)>2,OR(LEFT(N25,2)="N1",RIGHT(N25,2)="N1")),0.5)+IF(AND(LEN(O25)>2,OR(LEFT(O25,2)="N1",RIGHT(O25,2)="N1")),0.5)+IF(AND(LEN(P25)>2,OR(LEFT(P25,2)="N1",RIGHT(P25,2)="N1")),0.5)+IF(AND(LEN(Q25)>2,OR(LEFT(Q25,2)="N1",RIGHT(Q25,2)="N1")),0.5)+IF(AND(LEN(R25)>2,OR(LEFT(R25,2)="N1",RIGHT(R25,2)="N1")),0.5)+IF(AND(LEN(S25)>2,OR(LEFT(S25,2)="N1",RIGHT(S25,2)="N1")),0.5)+IF(AND(LEN(T25)>2,OR(LEFT(T25,2)="N1",RIGHT(T25,2)="N1")),0.5)+IF(AND(LEN(U25)>2,OR(LEFT(U25,2)="N1",RIGHT(U25,2)="N1")),0.5)+IF(AND(LEN(V25)>2,OR(LEFT(V25,2)="N1",RIGHT(V25,2)="N1")),0.5)+IF(AND(LEN(W25)>2,OR(LEFT(W25,2)="N1",RIGHT(W25,2)="N1")),0.5)+IF(AND(LEN(X25)>2,OR(LEFT(X25,2)="N1",RIGHT(X25,2)="N1")),0.5)+IF(AND(LEN(Y25)>2,OR(LEFT(Y25,2)="N1",RIGHT(Y25,2)="N1")),0.5)+IF(AND(LEN(Z25)>2,OR(LEFT(Z25,2)="N1",RIGHT(Z25,2)="N1")),0.5)+IF(AND(LEN(AA25)>2,OR(LEFT(AA25,2)="N1",RIGHT(AA25,2)="N1")),0.5)+IF(AND(LEN(AB25)>2,OR(LEFT(AB25,2)="N1",RIGHT(AB25,2)="N1")),0.5)+IF(AND(LEN(AC25)>2,OR(LEFT(AC25,2)="N1",RIGHT(AC25,2)="N1")),0.5)+IF(AND(LEN(AD25)>2,OR(LEFT(AD25,2)="N1",RIGHT(AD25,2)="N1")),0.5)+IF(AND(LEN(AE25)>2,OR(LEFT(AE25,2)="N1",RIGHT(AE25,2)="N1")),0.5)+IF(AND(LEN(AF25)>2,OR(LEFT(AF25,2)="N1",RIGHT(AF25,2)="N1")),0.5)+IF(AND(LEN(AG25)>2,OR(LEFT(AG25,2)="N1",RIGHT(AG25,2)="N1")),0.5)+IF(AND(LEN(AH25)>2,OR(LEFT(AH25,2)="N1",RIGHT(AH25,2)="N1")),0.5)+IF(AND(LEN(AI25)>2,OR(LEFT(AI25,2)="N1",RIGHT(AI25,2)="N1")),0.5)+IF(AND(LEN(AJ25)>2,OR(LEFT(AJ25,2)="N1",RIGHT(AJ25,2)="N1")),0.5)+IF(AND(LEN(AK25)>2,OR(LEFT(AK25,2)="N1",RIGHT(AK25,2)="N1")),0.5)+IF(AND(LEN(AL25)>2,OR(LEFT(AL25,2)="N1",RIGHT(AL25,2)="N1")),0.5)) -> 0 | AO25: =COUNTIF(H25:AL25,"ON")+COUNTIF(H25:AL25,"ON/2")/2 -> 0 | AP25: =IF(F25="","",COUNTIF($H25:$AL25,AP$8))+IF(F25="","",COUNTIF($H25:$AL25,$V$5)/2) -> 0 | AQ25: 0 | AR25: =IF(G25="","",AM25+AN25+AP25+AQ25) -> 16 | AS25: =IF(F25="","",COUNTIF($H25:$AL25,AS$8))++IF(F25="","",COUNTIF($H25:$AL25,"L1")/2) -> 0 | AT25: =AU25-AR25-AS25 -> 6 | AU25: 22
A26: 15 | B26: MS19 | C26: Vận hành | D26: Nhân viên bếp | F26: Bác Hạnh | G26: Part Time | H26: X | I26: X | J26: X | M26: X | N26: X | O26: X | P26: X | Q26: X | T26: X | U26: X | V26: X | W26: X | X26: X | AA26: X | AB26: X | AD26: X | AE26: X | AJ26: X | AM26: =IF(F26="","",COUNTIF($H26:$AL26,AM$8)) -> 18 | AN26: =IF(OR(G26="",G26="Đã nghỉ"),0,COUNTIF($H26:$AL26,"N1")/2++IF(AND(LEN(H26)>2,OR(LEFT(H26,2)="N1",RIGHT(H26,2)="N1")),0.5)+IF(AND(LEN(I26)>2,OR(LEFT(I26,2)="N1",RIGHT(I26,2)="N1")),0.5)+IF(AND(LEN(J26)>2,OR(LEFT(J26,2)="N1",RIGHT(J26,2)="N1")),0.5)+IF(AND(LEN(K26)>2,OR(LEFT(K26,2)="N1",RIGHT(K26,2)="N1")),0.5)+IF(AND(LEN(L26)>2,OR(LEFT(L26,2)="N1",RIGHT(L26,2)="N1")),0.5)+IF(AND(LEN(M26)>2,OR(LEFT(M26,2)="N1",RIGHT(M26,2)="N1")),0.5)+IF(AND(LEN(N26)>2,OR(LEFT(N26,2)="N1",RIGHT(N26,2)="N1")),0.5)+IF(AND(LEN(O26)>2,OR(LEFT(O26,2)="N1",RIGHT(O26,2)="N1")),0.5)+IF(AND(LEN(P26)>2,OR(LEFT(P26,2)="N1",RIGHT(P26,2)="N1")),0.5)+IF(AND(LEN(Q26)>2,OR(LEFT(Q26,2)="N1",RIGHT(Q26,2)="N1")),0.5)+IF(AND(LEN(R26)>2,OR(LEFT(R26,2)="N1",RIGHT(R26,2)="N1")),0.5)+IF(AND(LEN(S26)>2,OR(LEFT(S26,2)="N1",RIGHT(S26,2)="N1")),0.5)+IF(AND(LEN(T26)>2,OR(LEFT(T26,2)="N1",RIGHT(T26,2)="N1")),0.5)+IF(AND(LEN(U26)>2,OR(LEFT(U26,2)="N1",RIGHT(U26,2)="N1")),0.5)+IF(AND(LEN(V26)>2,OR(LEFT(V26,2)="N1",RIGHT(V26,2)="N1")),0.5)+IF(AND(LEN(W26)>2,OR(LEFT(W26,2)="N1",RIGHT(W26,2)="N1")),0.5)+IF(AND(LEN(X26)>2,OR(LEFT(X26,2)="N1",RIGHT(X26,2)="N1")),0.5)+IF(AND(LEN(Y26)>2,OR(LEFT(Y26,2)="N1",RIGHT(Y26,2)="N1")),0.5)+IF(AND(LEN(Z26)>2,OR(LEFT(Z26,2)="N1",RIGHT(Z26,2)="N1")),0.5)+IF(AND(LEN(AA26)>2,OR(LEFT(AA26,2)="N1",RIGHT(AA26,2)="N1")),0.5)+IF(AND(LEN(AB26)>2,OR(LEFT(AB26,2)="N1",RIGHT(AB26,2)="N1")),0.5)+IF(AND(LEN(AC26)>2,OR(LEFT(AC26,2)="N1",RIGHT(AC26,2)="N1")),0.5)+IF(AND(LEN(AD26)>2,OR(LEFT(AD26,2)="N1",RIGHT(AD26,2)="N1")),0.5)+IF(AND(LEN(AE26)>2,OR(LEFT(AE26,2)="N1",RIGHT(AE26,2)="N1")),0.5)+IF(AND(LEN(AF26)>2,OR(LEFT(AF26,2)="N1",RIGHT(AF26,2)="N1")),0.5)+IF(AND(LEN(AG26)>2,OR(LEFT(AG26,2)="N1",RIGHT(AG26,2)="N1")),0.5)+IF(AND(LEN(AH26)>2,OR(LEFT(AH26,2)="N1",RIGHT(AH26,2)="N1")),0.5)+IF(AND(LEN(AI26)>2,OR(LEFT(AI26,2)="N1",RIGHT(AI26,2)="N1")),0.5)+IF(AND(LEN(AJ26)>2,OR(LEFT(AJ26,2)="N1",RIGHT(AJ26,2)="N1")),0.5)+IF(AND(LEN(AK26)>2,OR(LEFT(AK26,2)="N1",RIGHT(AK26,2)="N1")),0.5)+IF(AND(LEN(AL26)>2,OR(LEFT(AL26,2)="N1",RIGHT(AL26,2)="N1")),0.5)) -> 0 | AO26: =COUNTIF(H26:AL26,"ON")+COUNTIF(H26:AL26,"ON/2")/2 -> 0 | AP26: =IF(F26="","",COUNTIF($H26:$AL26,AP$8))+IF(F26="","",COUNTIF($H26:$AL26,$V$5)/2) -> 0 | AQ26: 0 | AR26: =IF(G26="","",AM26+AN26+AP26+AQ26) -> 18 | AS26: =IF(F26="","",COUNTIF($H26:$AL26,AS$8))++IF(F26="","",COUNTIF($H26:$AL26,"L1")/2) -> 0 | AT26: =AU26-AR26-AS26 -> 4 | AU26: 22
A27: 16 | B27: MS20 | C27: Vận hành | D27: Nhân viên bếp | F27: Nguyễn Thị Thu Hiền | G27: Thử Việc | AI27: X | AJ27: X | AM27: =IF(F27="","",COUNTIF($H27:$AL27,AM$8)) -> 2 | AN27: =IF(OR(G27="",G27="Đã nghỉ"),0,COUNTIF($H27:$AL27,"N1")/2++IF(AND(LEN(H27)>2,OR(LEFT(H27,2)="N1",RIGHT(H27,2)="N1")),0.5)+IF(AND(LEN(I27)>2,OR(LEFT(I27,2)="N1",RIGHT(I27,2)="N1")),0.5)+IF(AND(LEN(J27)>2,OR(LEFT(J27,2)="N1",RIGHT(J27,2)="N1")),0.5)+IF(AND(LEN(K27)>2,OR(LEFT(K27,2)="N1",RIGHT(K27,2)="N1")),0.5)+IF(AND(LEN(L27)>2,OR(LEFT(L27,2)="N1",RIGHT(L27,2)="N1")),0.5)+IF(AND(LEN(M27)>2,OR(LEFT(M27,2)="N1",RIGHT(M27,2)="N1")),0.5)+IF(AND(LEN(N27)>2,OR(LEFT(N27,2)="N1",RIGHT(N27,2)="N1")),0.5)+IF(AND(LEN(O27)>2,OR(LEFT(O27,2)="N1",RIGHT(O27,2)="N1")),0.5)+IF(AND(LEN(P27)>2,OR(LEFT(P27,2)="N1",RIGHT(P27,2)="N1")),0.5)+IF(AND(LEN(Q27)>2,OR(LEFT(Q27,2)="N1",RIGHT(Q27,2)="N1")),0.5)+IF(AND(LEN(R27)>2,OR(LEFT(R27,2)="N1",RIGHT(R27,2)="N1")),0.5)+IF(AND(LEN(S27)>2,OR(LEFT(S27,2)="N1",RIGHT(S27,2)="N1")),0.5)+IF(AND(LEN(T27)>2,OR(LEFT(T27,2)="N1",RIGHT(T27,2)="N1")),0.5)+IF(AND(LEN(U27)>2,OR(LEFT(U27,2)="N1",RIGHT(U27,2)="N1")),0.5)+IF(AND(LEN(V27)>2,OR(LEFT(V27,2)="N1",RIGHT(V27,2)="N1")),0.5)+IF(AND(LEN(W27)>2,OR(LEFT(W27,2)="N1",RIGHT(W27,2)="N1")),0.5)+IF(AND(LEN(X27)>2,OR(LEFT(X27,2)="N1",RIGHT(X27,2)="N1")),0.5)+IF(AND(LEN(Y27)>2,OR(LEFT(Y27,2)="N1",RIGHT(Y27,2)="N1")),0.5)+IF(AND(LEN(Z27)>2,OR(LEFT(Z27,2)="N1",RIGHT(Z27,2)="N1")),0.5)+IF(AND(LEN(AA27)>2,OR(LEFT(AA27,2)="N1",RIGHT(AA27,2)="N1")),0.5)+IF(AND(LEN(AB27)>2,OR(LEFT(AB27,2)="N1",RIGHT(AB27,2)="N1")),0.5)+IF(AND(LEN(AC27)>2,OR(LEFT(AC27,2)="N1",RIGHT(AC27,2)="N1")),0.5)+IF(AND(LEN(AD27)>2,OR(LEFT(AD27,2)="N1",RIGHT(AD27,2)="N1")),0.5)+IF(AND(LEN(AE27)>2,OR(LEFT(AE27,2)="N1",RIGHT(AE27,2)="N1")),0.5)+IF(AND(LEN(AF27)>2,OR(LEFT(AF27,2)="N1",RIGHT(AF27,2)="N1")),0.5)+IF(AND(LEN(AG27)>2,OR(LEFT(AG27,2)="N1",RIGHT(AG27,2)="N1")),0.5)+IF(AND(LEN(AH27)>2,OR(LEFT(AH27,2)="N1",RIGHT(AH27,2)="N1")),0.5)+IF(AND(LEN(AI27)>2,OR(LEFT(AI27,2)="N1",RIGHT(AI27,2)="N1")),0.5)+IF(AND(LEN(AJ27)>2,OR(LEFT(AJ27,2)="N1",RIGHT(AJ27,2)="N1")),0.5)+IF(AND(LEN(AK27)>2,OR(LEFT(AK27,2)="N1",RIGHT(AK27,2)="N1")),0.5)+IF(AND(LEN(AL27)>2,OR(LEFT(AL27,2)="N1",RIGHT(AL27,2)="N1")),0.5)) -> 0 | AO27: =COUNTIF(H27:AL27,"ON")+COUNTIF(H27:AL27,"ON/2")/2 -> 0 | AP27: =IF(F27="","",COUNTIF($H27:$AL27,AP$8))+IF(F27="","",COUNTIF($H27:$AL27,$V$5)/2) -> 0 | AQ27: 0 | AR27: =IF(G27="","",AM27+AN27+AP27+AQ27) -> 2 | AS27: =IF(F27="","",COUNTIF($H27:$AL27,AS$8))++IF(F27="","",COUNTIF($H27:$AL27,"L1")/2) -> 0 | AT27: =AU27-AR27-AS27 -> 20 | AU27: 22
A28: Tổng | AM28: =SUBTOTAL(9,AM11:AM12) -> 27 | AN28: =SUBTOTAL(9,AN11:AN23) -> 8 | AO28: =SUBTOTAL(9,AO11:AO23) -> 10 | AP28: =SUBTOTAL(9,AP11:AP23) -> 0 | AQ28: =SUBTOTAL(9,AQ11:AQ12) -> 0 | AR28: =SUBTOTAL(9,AR11:AR23) -> 208 | AS28: =SUBTOTAL(9,AS11:AS23) -> 23 | AT28: =SUBTOTAL(9,AT11:AT23) -> 28 | AU28: =SUBTOTAL(9,AU11:AU23) -> 264
B29: 1 | C29: =B29+1 -> 2 | D29: =C29+1 -> 3 | E29: =D29+1 -> 4 | F29: =E29+1 -> 5 | G29: =F29+1 -> 6 | H29: =G29+1 -> 7 | I29: =H29+1 -> 8 | J29: =I29+1 -> 9 | ... AV29: =AU29+1 -> 47
AM30: Hà Nội, ngày ..... tháng ..... năm 2026
D31: Tổng giám đốc | M31: Phòng Tài chính - Kế toán | Z31: Phòng Hành chính - Nhân sự | AM31: Người lập

Sheet 4. Bảng phép năm 2026
A1: CVG - BẢNG THEO DÕI PHÉP NĂM 2026
A2: STT | B2: Mã NV | C2: Phòng | D2: Họ & Tên | E2: Số phép đã nghỉ (phép năm 2026) | R2: Tổng phép đã nghỉ năm 2026 | S2: Số ngày phép năm 2025 | T2: Phép tồn | U2: Ghi chú
E3: Thời gian bắt đầu tính phép Đvt: tháng | F3: T1 | G3: T2 | H3: T3 | I3: T4 | J3: T5 | K3: T6 | L3: T7 | M3: T8 | N3: T9 | O3: T10 | P3: T11 | Q3: T12
B4: 1 | C4: =B4+1 -> 2 | D4: =C4+1 -> 3 | E4: =#REF!+1 -> #REF! | F4: =E4+1 -> #REF! | G4: =F4+1 -> #REF! | H4: =G4+1 -> #REF! | I4: =H4+1 -> #REF! | J4: =I4+1 -> #REF! | K4: =J4+1 -> #REF! | L4: =K4+1 -> #REF! | M4: =L4+1 -> #REF! | ... U4: =T4+1 -> #REF!
