Workbook
Name __________________________________a129: #REF!
Name __________________________________a130: #REF!
Name _________________________________a129: #REF!
Name _________________________________a130: #REF!
Name ________________________________a129: #REF!
Name ________________________________a130: #REF!
Name _______________________________a129: #REF!
Name _______________________________a130: #REF!
Name ______________________________a129: #REF!
Name ______________________________a130: #REF!
Name _____________________________a129: #REF!
Name _____________________________a130: #REF!
Name ____________________________a129: #REF!
Name ____________________________a130: #REF!
Name ___________________________a129: #REF!
Name ___________________________a130: #REF!
Name __________________________a129: #REF!
Name __________________________a130: #REF!
Name _________________________a129: #REF!
Name _________________________a130: #REF!
Name ________________________a129: #REF!
Name ________________________a130: #REF!
Name _______________________a129: #REF!
Name _______________________a130: #REF!
Name ______________________a129: #REF!
Name ______________________a130: #REF!
Name _____________________a129: #REF!
Name _____________________a130: #REF!
Name ____________________a129: #REF!
Name ____________________a130: #REF!
Name ___________________a129: #REF!
Name ___________________a130: #REF!
Name __________________a129: #REF!
Name __________________a130: #REF!
Name _________________a129: #REF!
Name _________________a130: #REF!
Name ________________a129: #REF!
Name ________________a130: #REF!
Name _______________a129: #REF!
Name _______________a130: #REF!
Name ______________a129: #REF!
Name ______________a130: #REF!
Name _____________a129: #REF!
Name _____________a130: #REF!
Name ____________a129: #REF!
Name ____________a130: #REF!
Name ___________a129: #REF!
Name ___________a130: #REF!
Name __________a129: #REF!
Name __________a130: #REF!
Name _________a129: #REF!
Name _________a130: #REF!
Name ________a129: #REF!
Name ________a130: #REF!
Name _______a129: #REF!
Name _______a130: #REF!
Name ______a129: #REF!
Name ______a130: #REF!
Name _____a129: #REF!
Name _____a130: #REF!

Sheet MỤC LỤC
A1: DANH MỤC HỒ SƠ LƯƠNG THÁNG 04.2024
A2: STT | B2: Nội dung | C2: Link
A3: 1 | B3: Đề nghị thanh toán | C3: ĐỀ NGHỊ THANH TOÁN
A4: 2 | B4: Ngân hàng nhận lương của CBNV | C4: Bảng kê nhận lương
A5: 3 | B5: Bảng chấm công | C5: 3,BẢNG CHẤM CÔNG
A6: 4 | B6: Bảng phép năm 2025 | C6: Bảng phép năm 2023
A7: 5 | B7: Thông số tính lương | C7: Thông số TL
A8: 6 | B8: Bảng tính lương | C8: Bảng lương
A9: 7 | B9: Theo dõi Người phụ thuộc | C9: #'7.Danh sách NPT'!A1
A10: 8 | B10: Phiếu lương | C10: Phiếu lương

Sheet 1.ĐNTT LẦN 1
D1: CỘNG HOÀ XÃ HỘI CHỦ NGHĨA VIỆT NAM Độc lập - Tự do - Hạnh phúc
D2: ----------------------
M3: =IF(E3="","Hà Nội, Ngày 05 Tháng 04 Năm 2026",VLOOKUP(E3,'[24]NHẬP LIỆU'!B1:M29,2,0)) -> Hà Nội, Ngày 05 Tháng 04 Năm 2026
H5: ĐỀ NGHỊ THANH TOÁN
C6: Kính gửi: | D6: - Ban lãnh đạo Công ty cổ phần MS14 - Bộ phận kế toán của công ty
C7: Họ và tên người đề nghị: Nguyễn Thị Thu Hảo
C8: Bộ phận: | D8: Vận hành
C9: Nội dung thanh toán: MS14 thanh toán lương CBNV MS14 tháng 03/2026
C11: Nội dung thanh toán | N11: Thành tiền
C12: MS14 thanh toán lương CBNV MS14 tháng 03/2026 Danh sách cụ thể đính kèm. | N12: ='2. DS TKNH L1'!G16 -> 110882900
C13: Tổng tiền thanh toán | N13: =N12 -> 110882900
C14: Bằng chữ:
C15: =" Đề nghị Ban lãnh đạo và phòng kế toán phê duyệt để thanh toán số tiền nêu trên. Chi tiết cụ thể như số liệu đã đề cập." -> Đề nghị Ban lãnh đạo và phòng kế toán phê duyệt để thanh toán số tiền nêu trên. Chi tiết cụ thể như số liệu đã đề cập.
C16: Phương thức thanh toán: | H16: Tiền mặt | L16: FALSE
H17: Chuyển khoản | L17: TRUE
C18: Thông tin chuyển khoản:
C19: - Chủ tài khoản: | F19: Theo danh sách đính kèm
C20: - Số tài khoản : | F20: Theo danh sách đính kèm
C21: - Ngân hàng: | F21: Theo danh sách đính kèm
A23: Tổng Giám đốc | F23: Phòng TCKT | N23: Phòng HCNS | V23: Người lập

Sheet 2. DS TKNH L1
C1: BẢNG KÊ DANH SÁCH THANH TOÁN LƯƠNG THÁNG 03.2026
C2: Nội dung: MS14 thanh toán lương cho nhân sự MS14 Tháng 03.2026
A3: STT | B3: Mã NV | C3: Họ và tên | D3: Số tài khoản | E3: Ngân hàng | F3: Chi nhánh | G3: Số tiền thanh toán
A4: 1 | B4: MS03 | C4: =VLOOKUP(B4,'6.Bảng lương '!B13:$C$16,2,0) -> Lê Thị Kim Liên | D4: 19031627139016 | E4: Techcombank | G4: =VLOOKUP($B4,'6.Bảng lương '!$B$11:$AV$28,47,0) -> 16000000
A5: 2 | B5: MS04 | C5: =VLOOKUP(B5,'6.Bảng lương '!B15:$C$16,2,0) -> Nguyễn Thị Thu Hảo | D5: 19035531863010 | E5: Techcombank | G5: =VLOOKUP($B5,'6.Bảng lương '!$B$11:$AV$28,47,0) -> 15212500
A6: 3 | B6: MS02 | C6: =VLOOKUP(B6,'6.Bảng lương '!B12:$C$12,2,0) -> Bùi Thanh Anh | D6: 1978555558 | E6: ACB | G6: =VLOOKUP($B6,'6.Bảng lương '!$B$11:$AV$28,47,0) -> 15000000
A7: 4 | B7: MS06 | C7: =VLOOKUP(B7,'6.Bảng lương '!B$16:$C22,2,0) -> Eugene | D7: 1045887952 | E7: Vietcombank | G7: =VLOOKUP($B7,'6.Bảng lương '!$B$11:$AV$28,47,0) -> 19102700
A8: 5 | B8: MS07 | C8: =VLOOKUP(B8,'6.Bảng lương '!B$16:$C23,2,0) -> Nguyễn Thị Ánh Hồng | D8: 1033638061 | E8: Vietcombank | G8: =VLOOKUP($B8,'6.Bảng lương '!$B$11:$AV$28,47,0) -> 8422500
A9: 6 | B9: MS08 | C9: Hoàng Thị Hương Li | D9: 19036055792017 | E9: Techcombank | G9: =VLOOKUP($B9,'6.Bảng lương '!$B$11:$AV$28,47,0) -> 2045500
A10: 7 | B10: MS09 | C10: =VLOOKUP(B10,'6.Bảng lương '!$B$12:$C$23,2,0) -> Nguyễn Thị Thu | D10: 1991555558 | E10: ACB | G10: =VLOOKUP($B10,'6.Bảng lương '!$B$11:$AV$28,47,0) -> 8000000
A11: 8 | B11: MS11 | C11: =VLOOKUP(B11,' 5. Thông số TL'!$D$12:$E$25,2,0) -> Phùng Thị Lụa | D11: 0563250894 | E11: MB | G11: =VLOOKUP($B11,'6.Bảng lương '!$B$11:$AV$28,47,0) -> 5661600
A12: 9 | B12: MS12 | C12: =VLOOKUP(B12,' 5. Thông số TL'!$D$12:$E$25,2,0) -> Đinh Thị Bích Ngọc | D12: 19032824127018 | E12: Techcombank | G12: =VLOOKUP($B12,'6.Bảng lương '!$B$11:$AV$28,47,0) -> 5848600
A13: 10 | B13: MS13 | C13: =VLOOKUP(B13,' 5. Thông số TL'!$D$12:$E$25,2,0) -> Lương Văn Châm | D13: 9904677976 | E13: Techcombank | G13: =VLOOKUP($B13,'6.Bảng lương '!$B$11:$AV$28,47,0) -> 5182300
A14: 11 | B14: MS14 | C14: =VLOOKUP(B14,' 5. Thông số TL'!$D$12:$E$25,2,0) -> Nguyễn Thị Phúc | D14: 1036236348 | E14: VCB | G14: =VLOOKUP($B14,'6.Bảng lương '!$B$11:$AV$28,47,0) -> 8187000
A15: 12 | B15: MS15 | C15: =VLOOKUP(B15,' 5. Thông số TL'!$D$12:$E$25,2,0) -> Nguyễn Thị Thuỳ Trang | D15: 0374624154 | E15: MB | G15: =VLOOKUP($B15,'6.Bảng lương '!$B$11:$AV$28,47,0) -> 2220200
A16: Tổng | G16: =SUM(G4:G15) -> 110882900
E19: Hà Nội, ngày 05 tháng 04 năm 2026
A21: TỔNG GIÁM ĐỐC | C21: PHÒNG TÀI CHÍNH - KẾ TOÁN | E21: PHÒNG HCNS | F21: NGƯỜI LẬP

Sheet 3. BẢNG CHẤM CÔNG
C1: TÊN ĐƠN VỊ: CÔNG TY CỔ PHẦN MS14 ĐỊA CHỈ: Clubhouse 3 đường Phong Lan 1, khu đô thị Vinhomes Riverside, phường Phúc Lợi, thành phố Hà Nội MST: 0111258406
I2: Tháng | K2: 3 | M2: Bảng Ký Hiệu Các Loại Ngày Công
M3: Loại | O3: Đủ Công | P3: Nửa Ngày | Q3: Online | R3: Online nửa ngày | S3: Phép | T3: Nửa phép | U3: Làm việc CN, T7 | V3: Làm việc nửa CN/T7 | X3: Ngày Lễ | Y3: Nửa ngày lễ | Z3: Không Lương | AB3: Thai sản
I4: Năm | K4: 2026
M5: Ký Hiệu | O5: X | P5: N1 | Q5: On | R5: On/2 | S5: P | T5: P1 | U5: C | V5: C/2 | X5: L | Y5: L1 | Z5: K | AB5: TS
A6: MS14 - BẢNG CHẤM CÔNG THÁNG 03/2026
H7: 8 | I7: =1+H7 -> 9 | J7: =1+I7 -> 10 | K7: =1+J7 -> 11 | L7: =1+K7 -> 12 | M7: =1+L7 -> 13 | N7: =1+M7 -> 14 | O7: =1+N7 -> 15 | P7: =1+O7 -> 16 | ... AN7: =1+AM7 -> 40 | AP7: =1+AN7 -> 41 | AQ7: =1+AP7 -> 42 | AR7: =1+AQ7 -> 43 | AS7: =1+AR7 -> 44 | AT7: =1+AS7 -> 45 | AU7: =1+AT7 -> 46 | AV7: =1+AU7 -> 47
H8: =DATE(K4,K2,1) -> 46082 | I8: =H8+1 -> 46083 | J8: =I8+1 -> 46084 | K8: =J8+1 -> 46085 | L8: =K8+1 -> 46086 | M8: =L8+1 -> 46087 | N8: =M8+1 -> 46088 | O8: =N8+1 -> 46089 | P8: =O8+1 -> 46090 | ... AL8: =AK8+1 -> 46112 | AM8: X | AN8: N1 | AO8: ON | AP8: C | AQ8: P + P1 | AR8: Tổng Công đi làm & nghỉ phép | AS8: L | AT8: K | AU8: Số công full tháng | AV8: ="Phép Tồn năm 2023 tính đến T."&K2 -> Phép Tồn năm 2023 tính đến T.3
H9: =CHOOSE(WEEKDAY(H8),"Chủ Nhật","Thứ Hai","Thứ Ba","Thứ Tư","Thứ Năm","Thứ Sáu","Thứ Bảy") -> Chủ Nhật | I9: =CHOOSE(WEEKDAY(I8),"Chủ Nhật","Thứ Hai","Thứ Ba","Thứ Tư","Thứ Năm","Thứ Sáu","Thứ Bảy") -> Thứ Hai | J9: =CHOOSE(WEEKDAY(J8),"Chủ Nhật","Thứ Hai","Thứ Ba","Thứ Tư","Thứ Năm","Thứ Sáu","Thứ Bảy") -> Thứ Ba | K9: =CHOOSE(WEEKDAY(K8),"Chủ Nhật","Thứ Hai","Thứ Ba","Thứ Tư","Thứ Năm","Thứ Sáu","Thứ Bảy") -> Thứ Tư | L9: =CHOOSE(WEEKDAY(L8),"Chủ Nhật","Thứ Hai","Thứ Ba","Thứ Tư","Thứ Năm","Thứ Sáu","Thứ Bảy") -> Thứ Năm | M9: =CHOOSE(WEEKDAY(M8),"Chủ Nhật","Thứ Hai","Thứ Ba","Thứ Tư","Thứ Năm","Thứ Sáu","Thứ Bảy") -> Thứ Sáu | N9: =CHOOSE(WEEKDAY(N8),"Chủ Nhật","Thứ Hai","Thứ Ba","Thứ Tư","Thứ Năm","Thứ Sáu","Thứ Bảy") -> Thứ Bảy | O9: =CHOOSE(WEEKDAY(O8),"Chủ Nhật","Thứ Hai","Thứ Ba","Thứ Tư","Thứ Năm","Thứ Sáu","Thứ Bảy") -> Chủ Nhật | ... AL9: =CHOOSE(WEEKDAY(AL8),"Chủ Nhật","Thứ Hai","Thứ Ba","Thứ Tư","Thứ Năm","Thứ Sáu","Thứ Bảy") -> Thứ Ba | AM9: Đủ công | AN9: Nửa Công | AO9: Làm online | AP9: Làm việc CN, T7 | AQ9: Phép | AS9: Lễ Tết | AT9: Không Lương
A10: STT | B10: Mã NV | C10: Phòng ban | D10: Chức danh | E10: Tầng nhân sự | F10: Họ & Tên | G10: Tình Trạng | AR10: =SUM(AR12:AR28) -> 438 | AT10: =SUM(AT12:AT28) -> 156
A11: =SUBTOTAL(3,$F$11:F11) -> 1 | B11: MS04 | C11: Vận hành | D11: Trưởng phòng vận hành | F11: Nguyễn Thị Thu Hảo | G11: Chính Thức | I11: X | J11: X | K11: X | L11: X | M11: X | P11: X | Q11: X | R11: X | S11: X | T11: X | W11: X | X11: X | Y11: X | Z11: X | AA11: X | AD11: P | AE11: X | AF11: X | AG11: X | AH11: X | AK11: X | AL11: X | AM11: =IF(F11="","",COUNTIF($H11:$AL11,AM$8)) -> 21 | AN11: =IF(OR(G11="",G11="Đã nghỉ"),0,COUNTIF($H11:$AL11,"N1")/2++IF(AND(LEN(H11)>2,OR(LEFT(H11,2)="N1",RIGHT(H11,2)="N1")),0.5)+IF(AND(LEN(I11)>2,OR(LEFT(I11,2)="N1",RIGHT(I11,2)="N1")),0.5)+IF(AND(LEN(J11)>2,OR(LEFT(J11,2)="N1",RIGHT(J11,2)="N1")),0.5)+IF(AND(LEN(K11)>2,OR(LEFT(K11,2)="N1",RIGHT(K11,2)="N1")),0.5)+IF(AND(LEN(L11)>2,OR(LEFT(L11,2)="N1",RIGHT(L11,2)="N1")),0.5)+IF(AND(LEN(M11)>2,OR(LEFT(M11,2)="N1",RIGHT(M11,2)="N1")),0.5)+IF(AND(LEN(N11)>2,OR(LEFT(N11,2)="N1",RIGHT(N11,2)="N1")),0.5)+IF(AND(LEN(O11)>2,OR(LEFT(O11,2)="N1",RIGHT(O11,2)="N1")),0.5)+IF(AND(LEN(P11)>2,OR(LEFT(P11,2)="N1",RIGHT(P11,2)="N1")),0.5)+IF(AND(LEN(Q11)>2,OR(LEFT(Q11,2)="N1",RIGHT(Q11,2)="N1")),0.5)+IF(AND(LEN(R11)>2,OR(LEFT(R11,2)="N1",RIGHT(R11,2)="N1")),0.5)+IF(AND(LEN(S11)>2,OR(LEFT(S11,2)="N1",RIGHT(S11,2)="N1")),0.5)+IF(AND(LEN(T11)>2,OR(LEFT(T11,2)="N1",RIGHT(T11,2)="N1")),0.5)+IF(AND(LEN(U11)>2,OR(LEFT(U11,2)="N1",RIGHT(U11,2)="N1")),0.5)+IF(AND(LEN(V11)>2,OR(LEFT(V11,2)="N1",RIGHT(V11,2)="N1")),0.5)+IF(AND(LEN(W11)>2,OR(LEFT(W11,2)="N1",RIGHT(W11,2)="N1")),0.5)+IF(AND(LEN(X11)>2,OR(LEFT(X11,2)="N1",RIGHT(X11,2)="N1")),0.5)+IF(AND(LEN(Y11)>2,OR(LEFT(Y11,2)="N1",RIGHT(Y11,2)="N1")),0.5)+IF(AND(LEN(Z11)>2,OR(LEFT(Z11,2)="N1",RIGHT(Z11,2)="N1")),0.5)+IF(AND(LEN(AA11)>2,OR(LEFT(AA11,2)="N1",RIGHT(AA11,2)="N1")),0.5)+IF(AND(LEN(AB11)>2,OR(LEFT(AB11,2)="N1",RIGHT(AB11,2)="N1")),0.5)+IF(AND(LEN(AC11)>2,OR(LEFT(AC11,2)="N1",RIGHT(AC11,2)="N1")),0.5)+IF(AND(LEN(AD11)>2,OR(LEFT(AD11,2)="N1",RIGHT(AD11,2)="N1")),0.5)+IF(AND(LEN(AE11)>2,OR(LEFT(AE11,2)="N1",RIGHT(AE11,2)="N1")),0.5)+IF(AND(LEN(AF11)>2,OR(LEFT(AF11,2)="N1",RIGHT(AF11,2)="N1")),0.5)+IF(AND(LEN(AG11)>2,OR(LEFT(AG11,2)="N1",RIGHT(AG11,2)="N1")),0.5)+IF(AND(LEN(AH11)>2,OR(LEFT(AH11,2)="N1",RIGHT(AH11,2)="N1")),0.5)+IF(AND(LEN(AI11)>2,OR(LEFT(AI11,2)="N1",RIGHT(AI11,2)="N1")),0.5)+IF(AND(LEN(AJ11)>2,OR(LEFT(AJ11,2)="N1",RIGHT(AJ11,2)="N1")),0.5)+IF(AND(LEN(AK11)>2,OR(LEFT(AK11,2)="N1",RIGHT(AK11,2)="N1")),0.5)+IF(AND(LEN(AL11)>2,OR(LEFT(AL11,2)="N1",RIGHT(AL11,2)="N1")),0.5)) -> 0 | AO11: =COUNTIF(H11:AL11,"ON")+COUNTIF(H11:AL11,"ON/2")/2 -> 0 | AP11: =IF(F11="","",COUNTIF($H11:$AL11,AP$8))+IF(F11="","",COUNTIF($H11:$AL11,$V$5)/2) -> 0 | AQ11: =COUNTIF($H11:$AL11,"P")+COUNTIF($H11:$AL11,"P1")/2+IF(AND(LEN(I11)>2,OR(LEFT(I11,2)="P1",RIGHT(I11,2)="P1")),0.5)+IF(AND(LEN(J11)>2,OR(LEFT(J11,2)="P1",RIGHT(J11,2)="P1")),0.5)+IF(AND(LEN(K11)>2,OR(LEFT(K11,2)="P1",RIGHT(K11,2)="P1")),0.5)+IF(AND(LEN(L11)>2,OR(LEFT(L11,2)="P1",RIGHT(L11,2)="P1")),0.5)+IF(AND(LEN(M11)>2,OR(LEFT(M11,2)="P1",RIGHT(M11,2)="P1")),0.5)+IF(AND(LEN(N11)>2,OR(LEFT(N11,2)="P1",RIGHT(N11,2)="P1")),0.5)+IF(AND(LEN(O11)>2,OR(LEFT(O11,2)="P1",RIGHT(O11,2)="P1")),0.5)+IF(AND(LEN(P11)>2,OR(LEFT(P11,2)="P1",RIGHT(P11,2)="P1")),0.5)+IF(AND(LEN(Q11)>2,OR(LEFT(Q11,2)="P1",RIGHT(Q11,2)="P1")),0.5)+IF(AND(LEN(R11)>2,OR(LEFT(R11,2)="P1",RIGHT(R11,2)="P1")),0.5)+IF(AND(LEN(S11)>2,OR(LEFT(S11,2)="P1",RIGHT(S11,2)="P1")),0.5)+IF(AND(LEN(T11)>2,OR(LEFT(T11,2)="P1",RIGHT(T11,2)="P1")),0.5)+IF(AND(LEN(U11)>2,OR(LEFT(U11,2)="P1",RIGHT(U11,2)="P1")),0.5)+IF(AND(LEN(V11)>2,OR(LEFT(V11,2)="P1",RIGHT(V11,2)="P1")),0.5)+IF(AND(LEN(W11)>2,OR(LEFT(W11,2)="P1",RIGHT(W11,2)="P1")),0.5)+IF(AND(LEN(X11)>2,OR(LEFT(X11,2)="P1",RIGHT(X11,2)="P1")),0.5)+IF(AND(LEN(Y11)>2,OR(LEFT(Y11,2)="P1",RIGHT(Y11,2)="P1")),0.5)+IF(AND(LEN(Z11)>2,OR(LEFT(Z11,2)="P1",RIGHT(Z11,2)="P1")),0.5)+IF(AND(LEN(AA11)>2,OR(LEFT(AA11,2)="P1",RIGHT(AA11,2)="P1")),0.5)+IF(AND(LEN(AB11)>2,OR(LEFT(AB11,2)="P1",RIGHT(AB11,2)="P1")),0.5)+IF(AND(LEN(AC11)>2,OR(LEFT(AC11,2)="P1",RIGHT(AC11,2)="P1")),0.5)+IF(AND(LEN(AD11)>2,OR(LEFT(AD11,2)="P1",RIGHT(AD11,2)="P1")),0.5)+IF(AND(LEN(AE11)>2,OR(LEFT(AE352,2)="P1",RIGHT(AE11,2)="P1")),0.5)+IF(AND(LEN(AF11)>2,OR(LEFT(AF11,2)="P1",RIGHT(AF11,2)="P1")),0.5)+IF(AND(LEN(AG11)>2,OR(LEFT(AG11,2)="P1",RIGHT(AG11,2)="P1")),0.5)+IF(AND(LEN(AH11)>2,OR(LEFT(AH11,2)="P1",RIGHT(AH11,2)="P1")),0.5)+IF(AND(LEN(AI11)>2,OR(LEFT(AI11,2)="P1",RIGHT(AI11,2)="P1")),0.5)+IF(AND(LEN(AJ11)>2,OR(LEFT(AJ11,2)="P1",RIGHT(AJ11,2)="P1")),0.5)+IF(AND(LEN(AK11)>2,OR(LEFT(AK11,2)="P1",RIGHT(AK11,2)="P1")),0.5)+IF(AND(LEN(AL11)>2,OR(LEFT(AL11,2)="P1",RIGHT(AL11,2)="P1")),0.5) -> 1 | AR11: =IF(G11="","",AM11+AN11+AP11+AQ11) -> 22 | AS11: =IF(F11="","",COUNTIF($H11:$AL11,AS$8))++IF(F11="","",COUNTIF($H11:$AL11,"L1")/2) -> 0 | AT11: =AU11-AR11-AS11 -> 0 | AU11: 22
A12: =SUBTOTAL(3,$F$11:F12) -> 2 | B12: MS03 | C12: BGH | D12: Hiệu phó cơ sở | F12: Lê Thị Kim Liên | G12: Chính Thức | I12: X | J12: X | K12: X | L12: X | M12: X | P12: X | Q12: X | R12: X | S12: X | T12: X | W12: X | X12: X | Y12: X | Z12: X | AA12: X | AD12: X | AE12: X | AF12: X | AG12: X | AH12: X | AK12: X | AL12: X | AM12: =IF(F12="","",COUNTIF($H12:$AL12,AM$8)) -> 22 | AN12: =IF(OR(G12="",G12="Đã nghỉ"),0,COUNTIF($H12:$AL12,"N1")/2++IF(AND(LEN(H12)>2,OR(LEFT(H12,2)="N1",RIGHT(H12,2)="N1")),0.5)+IF(AND(LEN(I12)>2,OR(LEFT(I12,2)="N1",RIGHT(I12,2)="N1")),0.5)+IF(AND(LEN(J12)>2,OR(LEFT(J12,2)="N1",RIGHT(J12,2)="N1")),0.5)+IF(AND(LEN(K12)>2,OR(LEFT(K12,2)="N1",RIGHT(K12,2)="N1")),0.5)+IF(AND(LEN(L12)>2,OR(LEFT(L12,2)="N1",RIGHT(L12,2)="N1")),0.5)+IF(AND(LEN(M12)>2,OR(LEFT(M12,2)="N1",RIGHT(M12,2)="N1")),0.5)+IF(AND(LEN(N12)>2,OR(LEFT(N12,2)="N1",RIGHT(N12,2)="N1")),0.5)+IF(AND(LEN(O12)>2,OR(LEFT(O12,2)="N1",RIGHT(O12,2)="N1")),0.5)+IF(AND(LEN(P12)>2,OR(LEFT(P12,2)="N1",RIGHT(P12,2)="N1")),0.5)+IF(AND(LEN(Q12)>2,OR(LEFT(Q12,2)="N1",RIGHT(Q12,2)="N1")),0.5)+IF(AND(LEN(R12)>2,OR(LEFT(R12,2)="N1",RIGHT(R12,2)="N1")),0.5)+IF(AND(LEN(S12)>2,OR(LEFT(S12,2)="N1",RIGHT(S12,2)="N1")),0.5)+IF(AND(LEN(T12)>2,OR(LEFT(T12,2)="N1",RIGHT(T12,2)="N1")),0.5)+IF(AND(LEN(U12)>2,OR(LEFT(U12,2)="N1",RIGHT(U12,2)="N1")),0.5)+IF(AND(LEN(V12)>2,OR(LEFT(V12,2)="N1",RIGHT(V12,2)="N1")),0.5)+IF(AND(LEN(W12)>2,OR(LEFT(W12,2)="N1",RIGHT(W12,2)="N1")),0.5)+IF(AND(LEN(X12)>2,OR(LEFT(X12,2)="N1",RIGHT(X12,2)="N1")),0.5)+IF(AND(LEN(Y12)>2,OR(LEFT(Y12,2)="N1",RIGHT(Y12,2)="N1")),0.5)+IF(AND(LEN(Z12)>2,OR(LEFT(Z12,2)="N1",RIGHT(Z12,2)="N1")),0.5)+IF(AND(LEN(AA12)>2,OR(LEFT(AA12,2)="N1",RIGHT(AA12,2)="N1")),0.5)+IF(AND(LEN(AB12)>2,OR(LEFT(AB12,2)="N1",RIGHT(AB12,2)="N1")),0.5)+IF(AND(LEN(AC12)>2,OR(LEFT(AC12,2)="N1",RIGHT(AC12,2)="N1")),0.5)+IF(AND(LEN(AD12)>2,OR(LEFT(AD12,2)="N1",RIGHT(AD12,2)="N1")),0.5)+IF(AND(LEN(AE12)>2,OR(LEFT(AE12,2)="N1",RIGHT(AE12,2)="N1")),0.5)+IF(AND(LEN(AF12)>2,OR(LEFT(AF12,2)="N1",RIGHT(AF12,2)="N1")),0.5)+IF(AND(LEN(AG12)>2,OR(LEFT(AG12,2)="N1",RIGHT(AG12,2)="N1")),0.5)+IF(AND(LEN(AH12)>2,OR(LEFT(AH12,2)="N1",RIGHT(AH12,2)="N1")),0.5)+IF(AND(LEN(AI12)>2,OR(LEFT(AI12,2)="N1",RIGHT(AI12,2)="N1")),0.5)+IF(AND(LEN(AJ12)>2,OR(LEFT(AJ12,2)="N1",RIGHT(AJ12,2)="N1")),0.5)+IF(AND(LEN(AK12)>2,OR(LEFT(AK12,2)="N1",RIGHT(AK12,2)="N1")),0.5)+IF(AND(LEN(AL12)>2,OR(LEFT(AL12,2)="N1",RIGHT(AL12,2)="N1")),0.5)) -> 0 | AO12: =COUNTIF(H12:AL12,"ON")+COUNTIF(H12:AL12,"ON/2")/2 -> 0 | AP12: =IF(F12="","",COUNTIF($H12:$AL12,AP$8))+IF(F12="","",COUNTIF($H12:$AL12,$V$5)/2) -> 0 | AQ12: 0 | AR12: =IF(G12="","",AM12+AN12+AP12+AQ12) -> 22 | AS12: =IF(F12="","",COUNTIF($H12:$AL12,AS$8))++IF(F12="","",COUNTIF($H12:$AL12,"L1")/2) -> 0 | AT12: =AU12-AR12-AS12 -> 0 | AU12: 22 | AV12: =VLOOKUP(B12,'4. Bảng phép năm 2026'!B7:T7,24,0) -> #REF!
A13: =SUBTOTAL(3,$F$11:F13) -> 3 | B13: MS07 | C13: Giáo viên | D13: Giáo viên mầm non | F13: Nguyễn Thị Ánh Hồng | G13: Chính Thức | I13: X | J13: X | K13: X | L13: X | M13: X | P13: X | Q13: X | R13: X | S13: X | T13: X | W13: X | X13: X | Y13: X | Z13: X | AA13: X | AD13: X | AE13: X | AF13: X | AG13: X | AH13: X | AK13: X | AL13: X | AM13: =IF(F13="","",COUNTIF($H13:$AL13,AM$8)) -> 22 | AN13: =IF(OR(G13="",G13="Đã nghỉ"),0,COUNTIF($H13:$AL13,"N1")/2++IF(AND(LEN(H13)>2,OR(LEFT(H13,2)="N1",RIGHT(H13,2)="N1")),0.5)+IF(AND(LEN(I13)>2,OR(LEFT(I13,2)="N1",RIGHT(I13,2)="N1")),0.5)+IF(AND(LEN(J13)>2,OR(LEFT(J13,2)="N1",RIGHT(J13,2)="N1")),0.5)+IF(AND(LEN(K13)>2,OR(LEFT(K13,2)="N1",RIGHT(K13,2)="N1")),0.5)+IF(AND(LEN(L13)>2,OR(LEFT(L13,2)="N1",RIGHT(L13,2)="N1")),0.5)+IF(AND(LEN(M13)>2,OR(LEFT(M13,2)="N1",RIGHT(M13,2)="N1")),0.5)+IF(AND(LEN(N13)>2,OR(LEFT(N13,2)="N1",RIGHT(N13,2)="N1")),0.5)+IF(AND(LEN(O13)>2,OR(LEFT(O13,2)="N1",RIGHT(O13,2)="N1")),0.5)+IF(AND(LEN(P13)>2,OR(LEFT(P13,2)="N1",RIGHT(P13,2)="N1")),0.5)+IF(AND(LEN(Q13)>2,OR(LEFT(Q13,2)="N1",RIGHT(Q13,2)="N1")),0.5)+IF(AND(LEN(R13)>2,OR(LEFT(R13,2)="N1",RIGHT(R13,2)="N1")),0.5)+IF(AND(LEN(S13)>2,OR(LEFT(S13,2)="N1",RIGHT(S13,2)="N1")),0.5)+IF(AND(LEN(T13)>2,OR(LEFT(T13,2)="N1",RIGHT(T13,2)="N1")),0.5)+IF(AND(LEN(U13)>2,OR(LEFT(U13,2)="N1",RIGHT(U13,2)="N1")),0.5)+IF(AND(LEN(V13)>2,OR(LEFT(V13,2)="N1",RIGHT(V13,2)="N1")),0.5)+IF(AND(LEN(W13)>2,OR(LEFT(W13,2)="N1",RIGHT(W13,2)="N1")),0.5)+IF(AND(LEN(X13)>2,OR(LEFT(X13,2)="N1",RIGHT(X13,2)="N1")),0.5)+IF(AND(LEN(Y13)>2,OR(LEFT(Y13,2)="N1",RIGHT(Y13,2)="N1")),0.5)+IF(AND(LEN(Z13)>2,OR(LEFT(Z13,2)="N1",RIGHT(Z13,2)="N1")),0.5)+IF(AND(LEN(AA13)>2,OR(LEFT(AA13,2)="N1",RIGHT(AA13,2)="N1")),0.5)+IF(AND(LEN(AB13)>2,OR(LEFT(AB13,2)="N1",RIGHT(AB13,2)="N1")),0.5)+IF(AND(LEN(AC13)>2,OR(LEFT(AC13,2)="N1",RIGHT(AC13,2)="N1")),0.5)+IF(AND(LEN(AD13)>2,OR(LEFT(AD13,2)="N1",RIGHT(AD13,2)="N1")),0.5)+IF(AND(LEN(AE13)>2,OR(LEFT(AE13,2)="N1",RIGHT(AE13,2)="N1")),0.5)+IF(AND(LEN(AF13)>2,OR(LEFT(AF13,2)="N1",RIGHT(AF13,2)="N1")),0.5)+IF(AND(LEN(AG13)>2,OR(LEFT(AG13,2)="N1",RIGHT(AG13,2)="N1")),0.5)+IF(AND(LEN(AH13)>2,OR(LEFT(AH13,2)="N1",RIGHT(AH13,2)="N1")),0.5)+IF(AND(LEN(AI13)>2,OR(LEFT(AI13,2)="N1",RIGHT(AI13,2)="N1")),0.5)+IF(AND(LEN(AJ13)>2,OR(LEFT(AJ13,2)="N1",RIGHT(AJ13,2)="N1")),0.5)+IF(AND(LEN(AK13)>2,OR(LEFT(AK13,2)="N1",RIGHT(AK13,2)="N1")),0.5)+IF(AND(LEN(AL13)>2,OR(LEFT(AL13,2)="N1",RIGHT(AL13,2)="N1")),0.5)) -> 0 | AO13: =COUNTIF(H13:AL13,"ON")+COUNTIF(H13:AL13,"ON/2")/2 -> 0 | AP13: =IF(F13="","",COUNTIF($H13:$AL13,AP$8))+IF(F13="","",COUNTIF($H13:$AL13,$V$5)/2) -> 0 | AQ13: 0 | AR13: =IF(G13="","",AM13+AN13+AP13+AQ13) -> 22 | AS13: =IF(F13="","",COUNTIF($H13:$AL13,AS$8))++IF(F13="","",COUNTIF($H13:$AL13,"L1")/2) -> 0 | AT13: =AU13-AR13-AS13 -> 0 | AU13: 22
A14: =SUBTOTAL(3,$F$11:F14) -> 4 | B14: MS06 | C14: Giáo viên | D14: Giáo viên nước ngoài | F14: Eugene | G14: Chính Thức | I14: P1 | J14: P1 | K14: N1 | L14: N1 | M14: N1 | P14: N1 | Q14: N1 | R14: N1 | S14: K | T14: K | W14: N1 | X14: N1 | Y14: N1 | Z14: N1 | AA14: N1 | AD14: N1 | AE14: N1 | AF14: N1 | AG14: N1 | AH14: K | AK14: N1 | AL14: N1 | AM14: =IF(F14="","",COUNTIF($H14:$AL14,AM$8)) -> 0 | AN14: =IF(OR(G14="",G14="Đã nghỉ"),0,COUNTIF($H14:$AL14,"N1")/2++IF(AND(LEN(H14)>2,OR(LEFT(H14,2)="N1",RIGHT(H14,2)="N1")),0.5)+IF(AND(LEN(I14)>2,OR(LEFT(I14,2)="N1",RIGHT(I14,2)="N1")),0.5)+IF(AND(LEN(J14)>2,OR(LEFT(J14,2)="N1",RIGHT(J14,2)="N1")),0.5)+IF(AND(LEN(K14)>2,OR(LEFT(K14,2)="N1",RIGHT(K14,2)="N1")),0.5)+IF(AND(LEN(L14)>2,OR(LEFT(L14,2)="N1",RIGHT(L14,2)="N1")),0.5)+IF(AND(LEN(M14)>2,OR(LEFT(M14,2)="N1",RIGHT(M14,2)="N1")),0.5)+IF(AND(LEN(N14)>2,OR(LEFT(N14,2)="N1",RIGHT(N14,2)="N1")),0.5)+IF(AND(LEN(O14)>2,OR(LEFT(O14,2)="N1",RIGHT(O14,2)="N1")),0.5)+IF(AND(LEN(P14)>2,OR(LEFT(P14,2)="N1",RIGHT(P14,2)="N1")),0.5)+IF(AND(LEN(Q14)>2,OR(LEFT(Q14,2)="N1",RIGHT(Q14,2)="N1")),0.5)+IF(AND(LEN(R14)>2,OR(LEFT(R14,2)="N1",RIGHT(R14,2)="N1")),0.5)+IF(AND(LEN(S14)>2,OR(LEFT(S14,2)="N1",RIGHT(S14,2)="N1")),0.5)+IF(AND(LEN(T14)>2,OR(LEFT(T14,2)="N1",RIGHT(T14,2)="N1")),0.5)+IF(AND(LEN(U14)>2,OR(LEFT(U14,2)="N1",RIGHT(U14,2)="N1")),0.5)+IF(AND(LEN(V14)>2,OR(LEFT(V14,2)="N1",RIGHT(V14,2)="N1")),0.5)+IF(AND(LEN(W14)>2,OR(LEFT(W14,2)="N1",RIGHT(W14,2)="N1")),0.5)+IF(AND(LEN(X14)>2,OR(LEFT(X14,2)="N1",RIGHT(X14,2)="N1")),0.5)+IF(AND(LEN(Y14)>2,OR(LEFT(Y14,2)="N1",RIGHT(Y14,2)="N1")),0.5)+IF(AND(LEN(Z14)>2,OR(LEFT(Z14,2)="N1",RIGHT(Z14,2)="N1")),0.5)+IF(AND(LEN(AA14)>2,OR(LEFT(AA14,2)="N1",RIGHT(AA14,2)="N1")),0.5)+IF(AND(LEN(AB14)>2,OR(LEFT(AB14,2)="N1",RIGHT(AB14,2)="N1")),0.5)+IF(AND(LEN(AC14)>2,OR(LEFT(AC14,2)="N1",RIGHT(AC14,2)="N1")),0.5)+IF(AND(LEN(AD14)>2,OR(LEFT(AD14,2)="N1",RIGHT(AD14,2)="N1")),0.5)+IF(AND(LEN(AE14)>2,OR(LEFT(AE14,2)="N1",RIGHT(AE14,2)="N1")),0.5)+IF(AND(LEN(AF14)>2,OR(LEFT(AF14,2)="N1",RIGHT(AF14,2)="N1")),0.5)+IF(AND(LEN(AG14)>2,OR(LEFT(AG14,2)="N1",RIGHT(AG14,2)="N1")),0.5)+IF(AND(LEN(AH14)>2,OR(LEFT(AH14,2)="N1",RIGHT(AH14,2)="N1")),0.5)+IF(AND(LEN(AI14)>2,OR(LEFT(AI14,2)="N1",RIGHT(AI14,2)="N1")),0.5)+IF(AND(LEN(AJ14)>2,OR(LEFT(AJ14,2)="N1",RIGHT(AJ14,2)="N1")),0.5)+IF(AND(LEN(AK14)>2,OR(LEFT(AK14,2)="N1",RIGHT(AK14,2)="N1")),0.5)+IF(AND(LEN(AL14)>2,OR(LEFT(AL14,2)="N1",RIGHT(AL14,2)="N1")),0.5)) -> 8.5 | AO14: =COUNTIF(H14:AL14,"ON")+COUNTIF(H14:AL14,"ON/2")/2 -> 0 | AP14: =IF(F14="","",COUNTIF($H14:$AL14,AP$8))+IF(F14="","",COUNTIF($H14:$AL14,$V$5)/2) -> 0 | AQ14: 0 | AR14: =IF(G14="","",AM14+AN14+AP14+AQ14) -> 8.5 | AS14: =IF(F14="","",COUNTIF($H14:$AL14,AS$8))++IF(F14="","",COUNTIF($H14:$AL14,"L1")/2) -> 0 | AT14: =AU14-AR14-AS14 -> 13.5 | AU14: 22
A15: =SUBTOTAL(3,$F$11:F15) -> 5 | B15: MS08 | C15: Giáo viên | D15: Giáo viên mầm non | F15: Nguyễn Hương Li | G15: Chính Thức | I15: K | J15: K | K15: K | L15: K | M15: K | P15: X | Q15: X | R15: X | S15: X | T15: X | W15: X | X15: X | Y15: X | Z15: N1 | AA15: N1 | AD15: K | AE15: K | AF15: K | AG15: K | AH15: K | AK15: K | AL15: K | AM15: =IF(F15="","",COUNTIF($H15:$AL15,AM$8)) -> 8 | AN15: =IF(OR(G15="",G15="Đã nghỉ"),0,COUNTIF($H15:$AL15,"N1")/2++IF(AND(LEN(H15)>2,OR(LEFT(H15,2)="N1",RIGHT(H15,2)="N1")),0.5)+IF(AND(LEN(I15)>2,OR(LEFT(I15,2)="N1",RIGHT(I15,2)="N1")),0.5)+IF(AND(LEN(J15)>2,OR(LEFT(J15,2)="N1",RIGHT(J15,2)="N1")),0.5)+IF(AND(LEN(K15)>2,OR(LEFT(K15,2)="N1",RIGHT(K15,2)="N1")),0.5)+IF(AND(LEN(L15)>2,OR(LEFT(L15,2)="N1",RIGHT(L15,2)="N1")),0.5)+IF(AND(LEN(M15)>2,OR(LEFT(M15,2)="N1",RIGHT(M15,2)="N1")),0.5)+IF(AND(LEN(N15)>2,OR(LEFT(N15,2)="N1",RIGHT(N15,2)="N1")),0.5)+IF(AND(LEN(O15)>2,OR(LEFT(O15,2)="N1",RIGHT(O15,2)="N1")),0.5)+IF(AND(LEN(P15)>2,OR(LEFT(P15,2)="N1",RIGHT(P15,2)="N1")),0.5)+IF(AND(LEN(Q15)>2,OR(LEFT(Q15,2)="N1",RIGHT(Q15,2)="N1")),0.5)+IF(AND(LEN(R15)>2,OR(LEFT(R15,2)="N1",RIGHT(R15,2)="N1")),0.5)+IF(AND(LEN(S15)>2,OR(LEFT(S15,2)="N1",RIGHT(S15,2)="N1")),0.5)+IF(AND(LEN(T15)>2,OR(LEFT(T15,2)="N1",RIGHT(T15,2)="N1")),0.5)+IF(AND(LEN(U15)>2,OR(LEFT(U15,2)="N1",RIGHT(U15,2)="N1")),0.5)+IF(AND(LEN(V15)>2,OR(LEFT(V15,2)="N1",RIGHT(V15,2)="N1")),0.5)+IF(AND(LEN(W15)>2,OR(LEFT(W15,2)="N1",RIGHT(W15,2)="N1")),0.5)+IF(AND(LEN(X15)>2,OR(LEFT(X15,2)="N1",RIGHT(X15,2)="N1")),0.5)+IF(AND(LEN(Y15)>2,OR(LEFT(Y15,2)="N1",RIGHT(Y15,2)="N1")),0.5)+IF(AND(LEN(Z15)>2,OR(LEFT(Z15,2)="N1",RIGHT(Z15,2)="N1")),0.5)+IF(AND(LEN(AA15)>2,OR(LEFT(AA15,2)="N1",RIGHT(AA15,2)="N1")),0.5)+IF(AND(LEN(AB15)>2,OR(LEFT(AB15,2)="N1",RIGHT(AB15,2)="N1")),0.5)+IF(AND(LEN(AC15)>2,OR(LEFT(AC15,2)="N1",RIGHT(AC15,2)="N1")),0.5)+IF(AND(LEN(AD15)>2,OR(LEFT(AD15,2)="N1",RIGHT(AD15,2)="N1")),0.5)+IF(AND(LEN(AE15)>2,OR(LEFT(AE15,2)="N1",RIGHT(AE15,2)="N1")),0.5)+IF(AND(LEN(AF15)>2,OR(LEFT(AF15,2)="N1",RIGHT(AF15,2)="N1")),0.5)+IF(AND(LEN(AG15)>2,OR(LEFT(AG15,2)="N1",RIGHT(AG15,2)="N1")),0.5)+IF(AND(LEN(AH15)>2,OR(LEFT(AH15,2)="N1",RIGHT(AH15,2)="N1")),0.5)+IF(AND(LEN(AI15)>2,OR(LEFT(AI15,2)="N1",RIGHT(AI15,2)="N1")),0.5)+IF(AND(LEN(AJ15)>2,OR(LEFT(AJ15,2)="N1",RIGHT(AJ15,2)="N1")),0.5)+IF(AND(LEN(AK15)>2,OR(LEFT(AK15,2)="N1",RIGHT(AK15,2)="N1")),0.5)+IF(AND(LEN(AL15)>2,OR(LEFT(AL15,2)="N1",RIGHT(AL15,2)="N1")),0.5)) -> 1 | AO15: =COUNTIF(H15:AL15,"ON")+COUNTIF(H15:AL15,"ON/2")/2 -> 0 | AP15: =IF(F15="","",COUNTIF($H15:$AL15,AP$8))+IF(F15="","",COUNTIF($H15:$AL15,$V$5)/2) -> 0 | AQ15: 0 | AR15: =IF(G15="","",AM15+AN15+AP15+AQ15) -> 9 | AS15: =IF(F15="","",COUNTIF($H15:$AL15,AS$8))++IF(F15="","",COUNTIF($H15:$AL15,"L1")/2) -> 0 | AT15: =AU15-AR15-AS15 -> 13 | AU15: 22
A16: =SUBTOTAL(3,$F$11:F16) -> 6 | B16: MS09 | C16: BGH | D16: Quản lý chương trình TA | F16: Nguyễn Thị Thu | G16: Chính Thức | I16: X | J16: X | K16: X | L16: X | M16: X | P16: X | Q16: X | R16: X | S16: X | T16: X | W16: X | X16: X | Y16: X | Z16: X | AA16: X | AD16: X | AE16: X | AF16: X | AG16: X | AH16: X | AK16: X | AL16: X | AM16: =IF(F16="","",COUNTIF($H16:$AL16,AM$8)) -> 22 | AN16: =IF(OR(G16="",G16="Đã nghỉ"),0,COUNTIF($H16:$AL16,"N1")/2++IF(AND(LEN(H16)>2,OR(LEFT(H16,2)="N1",RIGHT(H16,2)="N1")),0.5)+IF(AND(LEN(I16)>2,OR(LEFT(I16,2)="N1",RIGHT(I16,2)="N1")),0.5)+IF(AND(LEN(J16)>2,OR(LEFT(J16,2)="N1",RIGHT(J16,2)="N1")),0.5)+IF(AND(LEN(K16)>2,OR(LEFT(K16,2)="N1",RIGHT(K16,2)="N1")),0.5)+IF(AND(LEN(L16)>2,OR(LEFT(L16,2)="N1",RIGHT(L16,2)="N1")),0.5)+IF(AND(LEN(M16)>2,OR(LEFT(M16,2)="N1",RIGHT(M16,2)="N1")),0.5)+IF(AND(LEN(N16)>2,OR(LEFT(N16,2)="N1",RIGHT(N16,2)="N1")),0.5)+IF(AND(LEN(O16)>2,OR(LEFT(O16,2)="N1",RIGHT(O16,2)="N1")),0.5)+IF(AND(LEN(P16)>2,OR(LEFT(P16,2)="N1",RIGHT(P16,2)="N1")),0.5)+IF(AND(LEN(Q16)>2,OR(LEFT(Q16,2)="N1",RIGHT(Q16,2)="N1")),0.5)+IF(AND(LEN(R16)>2,OR(LEFT(R16,2)="N1",RIGHT(R16,2)="N1")),0.5)+IF(AND(LEN(S16)>2,OR(LEFT(S16,2)="N1",RIGHT(S16,2)="N1")),0.5)+IF(AND(LEN(T16)>2,OR(LEFT(T16,2)="N1",RIGHT(T16,2)="N1")),0.5)+IF(AND(LEN(U16)>2,OR(LEFT(U16,2)="N1",RIGHT(U16,2)="N1")),0.5)+IF(AND(LEN(V16)>2,OR(LEFT(V16,2)="N1",RIGHT(V16,2)="N1")),0.5)+IF(AND(LEN(W16)>2,OR(LEFT(W16,2)="N1",RIGHT(W16,2)="N1")),0.5)+IF(AND(LEN(X16)>2,OR(LEFT(X16,2)="N1",RIGHT(X16,2)="N1")),0.5)+IF(AND(LEN(Y16)>2,OR(LEFT(Y16,2)="N1",RIGHT(Y16,2)="N1")),0.5)+IF(AND(LEN(Z16)>2,OR(LEFT(Z16,2)="N1",RIGHT(Z16,2)="N1")),0.5)+IF(AND(LEN(AA16)>2,OR(LEFT(AA16,2)="N1",RIGHT(AA16,2)="N1")),0.5)+IF(AND(LEN(AB16)>2,OR(LEFT(AB16,2)="N1",RIGHT(AB16,2)="N1")),0.5)+IF(AND(LEN(AC16)>2,OR(LEFT(AC16,2)="N1",RIGHT(AC16,2)="N1")),0.5)+IF(AND(LEN(AD16)>2,OR(LEFT(AD16,2)="N1",RIGHT(AD16,2)="N1")),0.5)+IF(AND(LEN(AE16)>2,OR(LEFT(AE16,2)="N1",RIGHT(AE16,2)="N1")),0.5)+IF(AND(LEN(AF16)>2,OR(LEFT(AF16,2)="N1",RIGHT(AF16,2)="N1")),0.5)+IF(AND(LEN(AG16)>2,OR(LEFT(AG16,2)="N1",RIGHT(AG16,2)="N1")),0.5)+IF(AND(LEN(AH16)>2,OR(LEFT(AH16,2)="N1",RIGHT(AH16,2)="N1")),0.5)+IF(AND(LEN(AI16)>2,OR(LEFT(AI16,2)="N1",RIGHT(AI16,2)="N1")),0.5)+IF(AND(LEN(AJ16)>2,OR(LEFT(AJ16,2)="N1",RIGHT(AJ16,2)="N1")),0.5)+IF(AND(LEN(AK16)>2,OR(LEFT(AK16,2)="N1",RIGHT(AK16,2)="N1")),0.5)+IF(AND(LEN(AL16)>2,OR(LEFT(AL16,2)="N1",RIGHT(AL16,2)="N1")),0.5)) -> 0 | AO16: =COUNTIF(H16:AL16,"ON")+COUNTIF(H16:AL16,"ON/2")/2 -> 0 | AP16: =IF(F16="","",COUNTIF($H16:$AL16,AP$8))+IF(F16="","",COUNTIF($H16:$AL16,$V$5)/2) -> 0 | AQ16: 0 | AR16: =IF(G16="","",AM16+AN16+AP16+AQ16) -> 22 | AS16: =IF(F16="","",COUNTIF($H16:$AL16,AS$8))++IF(F16="","",COUNTIF($H16:$AL16,"L1")/2) -> 0 | AT16: =AU16-AR16-AS16 -> 0 | AU16: 22
A17: =SUBTOTAL(3,$F$11:F17) -> 7 | B17: MS02 | C17: BGH | D17: Hiệu trưởng kiêm nhiệm | F17: Bùi Thanh Anh | G17: Chính Thức | I17: X | J17: X | K17: X | L17: X | M17: X | P17: X | Q17: X | R17: X | S17: X | T17: X | W17: X | X17: X | Y17: X | Z17: X | AA17: X | AD17: X | AE17: X | AF17: X | AG17: X | AH17: X | AK17: X | AL17: X | AM17: =IF(F17="","",COUNTIF($H17:$AL17,AM$8)) -> 22 | AN17: =IF(OR(G17="",G17="Đã nghỉ"),0,COUNTIF($H17:$AL17,"N1")/2++IF(AND(LEN(H17)>2,OR(LEFT(H17,2)="N1",RIGHT(H17,2)="N1")),0.5)+IF(AND(LEN(I17)>2,OR(LEFT(I17,2)="N1",RIGHT(I17,2)="N1")),0.5)+IF(AND(LEN(J17)>2,OR(LEFT(J17,2)="N1",RIGHT(J17,2)="N1")),0.5)+IF(AND(LEN(K17)>2,OR(LEFT(K17,2)="N1",RIGHT(K17,2)="N1")),0.5)+IF(AND(LEN(L17)>2,OR(LEFT(L17,2)="N1",RIGHT(L17,2)="N1")),0.5)+IF(AND(LEN(M17)>2,OR(LEFT(M17,2)="N1",RIGHT(M17,2)="N1")),0.5)+IF(AND(LEN(N17)>2,OR(LEFT(N17,2)="N1",RIGHT(N17,2)="N1")),0.5)+IF(AND(LEN(O17)>2,OR(LEFT(O17,2)="N1",RIGHT(O17,2)="N1")),0.5)+IF(AND(LEN(P17)>2,OR(LEFT(P17,2)="N1",RIGHT(P17,2)="N1")),0.5)+IF(AND(LEN(Q17)>2,OR(LEFT(Q17,2)="N1",RIGHT(Q17,2)="N1")),0.5)+IF(AND(LEN(R17)>2,OR(LEFT(R17,2)="N1",RIGHT(R17,2)="N1")),0.5)+IF(AND(LEN(S17)>2,OR(LEFT(S17,2)="N1",RIGHT(S17,2)="N1")),0.5)+IF(AND(LEN(T17)>2,OR(LEFT(T17,2)="N1",RIGHT(T17,2)="N1")),0.5)+IF(AND(LEN(U17)>2,OR(LEFT(U17,2)="N1",RIGHT(U17,2)="N1")),0.5)+IF(AND(LEN(V17)>2,OR(LEFT(V17,2)="N1",RIGHT(V17,2)="N1")),0.5)+IF(AND(LEN(W17)>2,OR(LEFT(W17,2)="N1",RIGHT(W17,2)="N1")),0.5)+IF(AND(LEN(X17)>2,OR(LEFT(X17,2)="N1",RIGHT(X17,2)="N1")),0.5)+IF(AND(LEN(Y17)>2,OR(LEFT(Y17,2)="N1",RIGHT(Y17,2)="N1")),0.5)+IF(AND(LEN(Z17)>2,OR(LEFT(Z17,2)="N1",RIGHT(Z17,2)="N1")),0.5)+IF(AND(LEN(AA17)>2,OR(LEFT(AA17,2)="N1",RIGHT(AA17,2)="N1")),0.5)+IF(AND(LEN(AB17)>2,OR(LEFT(AB17,2)="N1",RIGHT(AB17,2)="N1")),0.5)+IF(AND(LEN(AC17)>2,OR(LEFT(AC17,2)="N1",RIGHT(AC17,2)="N1")),0.5)+IF(AND(LEN(AD17)>2,OR(LEFT(AD17,2)="N1",RIGHT(AD17,2)="N1")),0.5)+IF(AND(LEN(AE17)>2,OR(LEFT(AE17,2)="N1",RIGHT(AE17,2)="N1")),0.5)+IF(AND(LEN(AF17)>2,OR(LEFT(AF17,2)="N1",RIGHT(AF17,2)="N1")),0.5)+IF(AND(LEN(AG17)>2,OR(LEFT(AG17,2)="N1",RIGHT(AG17,2)="N1")),0.5)+IF(AND(LEN(AH17)>2,OR(LEFT(AH17,2)="N1",RIGHT(AH17,2)="N1")),0.5)+IF(AND(LEN(AI17)>2,OR(LEFT(AI17,2)="N1",RIGHT(AI17,2)="N1")),0.5)+IF(AND(LEN(AJ17)>2,OR(LEFT(AJ17,2)="N1",RIGHT(AJ17,2)="N1")),0.5)+IF(AND(LEN(AK17)>2,OR(LEFT(AK17,2)="N1",RIGHT(AK17,2)="N1")),0.5)+IF(AND(LEN(AL17)>2,OR(LEFT(AL17,2)="N1",RIGHT(AL17,2)="N1")),0.5)) -> 0 | AO17: =COUNTIF(H17:AL17,"ON")+COUNTIF(H17:AL17,"ON/2")/2 -> 0 | AP17: =IF(F17="","",COUNTIF($H17:$AL17,AP$8))+IF(F17="","",COUNTIF($H17:$AL17,$V$5)/2) -> 0 | AQ17: 0 | AR17: =IF(G17="","",AM17+AN17+AP17+AQ17) -> 22 | AS17: =IF(F17="","",COUNTIF($H17:$AL17,AS$8))++IF(F17="","",COUNTIF($H17:$AL17,"L1")/2) -> 0 | AT17: =AU17-AR17-AS17 -> 0 | AU17: 22
A18: =SUBTOTAL(3,$F$11:F18) -> 8 | B18: MS11 | C18: Giáo viên | D18: Giáo viên mầm non | F18: Phùng Thị Lụa | G18: Thử Việc | P18: X | Q18: X | R18: X | S18: X | T18: X | W18: X | X18: X | Y18: X | Z18: X | AA18: X | AD18: X | AE18: X | AF18: X | AG18: X | AH18: X | AK18: X | AL18: X | AM18: =IF(F18="","",COUNTIF($H18:$AL18,AM$8)) -> 17 | AN18: =IF(OR(G18="",G18="Đã nghỉ"),0,COUNTIF($H18:$AL18,"N1")/2++IF(AND(LEN(H18)>2,OR(LEFT(H18,2)="N1",RIGHT(H18,2)="N1")),0.5)+IF(AND(LEN(I18)>2,OR(LEFT(I18,2)="N1",RIGHT(I18,2)="N1")),0.5)+IF(AND(LEN(J18)>2,OR(LEFT(J18,2)="N1",RIGHT(J18,2)="N1")),0.5)+IF(AND(LEN(K18)>2,OR(LEFT(K18,2)="N1",RIGHT(K18,2)="N1")),0.5)+IF(AND(LEN(L18)>2,OR(LEFT(L18,2)="N1",RIGHT(L18,2)="N1")),0.5)+IF(AND(LEN(M18)>2,OR(LEFT(M18,2)="N1",RIGHT(M18,2)="N1")),0.5)+IF(AND(LEN(N18)>2,OR(LEFT(N18,2)="N1",RIGHT(N18,2)="N1")),0.5)+IF(AND(LEN(O18)>2,OR(LEFT(O18,2)="N1",RIGHT(O18,2)="N1")),0.5)+IF(AND(LEN(P18)>2,OR(LEFT(P18,2)="N1",RIGHT(P18,2)="N1")),0.5)+IF(AND(LEN(Q18)>2,OR(LEFT(Q18,2)="N1",RIGHT(Q18,2)="N1")),0.5)+IF(AND(LEN(R18)>2,OR(LEFT(R18,2)="N1",RIGHT(R18,2)="N1")),0.5)+IF(AND(LEN(S18)>2,OR(LEFT(S18,2)="N1",RIGHT(S18,2)="N1")),0.5)+IF(AND(LEN(T18)>2,OR(LEFT(T18,2)="N1",RIGHT(T18,2)="N1")),0.5)+IF(AND(LEN(U18)>2,OR(LEFT(U18,2)="N1",RIGHT(U18,2)="N1")),0.5)+IF(AND(LEN(V18)>2,OR(LEFT(V18,2)="N1",RIGHT(V18,2)="N1")),0.5)+IF(AND(LEN(W18)>2,OR(LEFT(W18,2)="N1",RIGHT(W18,2)="N1")),0.5)+IF(AND(LEN(X18)>2,OR(LEFT(X18,2)="N1",RIGHT(X18,2)="N1")),0.5)+IF(AND(LEN(Y18)>2,OR(LEFT(Y18,2)="N1",RIGHT(Y18,2)="N1")),0.5)+IF(AND(LEN(Z18)>2,OR(LEFT(Z18,2)="N1",RIGHT(Z18,2)="N1")),0.5)+IF(AND(LEN(AA18)>2,OR(LEFT(AA18,2)="N1",RIGHT(AA18,2)="N1")),0.5)+IF(AND(LEN(AB18)>2,OR(LEFT(AB18,2)="N1",RIGHT(AB18,2)="N1")),0.5)+IF(AND(LEN(AC18)>2,OR(LEFT(AC18,2)="N1",RIGHT(AC18,2)="N1")),0.5)+IF(AND(LEN(AD18)>2,OR(LEFT(AD18,2)="N1",RIGHT(AD18,2)="N1")),0.5)+IF(AND(LEN(AE18)>2,OR(LEFT(AE18,2)="N1",RIGHT(AE18,2)="N1")),0.5)+IF(AND(LEN(AF18)>2,OR(LEFT(AF18,2)="N1",RIGHT(AF18,2)="N1")),0.5)+IF(AND(LEN(AG18)>2,OR(LEFT(AG18,2)="N1",RIGHT(AG18,2)="N1")),0.5)+IF(AND(LEN(AH18)>2,OR(LEFT(AH18,2)="N1",RIGHT(AH18,2)="N1")),0.5)+IF(AND(LEN(AI18)>2,OR(LEFT(AI18,2)="N1",RIGHT(AI18,2)="N1")),0.5)+IF(AND(LEN(AJ18)>2,OR(LEFT(AJ18,2)="N1",RIGHT(AJ18,2)="N1")),0.5)+IF(AND(LEN(AK18)>2,OR(LEFT(AK18,2)="N1",RIGHT(AK18,2)="N1")),0.5)+IF(AND(LEN(AL18)>2,OR(LEFT(AL18,2)="N1",RIGHT(AL18,2)="N1")),0.5)) -> 0 | AO18: =COUNTIF(H18:AL18,"ON")+COUNTIF(H18:AL18,"ON/2")/2 -> 0 | AP18: =IF(F18="","",COUNTIF($H18:$AL18,AP$8))+IF(F18="","",COUNTIF($H18:$AL18,$V$5)/2) -> 0 | AQ18: 0 | AR18: =IF(G18="","",AM18+AN18+AP18+AQ18) -> 17 | AS18: =IF(F18="","",COUNTIF($H18:$AL18,AS$8))++IF(F18="","",COUNTIF($H18:$AL18,"L1")/2) -> 0 | AT18: =AU18-AR18-AS18 -> 5 | AU18: 22
A19: =SUBTOTAL(3,$F$11:F19) -> 9 | B19: MS12 | C19: Vận hành | D19: HK | F19: Đinh Thị Bích Ngọc | G19: Thử Việc | I19: X | J19: X | K19: X | L19: X | M19: X | P19: X | Q19: X | R19: X | S19: X | T19: X | W19: X | X19: X | Y19: X | Z19: X | AA19: X | AD19: X | AE19: X | AF19: X | AG19: X | AH19: X | AK19: X | AL19: X | AM19: =IF(F19="","",COUNTIF($H19:$AL19,AM$8)) -> 22 | AN19: =IF(OR(G19="",G19="Đã nghỉ"),0,COUNTIF($H19:$AL19,"N1")/2++IF(AND(LEN(H19)>2,OR(LEFT(H19,2)="N1",RIGHT(H19,2)="N1")),0.5)+IF(AND(LEN(I19)>2,OR(LEFT(I19,2)="N1",RIGHT(I19,2)="N1")),0.5)+IF(AND(LEN(J19)>2,OR(LEFT(J19,2)="N1",RIGHT(J19,2)="N1")),0.5)+IF(AND(LEN(K19)>2,OR(LEFT(K19,2)="N1",RIGHT(K19,2)="N1")),0.5)+IF(AND(LEN(L19)>2,OR(LEFT(L19,2)="N1",RIGHT(L19,2)="N1")),0.5)+IF(AND(LEN(M19)>2,OR(LEFT(M19,2)="N1",RIGHT(M19,2)="N1")),0.5)+IF(AND(LEN(N19)>2,OR(LEFT(N19,2)="N1",RIGHT(N19,2)="N1")),0.5)+IF(AND(LEN(O19)>2,OR(LEFT(O19,2)="N1",RIGHT(O19,2)="N1")),0.5)+IF(AND(LEN(P19)>2,OR(LEFT(P19,2)="N1",RIGHT(P19,2)="N1")),0.5)+IF(AND(LEN(Q19)>2,OR(LEFT(Q19,2)="N1",RIGHT(Q19,2)="N1")),0.5)+IF(AND(LEN(R19)>2,OR(LEFT(R19,2)="N1",RIGHT(R19,2)="N1")),0.5)+IF(AND(LEN(S19)>2,OR(LEFT(S19,2)="N1",RIGHT(S19,2)="N1")),0.5)+IF(AND(LEN(T19)>2,OR(LEFT(T19,2)="N1",RIGHT(T19,2)="N1")),0.5)+IF(AND(LEN(U19)>2,OR(LEFT(U19,2)="N1",RIGHT(U19,2)="N1")),0.5)+IF(AND(LEN(V19)>2,OR(LEFT(V19,2)="N1",RIGHT(V19,2)="N1")),0.5)+IF(AND(LEN(W19)>2,OR(LEFT(W19,2)="N1",RIGHT(W19,2)="N1")),0.5)+IF(AND(LEN(X19)>2,OR(LEFT(X19,2)="N1",RIGHT(X19,2)="N1")),0.5)+IF(AND(LEN(Y19)>2,OR(LEFT(Y19,2)="N1",RIGHT(Y19,2)="N1")),0.5)+IF(AND(LEN(Z19)>2,OR(LEFT(Z19,2)="N1",RIGHT(Z19,2)="N1")),0.5)+IF(AND(LEN(AA19)>2,OR(LEFT(AA19,2)="N1",RIGHT(AA19,2)="N1")),0.5)+IF(AND(LEN(AB19)>2,OR(LEFT(AB19,2)="N1",RIGHT(AB19,2)="N1")),0.5)+IF(AND(LEN(AC19)>2,OR(LEFT(AC19,2)="N1",RIGHT(AC19,2)="N1")),0.5)+IF(AND(LEN(AD19)>2,OR(LEFT(AD19,2)="N1",RIGHT(AD19,2)="N1")),0.5)+IF(AND(LEN(AE19)>2,OR(LEFT(AE19,2)="N1",RIGHT(AE19,2)="N1")),0.5)+IF(AND(LEN(AF19)>2,OR(LEFT(AF19,2)="N1",RIGHT(AF19,2)="N1")),0.5)+IF(AND(LEN(AG19)>2,OR(LEFT(AG19,2)="N1",RIGHT(AG19,2)="N1")),0.5)+IF(AND(LEN(AH19)>2,OR(LEFT(AH19,2)="N1",RIGHT(AH19,2)="N1")),0.5)+IF(AND(LEN(AI19)>2,OR(LEFT(AI19,2)="N1",RIGHT(AI19,2)="N1")),0.5)+IF(AND(LEN(AJ19)>2,OR(LEFT(AJ19,2)="N1",RIGHT(AJ19,2)="N1")),0.5)+IF(AND(LEN(AK19)>2,OR(LEFT(AK19,2)="N1",RIGHT(AK19,2)="N1")),0.5)+IF(AND(LEN(AL19)>2,OR(LEFT(AL19,2)="N1",RIGHT(AL19,2)="N1")),0.5)) -> 0 | AO19: =COUNTIF(H19:AL19,"ON")+COUNTIF(H19:AL19,"ON/2")/2 -> 0 | AP19: =IF(F19="","",COUNTIF($H19:$AL19,AP$8))+IF(F19="","",COUNTIF($H19:$AL19,$V$5)/2) -> 0 | AQ19: 0 | AR19: =IF(G19="","",AM19+AN19+AP19+AQ19) -> 22 | AS19: =IF(F19="","",COUNTIF($H19:$AL19,AS$8))++IF(F19="","",COUNTIF($H19:$AL19,"L1")/2) -> 0 | AT19: =AU19-AR19-AS19 -> 0 | AU19: 22
A20: =SUBTOTAL(3,$F$11:F20) -> 10 | B20: MS13 | C20: Vận hành | D20: Bảo vệ | F20: Lương Văn Châm | G20: Thử Việc | S20: X | T20: X | W20: X | X20: X | Y20: X | Z20: X | AA20: X | AD20: X | AE20: X | AF20: X | AG20: X | AH20: X | AK20: X | AL20: X | AM20: =IF(F20="","",COUNTIF($H20:$AL20,AM$8)) -> 14 | AN20: =IF(OR(G20="",G20="Đã nghỉ"),0,COUNTIF($H20:$AL20,"N1")/2++IF(AND(LEN(H20)>2,OR(LEFT(H20,2)="N1",RIGHT(H20,2)="N1")),0.5)+IF(AND(LEN(I20)>2,OR(LEFT(I20,2)="N1",RIGHT(I20,2)="N1")),0.5)+IF(AND(LEN(J20)>2,OR(LEFT(J20,2)="N1",RIGHT(J20,2)="N1")),0.5)+IF(AND(LEN(K20)>2,OR(LEFT(K20,2)="N1",RIGHT(K20,2)="N1")),0.5)+IF(AND(LEN(L20)>2,OR(LEFT(L20,2)="N1",RIGHT(L20,2)="N1")),0.5)+IF(AND(LEN(M20)>2,OR(LEFT(M20,2)="N1",RIGHT(M20,2)="N1")),0.5)+IF(AND(LEN(N20)>2,OR(LEFT(N20,2)="N1",RIGHT(N20,2)="N1")),0.5)+IF(AND(LEN(O20)>2,OR(LEFT(O20,2)="N1",RIGHT(O20,2)="N1")),0.5)+IF(AND(LEN(P20)>2,OR(LEFT(P20,2)="N1",RIGHT(P20,2)="N1")),0.5)+IF(AND(LEN(Q20)>2,OR(LEFT(Q20,2)="N1",RIGHT(Q20,2)="N1")),0.5)+IF(AND(LEN(R20)>2,OR(LEFT(R20,2)="N1",RIGHT(R20,2)="N1")),0.5)+IF(AND(LEN(S20)>2,OR(LEFT(S20,2)="N1",RIGHT(S20,2)="N1")),0.5)+IF(AND(LEN(T20)>2,OR(LEFT(T20,2)="N1",RIGHT(T20,2)="N1")),0.5)+IF(AND(LEN(U20)>2,OR(LEFT(U20,2)="N1",RIGHT(U20,2)="N1")),0.5)+IF(AND(LEN(V20)>2,OR(LEFT(V20,2)="N1",RIGHT(V20,2)="N1")),0.5)+IF(AND(LEN(W20)>2,OR(LEFT(W20,2)="N1",RIGHT(W20,2)="N1")),0.5)+IF(AND(LEN(X20)>2,OR(LEFT(X20,2)="N1",RIGHT(X20,2)="N1")),0.5)+IF(AND(LEN(Y20)>2,OR(LEFT(Y20,2)="N1",RIGHT(Y20,2)="N1")),0.5)+IF(AND(LEN(Z20)>2,OR(LEFT(Z20,2)="N1",RIGHT(Z20,2)="N1")),0.5)+IF(AND(LEN(AA20)>2,OR(LEFT(AA20,2)="N1",RIGHT(AA20,2)="N1")),0.5)+IF(AND(LEN(AB20)>2,OR(LEFT(AB20,2)="N1",RIGHT(AB20,2)="N1")),0.5)+IF(AND(LEN(AC20)>2,OR(LEFT(AC20,2)="N1",RIGHT(AC20,2)="N1")),0.5)+IF(AND(LEN(AD20)>2,OR(LEFT(AD20,2)="N1",RIGHT(AD20,2)="N1")),0.5)+IF(AND(LEN(AE20)>2,OR(LEFT(AE20,2)="N1",RIGHT(AE20,2)="N1")),0.5)+IF(AND(LEN(AF20)>2,OR(LEFT(AF20,2)="N1",RIGHT(AF20,2)="N1")),0.5)+IF(AND(LEN(AG20)>2,OR(LEFT(AG20,2)="N1",RIGHT(AG20,2)="N1")),0.5)+IF(AND(LEN(AH20)>2,OR(LEFT(AH20,2)="N1",RIGHT(AH20,2)="N1")),0.5)+IF(AND(LEN(AI20)>2,OR(LEFT(AI20,2)="N1",RIGHT(AI20,2)="N1")),0.5)+IF(AND(LEN(AJ20)>2,OR(LEFT(AJ20,2)="N1",RIGHT(AJ20,2)="N1")),0.5)+IF(AND(LEN(AK20)>2,OR(LEFT(AK20,2)="N1",RIGHT(AK20,2)="N1")),0.5)+IF(AND(LEN(AL20)>2,OR(LEFT(AL20,2)="N1",RIGHT(AL20,2)="N1")),0.5)) -> 0 | AO20: =COUNTIF(H20:AL20,"ON")+COUNTIF(H20:AL20,"ON/2")/2 -> 0 | AP20: =IF(F20="","",COUNTIF($H20:$AL20,AP$8))+IF(F20="","",COUNTIF($H20:$AL20,$V$5)/2) -> 0 | AQ20: 0 | AR20: =IF(G20="","",AM20+AN20+AP20+AQ20) -> 14 | AS20: =IF(F20="","",COUNTIF($H20:$AL20,AS$8))++IF(F20="","",COUNTIF($H20:$AL20,"L1")/2) -> 0 | AT20: =AU20-AR20-AS20 -> 8 | AU20: 22
A21: =SUBTOTAL(3,$F$11:F21) -> 11 | B21: MS14 | C21: Vận hành | D21: Y tế | F21: Nguyễn Thị Phúc | G21: Thử Việc | I21: X | J21: X | K21: X | L21: X | M21: X | P21: X | Q21: X | R21: X | S21: X | T21: X | W21: X | X21: X | Y21: X | Z21: X | AA21: X | AD21: X | AE21: X | AF21: X | AG21: X | AH21: X | AK21: X | AL21: X | AM21: =IF(F21="","",COUNTIF($H21:$AL21,AM$8)) -> 22 | AN21: =IF(OR(G21="",G21="Đã nghỉ"),0,COUNTIF($H21:$AL21,"N1")/2++IF(AND(LEN(H21)>2,OR(LEFT(H21,2)="N1",RIGHT(H21,2)="N1")),0.5)+IF(AND(LEN(I21)>2,OR(LEFT(I21,2)="N1",RIGHT(I21,2)="N1")),0.5)+IF(AND(LEN(J21)>2,OR(LEFT(J21,2)="N1",RIGHT(J21,2)="N1")),0.5)+IF(AND(LEN(K21)>2,OR(LEFT(K21,2)="N1",RIGHT(K21,2)="N1")),0.5)+IF(AND(LEN(L21)>2,OR(LEFT(L21,2)="N1",RIGHT(L21,2)="N1")),0.5)+IF(AND(LEN(M21)>2,OR(LEFT(M21,2)="N1",RIGHT(M21,2)="N1")),0.5)+IF(AND(LEN(N21)>2,OR(LEFT(N21,2)="N1",RIGHT(N21,2)="N1")),0.5)+IF(AND(LEN(O21)>2,OR(LEFT(O21,2)="N1",RIGHT(O21,2)="N1")),0.5)+IF(AND(LEN(P21)>2,OR(LEFT(P21,2)="N1",RIGHT(P21,2)="N1")),0.5)+IF(AND(LEN(Q21)>2,OR(LEFT(Q21,2)="N1",RIGHT(Q21,2)="N1")),0.5)+IF(AND(LEN(R21)>2,OR(LEFT(R21,2)="N1",RIGHT(R21,2)="N1")),0.5)+IF(AND(LEN(S21)>2,OR(LEFT(S21,2)="N1",RIGHT(S21,2)="N1")),0.5)+IF(AND(LEN(T21)>2,OR(LEFT(T21,2)="N1",RIGHT(T21,2)="N1")),0.5)+IF(AND(LEN(U21)>2,OR(LEFT(U21,2)="N1",RIGHT(U21,2)="N1")),0.5)+IF(AND(LEN(V21)>2,OR(LEFT(V21,2)="N1",RIGHT(V21,2)="N1")),0.5)+IF(AND(LEN(W21)>2,OR(LEFT(W21,2)="N1",RIGHT(W21,2)="N1")),0.5)+IF(AND(LEN(X21)>2,OR(LEFT(X21,2)="N1",RIGHT(X21,2)="N1")),0.5)+IF(AND(LEN(Y21)>2,OR(LEFT(Y21,2)="N1",RIGHT(Y21,2)="N1")),0.5)+IF(AND(LEN(Z21)>2,OR(LEFT(Z21,2)="N1",RIGHT(Z21,2)="N1")),0.5)+IF(AND(LEN(AA21)>2,OR(LEFT(AA21,2)="N1",RIGHT(AA21,2)="N1")),0.5)+IF(AND(LEN(AB21)>2,OR(LEFT(AB21,2)="N1",RIGHT(AB21,2)="N1")),0.5)+IF(AND(LEN(AC21)>2,OR(LEFT(AC21,2)="N1",RIGHT(AC21,2)="N1")),0.5)+IF(AND(LEN(AD21)>2,OR(LEFT(AD21,2)="N1",RIGHT(AD21,2)="N1")),0.5)+IF(AND(LEN(AE21)>2,OR(LEFT(AE21,2)="N1",RIGHT(AE21,2)="N1")),0.5)+IF(AND(LEN(AF21)>2,OR(LEFT(AF21,2)="N1",RIGHT(AF21,2)="N1")),0.5)+IF(AND(LEN(AG21)>2,OR(LEFT(AG21,2)="N1",RIGHT(AG21,2)="N1")),0.5)+IF(AND(LEN(AH21)>2,OR(LEFT(AH21,2)="N1",RIGHT(AH21,2)="N1")),0.5)+IF(AND(LEN(AI21)>2,OR(LEFT(AI21,2)="N1",RIGHT(AI21,2)="N1")),0.5)+IF(AND(LEN(AJ21)>2,OR(LEFT(AJ21,2)="N1",RIGHT(AJ21,2)="N1")),0.5)+IF(AND(LEN(AK21)>2,OR(LEFT(AK21,2)="N1",RIGHT(AK21,2)="N1")),0.5)+IF(AND(LEN(AL21)>2,OR(LEFT(AL21,2)="N1",RIGHT(AL21,2)="N1")),0.5)) -> 0 | AO21: =COUNTIF(H21:AL21,"ON")+COUNTIF(H21:AL21,"ON/2")/2 -> 0 | AP21: =IF(F21="","",COUNTIF($H21:$AL21,AP$8))+IF(F21="","",COUNTIF($H21:$AL21,$V$5)/2) -> 0 | AQ21: 0 | AR21: =IF(G21="","",AM21+AN21+AP21+AQ21) -> 22 | AS21: =IF(F21="","",COUNTIF($H21:$AL21,AS$8))++IF(F21="","",COUNTIF($H21:$AL21,"L1")/2) -> 0 | AT21: =AU21-AR21-AS21 -> 0 | AU21: 22
A22: =SUBTOTAL(3,$F$11:F22) -> 12 | B22: MS15 | C22: Vận hành | D22: Vận hành | F22: Nguyễn Thị Thuỳ Trang | G22: Thử Việc | AE22: X | AF22: X | AG22: X | AH22: X | AK22: X | AL22: X | AM22: =IF(F22="","",COUNTIF($H22:$AL22,AM$8)) -> 6 | AN22: =IF(OR(G22="",G22="Đã nghỉ"),0,COUNTIF($H22:$AL22,"N1")/2++IF(AND(LEN(H22)>2,OR(LEFT(H22,2)="N1",RIGHT(H22,2)="N1")),0.5)+IF(AND(LEN(I22)>2,OR(LEFT(I22,2)="N1",RIGHT(I22,2)="N1")),0.5)+IF(AND(LEN(J22)>2,OR(LEFT(J22,2)="N1",RIGHT(J22,2)="N1")),0.5)+IF(AND(LEN(K22)>2,OR(LEFT(K22,2)="N1",RIGHT(K22,2)="N1")),0.5)+IF(AND(LEN(L22)>2,OR(LEFT(L22,2)="N1",RIGHT(L22,2)="N1")),0.5)+IF(AND(LEN(M22)>2,OR(LEFT(M22,2)="N1",RIGHT(M22,2)="N1")),0.5)+IF(AND(LEN(N22)>2,OR(LEFT(N22,2)="N1",RIGHT(N22,2)="N1")),0.5)+IF(AND(LEN(O22)>2,OR(LEFT(O22,2)="N1",RIGHT(O22,2)="N1")),0.5)+IF(AND(LEN(P22)>2,OR(LEFT(P22,2)="N1",RIGHT(P22,2)="N1")),0.5)+IF(AND(LEN(Q22)>2,OR(LEFT(Q22,2)="N1",RIGHT(Q22,2)="N1")),0.5)+IF(AND(LEN(R22)>2,OR(LEFT(R22,2)="N1",RIGHT(R22,2)="N1")),0.5)+IF(AND(LEN(S22)>2,OR(LEFT(S22,2)="N1",RIGHT(S22,2)="N1")),0.5)+IF(AND(LEN(T22)>2,OR(LEFT(T22,2)="N1",RIGHT(T22,2)="N1")),0.5)+IF(AND(LEN(U22)>2,OR(LEFT(U22,2)="N1",RIGHT(U22,2)="N1")),0.5)+IF(AND(LEN(V22)>2,OR(LEFT(V22,2)="N1",RIGHT(V22,2)="N1")),0.5)+IF(AND(LEN(W22)>2,OR(LEFT(W22,2)="N1",RIGHT(W22,2)="N1")),0.5)+IF(AND(LEN(X22)>2,OR(LEFT(X22,2)="N1",RIGHT(X22,2)="N1")),0.5)+IF(AND(LEN(Y22)>2,OR(LEFT(Y22,2)="N1",RIGHT(Y22,2)="N1")),0.5)+IF(AND(LEN(Z22)>2,OR(LEFT(Z22,2)="N1",RIGHT(Z22,2)="N1")),0.5)+IF(AND(LEN(AA22)>2,OR(LEFT(AA22,2)="N1",RIGHT(AA22,2)="N1")),0.5)+IF(AND(LEN(AB22)>2,OR(LEFT(AB22,2)="N1",RIGHT(AB22,2)="N1")),0.5)+IF(AND(LEN(AC22)>2,OR(LEFT(AC22,2)="N1",RIGHT(AC22,2)="N1")),0.5)+IF(AND(LEN(AD22)>2,OR(LEFT(AD22,2)="N1",RIGHT(AD22,2)="N1")),0.5)+IF(AND(LEN(AE22)>2,OR(LEFT(AE22,2)="N1",RIGHT(AE22,2)="N1")),0.5)+IF(AND(LEN(AF22)>2,OR(LEFT(AF22,2)="N1",RIGHT(AF22,2)="N1")),0.5)+IF(AND(LEN(AG22)>2,OR(LEFT(AG22,2)="N1",RIGHT(AG22,2)="N1")),0.5)+IF(AND(LEN(AH22)>2,OR(LEFT(AH22,2)="N1",RIGHT(AH22,2)="N1")),0.5)+IF(AND(LEN(AI22)>2,OR(LEFT(AI22,2)="N1",RIGHT(AI22,2)="N1")),0.5)+IF(AND(LEN(AJ22)>2,OR(LEFT(AJ22,2)="N1",RIGHT(AJ22,2)="N1")),0.5)+IF(AND(LEN(AK22)>2,OR(LEFT(AK22,2)="N1",RIGHT(AK22,2)="N1")),0.5)+IF(AND(LEN(AL22)>2,OR(LEFT(AL22,2)="N1",RIGHT(AL22,2)="N1")),0.5)) -> 0 | AO22: =COUNTIF(H22:AL22,"ON")+COUNTIF(H22:AL22,"ON/2")/2 -> 0 | AP22: =IF(F22="","",COUNTIF($H22:$AL22,AP$8))+IF(F22="","",COUNTIF($H22:$AL22,$V$5)/2) -> 0 | AQ22: 0 | AR22: =IF(G22="","",AM22+AN22+AP22+AQ22) -> 6 | AS22: =IF(F22="","",COUNTIF($H22:$AL22,AS$8))++IF(F22="","",COUNTIF($H22:$AL22,"L1")/2) -> 0 | AT22: =AU22-AR22-AS22 -> 16 | AU22: 22
A23: Tổng | AM23: =SUBTOTAL(9,AM11:AM12) -> 43 | AN23: =SUBTOTAL(9,AN11:AN22) -> 9.5 | AO23: =SUBTOTAL(9,AO11:AO22) -> 0 | AP23: =SUBTOTAL(9,AP11:AP22) -> 0 | AQ23: =SUBTOTAL(9,AQ11:AQ12) -> 1 | AR23: =SUBTOTAL(9,AR11:AR22) -> 208.5 | AS23: =SUBTOTAL(9,AS11:AS22) -> 0 | AT23: =SUBTOTAL(9,AT11:AT22) -> 55.5 | AU23: =SUBTOTAL(9,AU11:AU22) -> 264
B24: 1 | C24: =B24+1 -> 2 | D24: =C24+1 -> 3 | E24: =D24+1 -> 4 | F24: =E24+1 -> 5 | G24: =F24+1 -> 6 | H24: =G24+1 -> 7 | I24: =H24+1 -> 8 | J24: =I24+1 -> 9 | ... AV24: =AU24+1 -> 47
AM25: Hà Nội, ngày ..... tháng ..... năm 2026
D26: Tổng giám đốc | M26: Phòng Tài chính - Kế toán | Z26: Phòng Hành chính - Nhân sự | AM26: Người lập

Sheet 4. Bảng phép năm 2026
A1: CVG - BẢNG THEO DÕI PHÉP NĂM 2026
A2: STT | B2: Mã NV | C2: Phòng | D2: Họ & Tên | E2: Số phép đã nghỉ (phép năm 2026) | R2: Tổng phép đã nghỉ năm 2026 | S2: Số ngày phép năm 2025 | T2: Phép tồn | U2: Ghi chú
E3: Thời gian bắt đầu tính phép Đvt: tháng | F3: T1 | G3: T2 | H3: T3 | I3: T4 | J3: T5 | K3: T6 | L3: T7 | M3: T8 | N3: T9 | O3: T10 | P3: T11 | Q3: T12
B4: 1 | C4: =B4+1 -> 2 | D4: =C4+1 -> 3 | E4: =#REF!+1 -> #REF! | F4: =E4+1 -> #REF! | G4: =F4+1 -> #REF! | H4: =G4+1 -> #REF! | I4: =H4+1 -> #REF! | J4: =I4+1 -> #REF! | K4: =J4+1 -> #REF! | L4: =K4+1 -> #REF! | M4: =L4+1 -> #REF! | ... U4: =T4+1 -> #REF!
F5: =SUM(F6:F8) -> 1 | G5: =SUM(G6:G8) -> 0 | H5: =SUM(H6:H8) -> 0 | I5: =SUM(I6:I8) -> 0 | J5: =SUM(J6:J8) -> 0 | K5: =SUM(K6:K8) -> 0 | L5: =SUM(L6:L8) -> 0 | M5: =SUM(M6:M8) -> 0 | ... R5: =SUM(R6:R8) -> 1 | S5: 2 | T5: =SUM(T6:T8) -> 2
A6: =SUBTOTAL(3,$B$5:B6) -> 1 | B6: MS04 | D6: =VLOOKUP(B6,' 5. Thông số TL'!$D$12:$E$16,2,0) -> Nguyễn Thị Thu Hảo | F6: =VLOOKUP(B6,'3. BẢNG CHẤM CÔNG'!$B$11:$AU$12,42,0) -> 1 | G6: 0 | H6: 0 | I6: 0 | J6: 0 | K6: 0 | L6: 0 | M6: 0 | N6: 0 | O6: 0 | P6: 0 | Q6: 0 | R6: =SUM(F6:Q6) -> 1 | S6: 2 | T6: 2
A7: =SUBTOTAL(3,$B$5:B7) -> 2 | B7: MS03 | D7: =VLOOKUP(B7,' 5. Thông số TL'!$D$12:$E$16,2,0) -> Lê Thị Kim Liên | F7: 0 | G7: 0 | H7: 0 | I7: 0 | J7: 0 | K7: 0 | L7: 0 | M7: 0 | N7: 0 | O7: 0 | P7: 0 | Q7: 0 | R7: =SUM(F7:Q7) -> 0 | S7: 0 | T7: 0
A8: 3 | B8: MS02 | D8: =VLOOKUP(B8,' 5. Thông số TL'!$D$12:$E$16,2,0) -> Bùi Thanh Anh | F8: 0 | G8: 0 | H8: 0 | I8: 0 | J8: 0 | K8: 0 | L8: 0 | M8: 0 | N8: 0 | O8: 0 | P8: 0 | Q8: 0 | R8: =SUM(F8:Q8) -> 0 | S8: =SUM(G8:R8) -> 0 | T8: =SUM(H8:S8) -> 0
A9: 5 | B9: MS06 | D9: =VLOOKUP(B9,' 5. Thông số TL'!$D$12:$E$16,2,0) -> Eugene | F9: 0 | G9: 0 | H9: 0 | I9: 0 | J9: 0 | K9: 0 | L9: 0 | M9: 0 | N9: 0 | O9: 0 | P9: 0 | Q9: 0 | R9: =SUM(F9:Q9) -> 0 | S9: =SUM(G9:R9) -> 0 | T9: =SUM(H9:S9) -> 0

Sheet  5. Thông số TL
A3: BẢNG THÔNG SỐ TÍNH LƯƠNG VỊ TRÍ
A5: I. Mục tiêu
A8: II. Bảng thông số
A9: STT | B9: Phòng/Ban | C9: Chức danh | D9: Mã nhân viên | E9: Họ và tên | F9: Tầng NS | G9: Lương BHXH | H9: Thưởng Hiệu quả công việc | I9: Các khoản phụ cấp | O9: Tổng | P9: Thưởng Hiệu quả kinh doanh/Dự án | S9: Tổng thu nhập trước thuế
I10: PC miễn thuế | L10: PC đóng thuế | N10: Tổng phụ cấp | P10: Tên thông số | Q10: Hck | R10: Doanh thu
I11: Ăn trưa | J11: Trang phục | K11: Điện thoại | L11: Kiêm nhiệm | M11: Gửi xe
A12: =SUBTOTAL(3,$C$12:C12) -> 1 | B12: Vận hành | C12: Trưởng phòng vận hành | D12: MS04 | E12: Nguyễn Thị Thu Hảo | G12: 7500000 | H12: 4880000 | I12: 720000 | J12: 400000 | K12: 2500000 | N12: =SUM(I12:M12) -> 3620000 | O12: =G12+H12+N12 -> 16000000 | S12: =O12+R12 -> 16000000
A13: =SUBTOTAL(3,$C$12:C13) -> 2 | B13: Ban giám hiệu | C13: Hiệu phó cơ sở | D13: MS03 | E13: Lê Thị Kim Liên | G13: 7500000 | H13: 7267500 | I13: 720000 | J13: 400000 | K13: 900000 | N13: =SUM(I13:M13) -> 2020000 | O13: =G13+H13+N13 -> 16787500 | S13: =O13+R13 -> 16787500
A14: =SUBTOTAL(3,$C$12:C14) -> 3 | B14: Ban giám hiệu | C14: Hiệu trưởng ̣(kiêm nhiệm) | D14: MS02 | E14: Bùi Thanh Anh | H14: 13046667 | I14: 720000 | J14: 400000 | K14: 2500000 | N14: =SUM(I14:M14) -> 3620000 | O14: =G14+H14+N14 -> 16666667 | S14: =O14+R14 -> 16666667
A15: =SUBTOTAL(3,$C$12:C15) -> 4 | B15: Ban giám hiệu | C15: Hiệu phó cơ sở | D15: MS05 | E15: Hoàng Thị Hoa | G15: 8000000 | H15: 10180000 | I15: 720000 | J15: 400000 | K15: 1924000 | N15: =SUM(I15:M15) -> 3044000 | O15: =G15+H15+N15 -> 21224000 | S15: =O15+R15 -> 21224000
A16: =SUBTOTAL(3,$C$12:C16) -> 5 | B16: Giáo viên | C16: Giáo viên nước ngoài | D16: MS06 | E16: Eugene | G16: 5500000 | H16: 42306650 | I16: 720000 | J16: 400000 | K16: 900000 | N16: =SUM(I16:M16) -> 2020000 | O16: =G16+H16+N16 -> 49826650 | S16: =O16+R16 -> 49826650
A17: =SUBTOTAL(3,$C$12:C17) -> 6 | B17: Giáo viên | C17: Giáo viên mầm non | D17: MS07 | E17: Nguyễn Thị Ánh Hồng | G17: 5500000 | H17: 1880000 | I17: 720000 | J17: 400000 | K17: 500000 | N17: =SUM(I17:M17) -> 1620000 | O17: =G17+H17+N17 -> 9000000 | S17: =O17+R17 -> 9000000
A18: =SUBTOTAL(3,$C$12:C18) -> 7 | B18: Giáo viên | C18: Giáo viên mầm non | D18: MS08 | E18: Hoàng Thị Hương Li | G18: 5500000 | H18: 1880000 | I18: 720000 | J18: 400000 | K18: 500000 | N18: =SUM(I18:M18) -> 1620000 | O18: =G18+H18+N18 -> 9000000 | S18: =O18+R18 -> 9000000
A19: =SUBTOTAL(3,$C$12:C19) -> 8 | B19: Ban giám hiệu | C19: Quản lý chương trình TA | D19: MS09 | E19: Nguyễn Thị Thu | H19: 5768889 | I19: 720000 | J19: 400000 | K19: 2000000 | N19: =SUM(I19:M19) -> 3120000 | O19: =G19+H19+N19 -> 8888889 | S19: =O19+R19 -> 8888889
A20: =SUBTOTAL(3,$C$12:C20) -> 9 | B20: Giáo viên | C20: Giáo viên TA VN | D20: MS10 | E20: Bùi Thị Thương | G20: 5500000 | H20: 5880000 | I20: 720000 | J20: 400000 | K20: 500000 | N20: =SUM(I20:M20) -> 1620000 | O20: =G20+H20+N20 -> 13000000 | S20: =O20+R20 -> 13000000
A21: =SUBTOTAL(3,$C$12:C21) -> 10 | B21: Giáo viên | C21: Giáo viên mầm non | D21: MS11 | E21: Phùng Thị Lụa | G21: 5500000 | H21: 2457500 | I21: 720000 | J21: 400000 | K21: 500000 | N21: =SUM(I21:M21) -> 1620000 | O21: =G21+H21+N21 -> 9577500 | S21: =O21+R21 -> 9577500
A22: =SUBTOTAL(3,$C$12:C22) -> 11 | B22: Vận hành | C22: HK | D22: MS12 | E22: Đinh Thị Bích Ngọc | G22: 4960000 | H22: 1040800 | I22: 720000 | J22: 400000 | K22: 400000 | N22: =SUM(I22:M22) -> 1520000 | O22: =G22+H22+N22 -> 7520800 | S22: =O22+R22 -> 7520800
A23: =SUBTOTAL(3,$C$12:C23) -> 12 | B23: Vận hành | C23: Bảo vệ | D23: MS13 | E23: Lương Văn Châm | G23: 4960000 | H23: 4040800 | I23: 720000 | J23: 400000 | K23: 400000 | N23: =SUM(I23:M23) -> 1520000 | O23: =G23+H23+N23 -> 10520800 | S23: =O23+R23 -> 10520800
A24: =SUBTOTAL(3,$C$12:C24) -> 13 | B24: Vận hành | C24: Y tế | D24: MS14 | E24: Nguyễn Thị Phúc | G24: 5500000 | H24: 3457500 | I24: 720000 | J24: 400000 | K24: 500000 | N24: =SUM(I24:M24) -> 1620000 | O24: =G24+H24+N24 -> 10577500 | S24: =O24+R24 -> 10577500
A25: =SUBTOTAL(3,$C$12:C25) -> 14 | B25: Vận hành | C25: Vận hành | D25: MS15 | E25: Nguyễn Thị Thuỳ Trang | G25: 5500000 | H25: 2457500 | I25: 720000 | J25: 400000 | K25: 500000 | N25: =SUM(I25:M25) -> 1620000 | O25: =G25+H25+N25 -> 9577500 | S25: =O25+R25 -> 9577500
A26: Tổng | G26: =SUM(G12:G17) -> 34000000 | H26: =SUM(H12:H17) -> 79560817 | I26: =SUM(I12:I16) -> 3600000 | J26: =SUM(J12:J16) -> 2000000 | K26: =SUM(K12:K17) -> 9224000 | L26: =SUM(L12:L13) -> 0 | M26: =SUM(M12:M13) -> 0 | N26: =SUM(N12:N17) -> 15944000 | O26: =SUM(O12:O16) -> 120504817 | P26: =SUM(P12:P13) -> 0 | Q26: =SUM(Q12:Q13) -> 0 | R26: =SUM(R12:R13) -> 0 | S26: =SUM(S12:S16) -> 120504817
D27: 1 | E27: =1+D27 -> 2 | F27: =1+E27 -> 3 | G27: =1+F27 -> 4 | H27: =1+G27 -> 5 | I27: =1+H27 -> 6 | J27: =1+I27 -> 7 | K27: =1+J27 -> 8 | L27: =1+K27 -> 9 | M27: =1+L27 -> 10 | Q27: =+#REF!/R27 -> #REF! | R27: 2500000000
A28: III. Tổ chức thực hiện | Q28: A | R28: B
A29: - Giám đốc Trung tâm Dịch vụ quản trị phê duyệt quy định này;
A30: - Ban Nhân sự - Trung tâm Dịch vụ quản trị thực hiện việc phối hợp, giám sát, đảm bảo công tác tính lương và bảo hiểm xã hội của cán bộ nhân viên trung tâm;
A31: - Phòng Tổng hợp, Phòng kế toán CVG tiếp nhận và thực hiện tính lương, tham gia Bảo hiểm xã hội cho cán bộ nhân viên thuộc Trung tâm dịch vụ quản trị;
A32: - Văn bản có hiệu lực kể từ ngày 01/10/2025.
A34: Nơi nhận: | G34: Hà Nội, ngày tháng năm 2025
A35: - GĐ TTDVQT (để chủ trì t/c t/h); | G35: Người lập
A36: - Ban NS (để p/h, g/s);
A37: - P.TH, P.KT (để t/n, t/h);
A38: - Lưu P.TH, TTDVQT.

Sheet 5.1 Cộng tác viên
A2: BẢNG THÔNG SỐ TÍNH LƯƠNG VỊ TRÍ
A4: STT | B4: Phòng/Ban | C4: Chức danh | D4: Mã nhân viên | E4: Họ và tên | F4: Tầng NS | G4: Thù lao thực nhận | H4: Thuế TNCN khấu trừ | I4: Thù lao thực nhận
A7: =SUBTOTAL(3,$C$7:C7) -> 1 | B7: Marketing | C7: CTV Content | D7: CTV002 | E7: Nông Thị Thu Hiền | G7: =I7/90% -> 3333333.3 | H7: =G7*10% -> 333333.33 | I7: 3000000
A8: =SUBTOTAL(3,$C$7:C8) -> 2 | B8: Marketing | C8: CTV Content | D8: CTV003 | E8: Phan Thị Minh Thu | G8: 13333333 | H8: =G8*10% -> 1333333.3 | I8: 12000000
A9: Tổng | G9: =SUM(G7) -> 3333333.3 | H9: =SUM(H7) -> 333333.33 | I9: =SUM(I7) -> 3000000
P10: =+#REF!/Q10 -> #REF! | Q10: 2500000000
G12: Hà Nội, ngày tháng năm 2024
G13: Người lập
E14: =G8*90% -> 12000000
G18: Nguyễn Thị Mai Hằng

Sheet 6.Bảng lương  
C1: TÊN ĐƠN VỊ: CÔNG TY CỔ PHẦN MS14 ĐỊA CHỈ: Clubhouse 3 đường Phong Lan 1, khu đô thị Vinhomes Riverside, phường Phúc Lợi, thành phố Hà Nội MST: 0111258406 | L1: BẢNG TÍNH THU NHẬP THÁNG 03/2026
A4: Ngày công tiêu chuẩn của CBNV | G4: ='3. BẢNG CHẤM CÔNG'!$AU$11 -> 22
A5: TT | B5: Mã nhân viên | C5: Họ và tên | D5: Phòng/Ban | E5: Chức danh/ Chức vụ | F5: Tình trạng | G5: Thu nhập đóng BHXH/ lương lễ tết phép (tổng thu nhập tháng trước thuế) | M5: (B) Thưởng YTCLCV (HQCV) | P5: (C) Thưởng hiệu quả kinh doanh | T5: (D) Các khoản mang tính chất lương khác | W5: (E) Các khoản hỗ trợ | AE5: Tổng thu nhập trước thuế | AF5: Tổng thu nhập chịu thuế | AG5: (VII) BHXH VÀ CÔNG ĐOÀN | AO5: Các khoản giảm trừ (bản thân và người phụ thuộc) | AS5: Tổng thu nhập tính thuế (I) | AT5: Thuế TNCN | AU5: Các khoản tạm ứng khác | AV5: Tổng thu nhập thực lĩnh | AW5: Tỷ trọng quỹ lương
G6: Ngày công | J6: Lương cơ bản/đóng BHXH/Lễ tết phép | K6: Lương cơ bản theo ngày công | L6: Tổng (A) | M6: Định mức thưởng | N6: Nghiệm thu YTCLCV (HQCV) | O6: TỔNG (B) | T6: Thưởng lương tháng 13 | U6: Phúc lợi | V6: Tổng ( D) | W6: Các khoản hỗ trợ miễn thuế TNCN | AA6: Các khoản hỗ trợ đóng thuế TNCN | AD6: Tổng (E) | AG6: Công ty đóng | AK6: Người lao động đóng
G7: Ngày công đi làm, nghỉ phép năm | H7: Ngày công lễ, Tết | I7: Ngày công làm online | P7: Doanh thu | Q7: Hck | R7: Thưởng doanh thu | S7: Tổng (C) | W7: Ăn trưa | X7: Trang phục | Y7: Điện thoại | Z7: Tổng ( E.1 ) | AA7: Gửi xe | AB7: Hỗ trợ kiêm nhiệm vị trí | AC7: Tổng (E.2) | AG7: BHXH (17,5%) | AH7: BHYT (3%) | AI7: BHTN (1%) | AJ7: Tổng (G) | AK7: BHXH (8%) | AL7: BHYT (1,5%) | AM7: BHTN (1%) | AN7: Tổng ( H ) | AO7: Bản thân | AP7: Người phụ thuộc | AR7: Tổng giảm trừ
AG8: 0.175 | AH8: 0.03 | AI8: 0.01 | AK8: 0.08 | AL8: 0.015 | AM8: 0.01 | AP8: Số người | AQ8: Số giảm
G9: 6 | H9: =G9+1 -> 7 | I9: =H9+1 -> 8 | J9: =I9+1 -> 9 | K9: =J9+1 -> 10 | L9: =K9+1 -> 11 | M9: =L9+1 -> 12 | N9: =M9+1 -> 13 | O9: =N9+1 -> 14 | ... AA9: =Z9+1 -> 26 | AC9: =AA9+1 -> 27 | AD9: =AC9+1 -> 28 | AE9: =AD9+1 -> 29 | AF9: =AE9+1 -> 30 | AG9: =AF9+1 -> 31 | AH9: =AG9+1 -> 32 | AI9: =AH9+1 -> 33 | AJ9: =AI9+1 -> 34 | AK9: =AJ9+1 -> 35 | ... AW9: =AV9+1 -> 47
AO10: 15500000 | AQ10: 6200000
B11: Ban Giám hiệu | J11: =SUBTOTAL(9,J12:J14) -> 7500000 | K11: =SUBTOTAL(9,K12:K14) -> 7500000 | L11: =SUBTOTAL(9,L12:L14) -> 7500000 | M11: =SUBTOTAL(9,M12:M14) -> 26083056 | N11: =SUBTOTAL(9,N12:N14) -> 3 | O11: =SUBTOTAL(9,O12:O14) -> 26083056 | P11: =SUBTOTAL(9,P12:P14) -> 0 | Q11: =SUBTOTAL(9,Q12:Q14) -> 0 | ... AT11: =SUBTOTAL(9,AT12:AT14) -> 2555555.6 | AV11: =AV12+AV13+AV14 -> 39000000
A12: 1 | B12: MS02 | C12: Bùi Thanh Anh | D12: BGH | E12: Hiệu trưởng | F12: =IFERROR(VLOOKUP($B12,'3. BẢNG CHẤM CÔNG'!$B$11:$AV$23,6,0),0) -> Chính Thức | G12: =IFERROR(VLOOKUP($B12, '3. BẢNG CHẤM CÔNG'!$B$10:$AV27,43,0),0) -> 22 | H12: =IFERROR(VLOOKUP($B12, '3. BẢNG CHẤM CÔNG'!$B$10:$AV27,44,0),0) -> 0 | J12: =IFERROR(VLOOKUP($B12,' 5. Thông số TL'!$D$12:$S$26,4,0),0) -> 0 | K12: =IFERROR(IF($F12="Chính Thức",$J12/$G$4*($G12+$H12),IF($F12="Thử Việc",$J12/$G$4*($G12+$H12)*85%,"")),0) -> 0 | L12: =SUM(K12) -> 0 | M12: =IFERROR(VLOOKUP($B12,' 5. Thông số TL'!$D$12:$S$26,5,0),0) -> 13046667 | N12: 1 | O12: =IFERROR(IF($F12="Chính Thức",$M12/$G$4*($G12+$H12)*N12,IF($F12="Thử Việc",$M12/$G$4*N12*($G12+$H12)*85%)),0) -> 13046667 | V12: =SUM(T12:U12) -> 0 | W12: =IFERROR(IF($F12="Chính Thức",VLOOKUP($B12,' 5. Thông số TL'!$D$12:$S$26,6,0)/$G$4*($G12+$H12),IF($F12="Thử Việc",VLOOKUP($B12,' 5. Thông số TL'!$D$12:$S$26,6,0)/$G$4*($G12+$H12)*85%,"")),0) -> 720000 | X12: =IFERROR(IF($F12="Chính Thức",VLOOKUP($B12,' 5. Thông số TL'!$D$12:$S$26,7,0)/$G$4*($G12+$H12),IF($F12="Thử Việc",VLOOKUP($B12,' 5. Thông số TL'!$D$12:$S$26,7,0)/$G$4*($G12+$H12)*85%,"")),0) -> 400000 | Y12: =IFERROR(IF($F12="Chính Thức",VLOOKUP($B12,' 5. Thông số TL'!$D$12:$S$26,8,0)/$G$4*($G12+$H12),IF($F12="Thử Việc",VLOOKUP($B12,' 5. Thông số TL'!$D$12:$S$26,8,0)/$G$4*($G12+$H12)*85%,"")),0) -> 2500000 | Z12: =SUM(W12:Y12) -> 3620000 | AA12: =IFERROR(IF($F12="Chính Thức",VLOOKUP($B12,' 5. Thông số TL'!$D$12:$S$26,10,0)/$G$4*($G12+$H12),IF($F12="Thử Việc",VLOOKUP($B12,' 5. Thông số TL'!$D$12:$S$26,10,0)/$G$4*($G12+$H12)*85%,"")),0) -> 0 | AC12: =SUM(AA12:AB12) -> 0 | AD12: =Z12+AC12 -> 3620000 | AE12: =L12+O12+S12+V12+AD12 -> 16666667 | AF12: =IF(F12="Chính Thức",AE12,IF(F12="Thử Việc",AE12-W12-X12,IF(F12="CTV",AE12,0))) -> 16666667 | AG12: =IFERROR(IF(AND($F12="Chính Thức",($G12+$H12)>=11),$J12*AG$8,IF(AND($F12="Chính Thức",($G12+$H12)<11,0),IF($F12="Thử Việc",0),"")),0) -> 0 | AH12: =IFERROR(IF(AND($F12="Chính Thức",($G12+$H12)>=11),$J12*AH$8,IF(AND($F12="Chính Thức",($G12+$H12)<11,0),IF($F12="Thử Việc",0),"")),0) -> 0 | AI12: =IFERROR(IF(AND($F12="Chính Thức",($G12+$H12)>=11),$J12*AI$8,IF(AND($F12="Chính Thức",($G12+$H12)<11,0),IF($F12="Thử Việc",0),"")),0) -> 0 | AJ12: =ROUND(SUM(AG12:AI12),0) -> 0 | AK12: =IFERROR(IF(AND($F12="Chính Thức",($G12+$H12)>=11),$J12*AK$8,IF(AND($F12="Chính Thức",($G12+$H12)<11,0),IF($F12="Thử Việc",0),"")),0) -> 0 | AL12: =IFERROR(IF(AND($F12="Chính Thức",($G12+$H12)>=11),$J12*AL$8,IF(AND($F12="Chính Thức",($G12+$H12)<11,0),IF($F12="Thử Việc",0),"")),0) -> 0 | AM12: =IFERROR(IF(AND($F12="Chính Thức",($G12+$H12)>=11),$J12*AM$8,IF(AND($F12="Chính Thức",($G12+$H12)<11,0),IF($F12="Thử Việc",0),"")),0) -> 0 | AN12: =ROUND(SUM(AK12:AM12),-1) -> 0 | AO12: 0 | AQ12: =AP12*$AQ$10 -> 0 | AR12: =+AO12+AQ12 -> 0 | AS12: =MAX(AF12,0) -> 16666667 | AT12: =AS12*10% -> 1666666.7 | AV12: =ROUND(AE12-AN12-AT12+AU12,-2) -> 15000000
